Workbook

Sheet Consolidated
G1: =SUBTOTAL(9,G4:G149027) -> 7392 | H1: =SUBTOTAL(9,H4:H149027) -> 65088.4 | I1: =SUBTOTAL(9,I4:I149027) -> 0 | J1: =SUBTOTAL(9,J4:J149027) -> 5002.54 | K1: =SUBTOTAL(9,K4:K149027) -> 79659.7 | L1: =SUBTOTAL(9,L4:L149027) -> 20145.97 | M1: =SUBTOTAL(9,M4:M149027) -> 87051.7 | N1: =SUBTOTAL(9,N4:N149027) -> 90236.91
B2: Stock Take Compilation | D2: 46075 | E2: Location: | G2: Rack & Dock | I2: Production | K2: Packing | M2: Total Stock
A3: Sr. No. | B3: ITEM | C3: FG/RM | D3: GROUP | E3: Sub-Group | F3: PACK SIZE | G3: Total Quantity | H3: Qty. in KG | I3: Total Quantity | J3: Qty. in KG | K3: Total Quantity | L3: Qty. in KG | M3: Total Quantity | N3: Qty. in KG
A4: 1 | B4: Almond Blanched Sliced | C4: RM | D4: ALMOND | E4: Almond - Broken | F4: 1 | G4: 0 | H4: 0 | I4: 0 | J4: 0 | K4: 0 | L4: 0 | M4: =G4+I4+K4 -> 0 | N4: =H4+J4+L4 -> 0
A5: 2 | B5: Almond Powder | C5: RM | D5: ALMOND | E5: Almond - Broken | F5: 1 | G5: 0 | H5: 0 | I5: 0 | J5: 0 | K5: 0 | L5: 0 | M5: =G5+I5+K5 -> 0 | N5: =H5+J5+L5 -> 0
A6: 3 | B6: Almond Sliced | C6: RM | D6: ALMOND | E6: Almond - Broken | F6: 1 | G6: 0 | H6: 0 | I6: 0 | J6: 0 | K6: 0 | L6: 0 | M6: =G6+I6+K6 -> 0 | N6: =H6+J6+L6 -> 0
A7: 4 | B7: Almonds Kernel Cube Cut | C7: RM | D7: ALMOND | E7: Almond - Broken | F7: 1 | G7: 0 | H7: 0 | I7: 0 | J7: 4.6 | K7: 0 | L7: 0 | M7: =G7+I7+K7 -> 0 | N7: =H7+J7+L7 -> 4.6
A8: 5 | B8: American Almonds Tukda | C8: RM | D8: ALMOND | E8: Almond - Broken | F8: 1 | G8: 0 | H8: 0 | I8: 0 | J8: 0 | K8: 0 | L8: 0 | M8: =G8+I8+K8 -> 0 | N8: =H8+J8+L8 -> 0
A9: 6 | B9: BLANCHED ALMOND FLOUR | C9: RM | D9: ALMOND | E9: Almond - Broken | F9: 1 | G9: 0 | H9: 0 | I9: 0 | J9: 0 | K9: 0 | L9: 0 | M9: =G9+I9+K9 -> 0 | N9: =H9+J9+L9 -> 0
A10: 7 | B10: Diced Almond | C10: RM | D10: ALMOND | E10: Almond - Broken | F10: 1 | G10: 0 | H10: 0 | I10: 0 | J10: 0 | K10: 0 | L10: 0 | M10: =G10+I10+K10 -> 0 | N10: =H10+J10+L10 -> 0
A11: 8 | B11: Slivered Almonds | C11: RM | D11: ALMOND | E11: Almond - Broken | F11: 1 | G11: 0 | H11: 0 | I11: 0 | J11: 0 | K11: 0 | L11: 0 | M11: =G11+I11+K11 -> 0 | N11: =H11+J11+L11 -> 0
A12: 9 | B12: AUSTRALIAN ALMOND INSHELL | C12: RM | D12: ALMOND | E12: Almond - Inshell | F12: 1 | G12: 0 | H12: 0 | I12: 0 | J12: 0 | K12: 0 | L12: 0 | M12: =G12+I12+K12 -> 0 | N12: =H12+J12+L12 -> 0
A13: 10 | B13: California Inshell Almonds | C13: RM | D13: ALMOND | E13: Almond - Inshell | F13: 1 | G13: 0 | H13: 0 | I13: 0 | J13: 0 | K13: 0 | L13: 0 | M13: =G13+I13+K13 -> 0 | N13: =H13+J13+L13 -> 0
A14: 11 | B14: Independent Almond Inshell | C14: RM | D14: ALMOND | E14: Almond - Inshell | F14: 1 | G14: 0 | H14: 0 | I14: 0 | J14: 0 | K14: 0 | L14: 0 | M14: =G14+I14+K14 -> 0 | N14: =H14+J14+L14 -> 0
A15: 12 | B15: Almond Blanched, whole | C15: RM | D15: ALMOND | E15: Almond - Kernels | F15: 1 | G15: 0 | H15: 0 | I15: 0 | J15: 0 | K15: 0 | L15: 0 | M15: =G15+I15+K15 -> 0 | N15: =H15+J15+L15 -> 0
... A1920: 1897 | B1920: Dry Kokam Phool | C1920: RM | D1920: DEHYDRATED FRUITS | E1920: DF - Other | F1920: 1 | G1920: 0 | H1920: 0 | I1920: 0 | J1920: 0 | K1920: 0 | L1920: 0 | M1920: =G1920+I1920+K1920 -> 0 | N1920: =H1920+J1920+L1920 -> 0
A1921: 1898 | B1921: Organic Cinnamon-Samruddhi Organic | D1921: SPICES | E1921: Whole Spices | F1921: 1 | G1921: 0 | H1921: 0 | I1921: 0 | J1921: 0 | K1921: 0 | L1921: 0 | M1921: =G1921+I1921+K1921 -> 0 | N1921: =H1921+J1921+L1921 -> 0
A1922: 1899 | B1922: Smoke BBQ Coated Peanut | C1922: FG | D1922: PEANUTS | E1922: Peanut - Coated | F1922: 1 | G1922: 0 | H1922: 0 | I1922: 0 | J1922: 0 | K1922: 0 | L1922: 0 | M1922: =G1922+I1922+K1922 -> 0 | N1922: =H1922+J1922+L1922 -> 0
A1923: 1900 | B1923: SNACK MASALA MIX | C1923: FG | D1923: TRAIL MIX | E1923: Trail Mix | F1923: 0.25 | G1923: 0 | H1923: 0 | I1923: 0 | J1923: 0 | K1923: 1.7 | L1923: 1.7 | M1923: =G1923+I1923+K1923 -> 1.7 | N1923: =H1923+J1923+L1923 -> 1.7
A1924: 1901 | B1924: Udid dal | C1924: RM | D1924: MISCELLANEOUS - RM | E1924: Other Misc | F1924: 1 | G1924: 0 | H1924: 0 | I1924: 0 | J1924: 0 | K1924: 0 | L1924: 0 | M1924: =G1924+I1924+K1924 -> 0 | N1924: =H1924+J1924+L1924 -> 0
A1925: 1902 | B1925: Rhine Valley Barbeque Trail Mix | C1925: FG | D1925: TRAIL MIX | E1925: Trail Mix | F1925: 1 | G1925: 0 | H1925: 0 | I1925: 0 | J1925: 0 | K1925: 0 | L1925: 0 | M1925: =G1925+I1925+K1925 -> 0 | N1925: =H1925+J1925+L1925 -> 0
A1926: 1903 | B1926: Rhine Valley Black Pepper Trail Mix | C1926: FG | D1926: TRAIL MIX | E1926: Trail Mix | F1926: 1 | G1926: 0 | H1926: 0 | I1926: 0 | J1926: 0 | K1926: 0 | L1926: 0 | M1926: =G1926+I1926+K1926 -> 0 | N1926: =H1926+J1926+L1926 -> 0
A1927: 1904 | B1927: Rhine Valley Peri Peri Trail Mix | C1927: FG | D1927: TRAIL MIX | E1927: Trail Mix | F1927: 1 | G1927: 0 | H1927: 0 | I1927: 0 | J1927: 0 | K1927: 0 | L1927: 0 | M1927: =G1927+I1927+K1927 -> 0 | N1927: =H1927+J1927+L1927 -> 0
A1928: 1905 | B1928: Rhine Valley Himalayan Pink Salt Trail Mix | C1928: FG | D1928: TRAIL MIX | E1928: Trail Mix | F1928: 1 | G1928: 0 | H1928: 0 | I1928: 0 | J1928: 0 | K1928: 0 | L1928: 0 | M1928: =G1928+I1928+K1928 -> 0 | N1928: =H1928+J1928+L1928 -> 0
A1929: 1906 | B1929: Bluberry Powder | C1929: RM | D1929: MISCELLANEOUS - RM | E1929: Other Misc | F1929: 1 | G1929: 0 | H1929: 0 | I1929: 0 | J1929: 0 | K1929: 0 | L1929: 0 | M1929: =G1929+I1929+K1929 -> 0 | N1929: =H1929+J1929+L1929 -> 0
A1930: 1907 | B1930: PEPPER PEANUT | C1930: FG | D1930: PEANUTS | E1930: Peanut - Whole | F1930: 1 | G1930: 0 | H1930: 0 | I1930: 0 | J1930: 0 | K1930: 0 | L1930: 0 | M1930: =G1930+I1930+K1930 -> 0 | N1930: =H1930+J1930+L1930 -> 0
A1931: 1908 | B1931: Roasted salted peanuts | C1931: FG | D1931: PEANUTS | E1931: Peanut - Whole | F1931: 1 | G1931: 0 | H1931: 0 | I1931: 0 | J1931: 0 | K1931: 0 | L1931: 0 | M1931: =G1931+I1931+K1931 -> 0 | N1931: =H1931+J1931+L1931 -> 0
A1932: 1909 | B1932: 5 GC dark chocolate | C1932: FG | D1932: BARS & CEREALS | E1932: Cereal | F1932: 1 | G1932: 0 | H1932: 0 | I1932: 0 | J1932: 0 | K1932: 0 | L1932: 0 | M1932: =G1932+I1932+K1932 -> 0 | N1932: =H1932+J1932+L1932 -> 0
A1933: 1910 | B1933: Indian Raisin 210 G | C1933: FG | D1933: RAISIN | E1933: Raisin - Indian | F1933: 0.21 | G1933: 0 | H1933: 0 | I1933: 0 | J1933: 0 | K1933: 0 | L1933: 0 | M1933: =G1933+I1933+K1933 -> 0 | N1933: =H1933+J1933+L1933 -> 0
... A1948: 1945 | B1948: TANGY THAI COATED PEANUT | C1948: FG | D1948: PEANUTS | E1948: Peanut - Coated | F1948: 1 | G1948: 0 | H1948: 0 | I1948: 0 | J1948: 0 | K1948: 0 | L1948: 2.83 | M1948: =G1948+I1948+K1948 -> 0 | N1948: =H1948+J1948+L1948 -> 2.83

Sheet Consolidated Rej
G1: =SUBTOTAL(9,G4:G149027) -> 0 | H1: =SUBTOTAL(9,H4:H149027) -> 2970.9 | I1: =SUBTOTAL(9,I4:I149027) -> 0 | J1: =SUBTOTAL(9,J4:J149027) -> 32 | K1: =SUBTOTAL(9,K4:K149027) -> 0 | L1: =SUBTOTAL(9,L4:L149027) -> 552.91 | M1: =SUBTOTAL(9,M4:M149027) -> 394 | N1: =SUBTOTAL(9,N4:N149027) -> 561.69 | ... P1: =SUBTOTAL(9,P4:P149027) -> 4117.5
B2: Stock Take Compilation | D2: 46075 | E2: Location: | G2: Rack & Dock | I2: Production | K2: Packing | M2: Fumigation | O2: Total Stock
A3: Sr. No. | B3: ITEM | C3: FG/RM | D3: GROUP | E3: Sub-Group | F3: PACK SIZE | G3: Total Quantity | H3: Qty. in KG | I3: Total Quantity | J3: Qty. in KG | K3: Total Quantity | L3: Qty. in KG | M3: Total Quantity | N3: Qty. in KG | O3: Total Quantity | P3: Qty. in KG
A4: 1 | B4: Almond Blanched Sliced | C4: RM | D4: ALMOND | E4: Almond - Broken | F4: 1 | G4: 0 | H4: 0 | I4: 0 | J4: 0 | K4: 0 | L4: 0 | M4: {=VLOOKUP(B4,'Fumigation Room'!B:H,{6,7},0)} -> 0 | N4: 0 | O4: =G4+I4+K4+M4 -> 0 | P4: =H4+J4+L4+N4 -> 0
A5: 2 | B5: Almond Powder | C5: RM | D5: ALMOND | E5: Almond - Broken | F5: 1 | G5: 0 | H5: 0 | I5: 0 | J5: 0 | K5: 0 | L5: 0 | M5: {=VLOOKUP(B5,'Fumigation Room'!B:H,{6,7},0)} -> 0 | N5: 26.15 | O5: =G5+I5+K5+M5 -> 0 | P5: =H5+J5+L5+N5 -> 26.15
A6: 3 | B6: Almond Sliced | C6: RM | D6: ALMOND | E6: Almond - Broken | F6: 1 | G6: 0 | H6: 0 | I6: 0 | J6: 0 | K6: 0 | L6: 0 | M6: {=VLOOKUP(B6,'Fumigation Room'!B:H,{6,7},0)} -> 0 | N6: 0 | O6: =G6+I6+K6+M6 -> 0 | P6: =H6+J6+L6+N6 -> 0
A7: 4 | B7: Almonds Kernel Cube Cut | C7: RM | D7: ALMOND | E7: Almond - Broken | F7: 1 | G7: 0 | H7: 0 | I7: 0 | J7: 0 | K7: 0 | L7: 0 | M7: {=VLOOKUP(B7,'Fumigation Room'!B:H,{6,7},0)} -> 0 | N7: 0.6 | O7: =G7+I7+K7+M7 -> 0 | P7: =H7+J7+L7+N7 -> 0.6
A8: 5 | B8: American Almonds Tukda | C8: RM | D8: ALMOND | E8: Almond - Broken | F8: 1 | G8: 0 | H8: 0 | I8: 0 | J8: 0 | K8: 0 | L8: 0 | M8: {=VLOOKUP(B8,'Fumigation Room'!B:H,{6,7},0)} -> 0 | N8: 0 | O8: =G8+I8+K8+M8 -> 0 | P8: =H8+J8+L8+N8 -> 0
A9: 6 | B9: BLANCHED ALMOND FLOUR | C9: RM | D9: ALMOND | E9: Almond - Broken | F9: 1 | G9: 0 | H9: 0 | I9: 0 | J9: 0 | K9: 0 | L9: 0 | M9: {=VLOOKUP(B9,'Fumigation Room'!B:H,{6,7},0)} -> 0 | N9: 0 | O9: =G9+I9+K9+M9 -> 0 | P9: =H9+J9+L9+N9 -> 0
A10: 7 | B10: Diced Almond | C10: RM | D10: ALMOND | E10: Almond - Broken | F10: 1 | G10: 0 | H10: 0 | I10: 0 | J10: 0 | K10: 0 | L10: 0 | M10: {=VLOOKUP(B10,'Fumigation Room'!B:H,{6,7},0)} -> 0 | N10: 0 | O10: =G10+I10+K10+M10 -> 0 | P10: =H10+J10+L10+N10 -> 0
A11: 8 | B11: Slivered Almonds | C11: RM | D11: ALMOND | E11: Almond - Broken | F11: 1 | G11: 0 | H11: 0 | I11: 0 | J11: 0 | K11: 0 | L11: 0 | M11: {=VLOOKUP(B11,'Fumigation Room'!B:H,{6,7},0)} -> 0 | N11: 0 | O11: =G11+I11+K11+M11 -> 0 | P11: =H11+J11+L11+N11 -> 0
A12: 9 | B12: AUSTRALIAN ALMOND INSHELL | C12: RM | D12: ALMOND | E12: Almond - Inshell | F12: 1 | G12: 0 | H12: 0 | I12: 0 | J12: 0 | K12: 0 | L12: 0 | M12: {=VLOOKUP(B12,'Fumigation Room'!B:H,{6,7},0)} -> 0 | N12: 0 | O12: =G12+I12+K12+M12 -> 0 | P12: =H12+J12+L12+N12 -> 0
A13: 10 | B13: California Inshell Almonds | C13: RM | D13: ALMOND | E13: Almond - Inshell | F13: 1 | G13: 0 | H13: 0 | I13: 0 | J13: 0 | K13: 0 | L13: 0 | M13: {=VLOOKUP(B13,'Fumigation Room'!B:H,{6,7},0)} -> 0 | N13: 0 | O13: =G13+I13+K13+M13 -> 0 | P13: =H13+J13+L13+N13 -> 0
A14: 11 | B14: Independent Almond Inshell | C14: RM | D14: ALMOND | E14: Almond - Inshell | F14: 1 | G14: 0 | H14: 0 | I14: 0 | J14: 0 | K14: 0 | L14: 0 | M14: {=VLOOKUP(B14,'Fumigation Room'!B:H,{6,7},0)} -> 0 | N14: 0 | O14: =G14+I14+K14+M14 -> 0 | P14: =H14+J14+L14+N14 -> 0
A15: 12 | B15: Almond Blanched, whole | C15: RM | D15: ALMOND | E15: Almond - Kernels | F15: 1 | G15: 0 | H15: 0 | I15: 0 | J15: 0 | K15: 0 | L15: 0 | M15: {=VLOOKUP(B15,'Fumigation Room'!B:H,{6,7},0)} -> 0 | N15: 0 | O15: =G15+I15+K15+M15 -> 0 | P15: =H15+J15+L15+N15 -> 0
... A125: 122 | B125: PREMIA ALMONDS SMOKD-100G | C125: FG | D125: ALMOND | E125: Almond - Kernels | F125: 0.1 | G125: 0 | H125: 0 | I125: 0 | J125: 0 | K125: 0 | L125: 0 | M125: {=VLOOKUP(B125,'Fumigation Room'!B:H,{6,7},0)} -> 0 | N125: 0 | O125: =G125+I125+K125+M125 -> 0 | P125: =H125+J125+L125+N125 -> 0
A126: 123 | B126: Roasted & Salted Almonds | C126: FG | D126: ALMOND | E126: Almond - Kernels | F126: 1 | G126: 0 | H126: 0 | I126: 0 | J126: 0 | K126: 0 | L126: =VLOOKUP(B126,'Packing Off Grade'!I:J,2,0) -> 6.6 | M126: {=VLOOKUP(B126,'Fumigation Room'!B:H,{6,7},0)} -> 0 | N126: 12.5 | O126: =G126+I126+K126+M126 -> 0 | P126: =H126+J126+L126+N126 -> 19.1
A127: 124 | B127: Roasted & Salted Almonds 140g | C127: FG | D127: ALMOND | E127: Almond - Kernels | F127: 0.14 | G127: 0 | H127: 0 | I127: 0 | J127: 0 | K127: 0 | L127: 0 | M127: {=VLOOKUP(B127,'Fumigation Room'!B:H,{6,7},0)} -> 0 | N127: 0 | O127: =G127+I127+K127+M127 -> 0 | P127: =H127+J127+L127+N127 -> 0
A128: 125 | B128: Roasted & Salted Almonds 75g | C128: FG | D128: ALMOND | E128: Almond - Kernels | F128: 0.075 | G128: 0 | H128: 0 | I128: 0 | J128: 0 | K128: 0 | L128: 0 | M128: {=VLOOKUP(B128,'Fumigation Room'!B:H,{6,7},0)} -> 0 | N128: 0 | O128: =G128+I128+K128+M128 -> 0 | P128: =H128+J128+L128+N128 -> 0
A129: 126 | B129: Roasted & Salted Almonds 90g | C129: FG | D129: ALMOND | E129: Almond - Kernels | F129: 0.09 | G129: 0 | H129: 0 | I129: 0 | J129: 0 | K129: 0 | L129: 0 | M129: {=VLOOKUP(B129,'Fumigation Room'!B:H,{6,7},0)} -> 0 | N129: 0 | O129: =G129+I129+K129+M129 -> 0 | P129: =H129+J129+L129+N129 -> 0
A130: 127 | B130: Roasted & Salted Almonds Bulk | C130: FG | D130: ALMOND | E130: Almond - Kernels | F130: 1 | G130: 0 | H130: 0 | I130: 0 | J130: 0 | K130: 0 | L130: 0 | M130: {=VLOOKUP(B130,'Fumigation Room'!B:H,{6,7},0)} -> 0 | N130: 0 | O130: =G130+I130+K130+M130 -> 0 | P130: =H130+J130+L130+N130 -> 0
A131: 128 | B131: Roasted Independence Almonds Bulk | C131: FG | D131: ALMOND | E131: Almond - Kernels | F131: 1 | G131: 0 | H131: 0 | I131: 0 | J131: 0 | K131: 0 | L131: 0 | M131: {=VLOOKUP(B131,'Fumigation Room'!B:H,{6,7},0)} -> 0 | N131: 0 | O131: =G131+I131+K131+M131 -> 0 | P131: =H131+J131+L131+N131 -> 0
A132: 129 | B132: Royal Traditions Almond 100g | C132: FG | D132: ALMOND | E132: Almond - Kernels | F132: 0.1 | G132: 0 | H132: 0 | I132: 0 | J132: 0 | K132: 0 | L132: 0 | M132: {=VLOOKUP(B132,'Fumigation Room'!B:H,{6,7},0)} -> 0 | N132: 0 | O132: =G132+I132+K132+M132 -> 0 | P132: =H132+J132+L132+N132 -> 0
A133: 130 | B133: Royal Traditions Almonds Salted 100g | C133: FG | D133: ALMOND | E133: Almond - Kernels | F133: 0.1 | G133: 0 | H133: 0 | I133: 0 | J133: 0 | K133: 0 | L133: 0 | M133: {=VLOOKUP(B133,'Fumigation Room'!B:H,{6,7},0)} -> 0 | N133: 0 | O133: =G133+I133+K133+M133 -> 0 | P133: =H133+J133+L133+N133 -> 0
A134: 131 | B134: Smoked Almonds | C134: FG | D134: ALMOND | E134: Almond - Kernels | F134: 1 | G134: 0 | H134: 0 | I134: 0 | J134: 0 | K134: 0 | L134: 0 | M134: {=VLOOKUP(B134,'Fumigation Room'!B:H,{6,7},0)} -> 0 | N134: 2.55 | O134: =G134+I134+K134+M134 -> 0 | P134: =H134+J134+L134+N134 -> 2.55
A135: 132 | B135: Smoked Almonds Bulk | C135: FG | D135: ALMOND | E135: Almond - Kernels | F135: 1 | G135: 0 | H135: 0 | I135: 0 | J135: 0 | K135: 0 | L135: 0 | M135: {=VLOOKUP(B135,'Fumigation Room'!B:H,{6,7},0)} -> 0 | N135: 0 | O135: =G135+I135+K135+M135 -> 0 | P135: =H135+J135+L135+N135 -> 0
A136: 133 | B136: SnackAmor Roasted Salted Almonds 170g | C136: FG | D136: ALMOND | E136: Almond - Kernels | F136: 0.17 | G136: 0 | H136: 0 | I136: 0 | J136: 0 | K136: 0 | L136: 0 | M136: {=VLOOKUP(B136,'Fumigation Room'!B:H,{6,7},0)} -> 0 | N136: 0 | O136: =G136+I136+K136+M136 -> 0 | P136: =H136+J136+L136+N136 -> 0
A137: 134 | B137: Snackania American Almonds 480g | C137: FG | D137: ALMOND | E137: Almond - Kernels | F137: 0.48 | G137: 0 | H137: 0 | I137: 0 | J137: 0 | K137: 0 | L137: 0 | M137: {=VLOOKUP(B137,'Fumigation Room'!B:H,{6,7},0)} -> 0 | N137: 0 | O137: =G137+I137+K137+M137 -> 0 | P137: =H137+J137+L137+N137 -> 0
A138: 135 | B138: Solimo Preimum Almonds 1kg (B01LPY9P2I) - FBA | C138: FG | D138: ALMOND | E138: Almond - Kernels | F138: 1 | G138: 0 | H138: 0 | I138: 0 | J138: 0 | K138: 0 | L138: 0 | M138: {=VLOOKUP(B138,'Fumigation Room'!B:H,{6,7},0)} -> 0 | N138: 0 | O138: =G138+I138+K138+M138 -> 0 | P138: =H138+J138+L138+N138 -> 0
... A166: 163 | B166: NB MAMRA ALMOND CLASSIC LOOSE | C166: FG | D166: ALMOND | E166: Almond - Mamra | F166: 1 | G166: 0 | H166: 0 | I166: 0 | J166: 0 | K166: 0 | L166: 0 | M166: {=VLOOKUP(B166,'Fumigation Room'!B:H,{6,7},0)} -> 0 | N166: 0 | O166: =G166+I166+K166+M166 -> 0 | P166: =H166+J166+L166+N166 -> 0
A167: 164 | B167: NB MAMRA ALMOND ROYAL LOOSE (Not in Use) | C167: FG | D167: ALMOND | E167: Almond - Mamra | F167: 1 | G167: 0 | H167: 0 | I167: 0 | J167: 0 | K167: 0 | L167: 0 | M167: 0 | N167: 0 | O167: =G167+I167+K167+M167 -> 0 | P167: =H167+J167+L167+N167 -> 0
A168: 165 | B168: NB MAMRA ALMOND ROYAL LOOSE_x000D_ | C168: FG | D168: ALMOND | E168: Almond - Mamra | F168: 1 | G168: 0 | H168: 0 | I168: 0 | J168: 0 | K168: 0 | L168: 0 | M168: {=VLOOKUP(B168,'Fumigation Room'!B:H,{6,7},0)} -> 0 | N168: 0 | O168: =G168+I168+K168+M168 -> 0 | P168: =H168+J168+L168+N168 -> 0
A169: 166 | B169: OFF-GRADE ALMOND | C169: RM | D169: ALMOND | E169: OFF-GRADE ALMOND | F169: 1 | G169: 0 | H169: 0 | I169: 0 | J169: 0 | K169: 0 | L169: 0 | M169: {=VLOOKUP(B169,'Fumigation Room'!B:H,{6,7},0)} -> 0 | N169: 0 | O169: =G169+I169+K169+M169 -> 0 | P169: =H169+J169+L169+N169 -> 0
A170: 167 | B170: Anjeer (Figs) | C170: RM | D170: ANJEER | E170: Dried Figs | F170: 1 | G170: 0 | H170: 0 | I170: 0 | J170: 0 | K170: 0 | L170: 0 | M170: {=VLOOKUP(B170,'Fumigation Room'!B:H,{6,7},0)} -> 0 | N170: 0 | O170: =G170+I170+K170+M170 -> 0 | P170: =H170+J170+L170+N170 -> 0
A171: 168 | B171: Anjeer 1*1 | C171: RM | D171: ANJEER | E171: Dried Figs | F171: 1 | G171: 0 | H171: 0 | I171: 0 | J171: 0 | K171: 0 | L171: 0 | M171: {=VLOOKUP(B171,'Fumigation Room'!B:H,{6,7},0)} -> 0 | N171: 0 | O171: =G171+I171+K171+M171 -> 0 | P171: =H171+J171+L171+N171 -> 0
A172: 169 | B172: Anjeer 1*2 | C172: RM | D172: ANJEER | E172: Dried Figs | F172: 1 | G172: 0 | H172: 0 | I172: 0 | J172: 0 | K172: 0 | L172: 0 | M172: {=VLOOKUP(B172,'Fumigation Room'!B:H,{6,7},0)} -> 0 | N172: 10.4 | O172: =G172+I172+K172+M172 -> 0 | P172: =H172+J172+L172+N172 -> 10.4
A173: 170 | B173: Anjeer Chutta | C173: RM | D173: ANJEER | E173: Dried Figs | F173: 1 | G173: 0 | H173: 0 | I173: 0 | J173: 0 | K173: 0 | L173: 0 | M173: {=VLOOKUP(B173,'Fumigation Room'!B:H,{6,7},0)} -> 0 | N173: 0 | O173: =G173+I173+K173+M173 -> 0 | P173: =H173+J173+L173+N173 -> 0
A174: 171 | B174: Anjeer Selected | C174: RM | D174: ANJEER | E174: Dried Figs | F174: 1 | G174: 0 | H174: 0 | I174: 0 | J174: 0 | K174: 0 | L174: 0 | M174: {=VLOOKUP(B174,'Fumigation Room'!B:H,{6,7},0)} -> 0 | N174: 0 | O174: =G174+I174+K174+M174 -> 0 | P174: =H174+J174+L174+N174 -> 0
A175: 172 | B175: Anjeer 1*2 75gm | C175: FG | D175: ANJEER | E175: Dried Figs | F175: 0.075 | G175: 0 | H175: 0 | I175: 0 | J175: 0 | K175: 0 | L175: 0 | M175: {=VLOOKUP(B175,'Fumigation Room'!B:H,{6,7},0)} -> 0 | N175: 0 | O175: =G175+I175+K175+M175 -> 0 | P175: =H175+J175+L175+N175 -> 0
A176: 173 | B176: Cafe Galleries Anjeer 500g Big | C176: FG | D176: ANJEER | E176: Dried Figs | F176: 0.5 | G176: 0 | H176: 0 | I176: 0 | J176: 0 | K176: 0 | L176: 0 | M176: {=VLOOKUP(B176,'Fumigation Room'!B:H,{6,7},0)} -> 0 | N176: 0 | O176: =G176+I176+K176+M176 -> 0 | P176: =H176+J176+L176+N176 -> 0
...

Sheet Rack rej
A1: Off Grade/Rejection Entries
A2: Warehouse: | D2: Floor:
A3: Submitted By: | D3: Submitted At:
A5: S.No | B5: Category (Group) | C5: Subcategory | D5: Item Description | E5: UOM (kg) | F5: Units | G5: Total Weight (kg) | J5: Row Labels | K5: Sum of Total Weight (kg)
A6: 1 | B6: PISTA | C6: PISTA - INSHELL | D6: CALIFORNIA PISTA INSHELL ROASTED AND SALTED | E6: 1.000 | F6: 303 | G6: 303 | K6: 2970.9
A7: 2 | B7: PISTA | C7: PISTA - INSHELL | D7: CALIFORNIA PISTA INSHELL | E7: 1.000 | F7: 266 | G7: 266 | J7: CALIFORNIA PISTA INSHELL | K7: 1376.18
A8: 3 | B8: PISTA | C8: PISTA - INSHELL | D8: CALIFORNIA PISTA INSHELL ROASTED AND SALTED | E8: 1.000 | F8: 386.42 | G8: 386.42 | J8: CALIFORNIA PISTA INSHELL ROASTED AND SALTED | K8: 1594.72
A9: 4 | B9: PISTA | C9: PISTA - INSHELL | D9: CALIFORNIA PISTA INSHELL | E9: 1.000 | F9: 149 | G9: 149 | J9: Grand Total | K9: 5941.8
A10: 5 | B10: PISTA | C10: PISTA - INSHELL | D10: CALIFORNIA PISTA INSHELL | E10: 1.000 | F10: 240 | G10: 240
A11: 6 | B11: PISTA | C11: PISTA - INSHELL | D11: CALIFORNIA PISTA INSHELL | E11: 1.000 | F11: 331.18 | G11: 331.18
A12: 7 | B12: PISTA | C12: PISTA - INSHELL | D12: CALIFORNIA PISTA INSHELL | E12: 1.000 | F12: 150 | G12: 150
A13: 8 | B13: PISTA | C13: PISTA - INSHELL | D13: CALIFORNIA PISTA INSHELL ROASTED AND SALTED | E13: 1.000 | F13: 149 | G13: 149
A14: 9 | B14: PISTA | C14: PISTA - INSHELL | D14: CALIFORNIA PISTA INSHELL | E14: 1.000 | F14: 240 | G14: 240
A15: 10 | B15: PISTA | C15: PISTA - INSHELL | D15: CALIFORNIA PISTA INSHELL ROASTED AND SALTED | E15: 1.000 | F15: 332.28 | G15: 332.28
A16: 11 | B16: PISTA | C16: PISTA - INSHELL | D16: CALIFORNIA PISTA INSHELL ROASTED AND SALTED | E16: 1.000 | F16: 243.86 | G16: 243.86
A17: 12 | B17: PISTA | C17: PISTA - INSHELL | D17: CALIFORNIA PISTA INSHELL ROASTED AND SALTED | E17: 1.000 | F17: 180.16 | G17: 180.16
A18: TOTAL | F18: 2970.9 | G18: 2970.9

Sheet Production Rej
A1: Off Grade/Rejection Entries
A2: Warehouse: | D2: Floor:
A3: Submitted By: | D3: Submitted At:
A5: S.No | B5: Category (Group) | C5: Subcategory | D5: Item Description | E5: UOM (kg) | F5: Units | G5: Total Weight (kg)
A6: 1 | B6: PEANUTS | C6: PEANUT - COATED | D6: KRACK NUT COATED PEANUTS TANDOORI TOOFAN 1 KG | E6: 1.000 | F6: 7 | G6: 7.00
A7: 2 | B7: PEANUTS | C7: PEANUT - COATED | D7: COATED PEANUT BASE | E7: 1.000 | F7: 25 | G7: 25.00
A8: TOTAL | F8: 32 | G8: 32.00

Sheet Packing Off Grade
A1: Off Grade/Rejection Entries
A2: Warehouse: | D2: Floor:
A3: Submitted By: | D3: Submitted At:
A5: S.No | B5: Category (Group) | C5: Subcategory | D5: Item Description | E5: UOM (kg) | F5: Units | G5: Total Weight (kg) | I5: Row Labels | J5: Sum of Total Weight (kg)
A6: 1 | B6: PEANUTS | C6: PEANUT - COATED | D6: PLAIN COATED PEANUTS | E6: 1.000 | F6: 269.56 | G6: 269.56 | J6: 0
A7: 2 | B7: PEANUTS | C7: PEANUT - COATED | D7: SMOKEY BBQ COATED PEANUT | E7: 1.000 | F7: 1.5 | G7: 1.5 | I7: AFGHAN BLACK RAISINS SEEDLESS 1*2 | J7: 5.6
A8: 3 | B8: PEANUTS | C8: PEANUT - COATED | D8: Honey Chipotle Coated Peanut | E8: 1.000 | F8: 5.6 | G8: 5.6 | I8: AFGHAN MUNAKKA / ABJOSH 1X2 | J8: 2.7
A9: 4 | B9: CASHEW | C9: CASHEW - KERNEL | D9: ROASTED & SALTED CASHEW | E9: 1.000 | F9: 31.4 | G9: 31.4 | I9: BLACK PEPPER CASHEW | J9: 22.7
A10: 5 | B10: CASHEW | C10: CASHEW - KERNEL | D10: ROASTED & SALTED CASHEW | E10: 1.000 | F10: 5.78 | G10: 5.78 | I10: CALIFORNIA PISTA INSHELL | J10: 127.4
A11: 6 | B11: CASHEW | C11: CASHEW - KERNEL | D11: BLACK PEPPER CASHEW | E11: 1.000 | F11: 22.7 | G11: 22.7 | I11: CALIFORNIA PISTA INSHELL ROASTED AND SALTED | J11: 21
A12: 7 | B12: RAISIN | C12: RAISIN - ABJOSH | D12: AFGHAN MUNAKKA / ABJOSH 1X2 | E12: 1.000 | F12: 2.7 | G12: 2.7 | I12: Honey Chipotle Coated Peanut | J12: 5.6
A13: 8 | B13: RAISIN | C13: RAISIN - BLACK | D13: AFGHAN BLACK RAISINS SEEDLESS 1*2 | E13: 1.000 | F13: 5.6 | G13: 5.6 | I13: PISTA KERNAL ROASTED AND SALTED | J13: 14.52
A14: 9 | B14: ALMOND | C14: ALMOND - KERNELS | D14: ROASTED & SALTED ALMONDS | E14: 1.000 | F14: 6.6 | G14: 6.6 | I14: PISTA KERNEL | J14: 2.1
A15: 10 | B15: PISTA | C15: PISTA - KERNEL | D15: PISTA KERNAL ROASTED AND SALTED | E15: 1.000 | F15: 14.52 | G15: 14.52 | I15: PISTA MAGAZ SPLIT CALIFORNIA | J15: 14.6
A16: 11 | B16: PISTA | C16: PISTA - KERNEL | D16: PISTA MAGAZ SPLIT CALIFORNIA | E16: 1.000 | F16: 14.6 | G16: 14.6 | I16: PLAIN COATED PEANUTS | J16: 269.56
A17: 12 | B17: PISTA | C17: PISTA - KERNEL | D17: PISTA KERNEL | E17: 1.000 | F17: 2.1 | G17: 2.1 | I17: ROASTED & SALTED ALMONDS | J17: 6.6
A18: 13 | B18: SEEDS | C18: SUNFLOWER | D18: SUNFLOWER SEEDS | E18: 1.000 | F18: 19.15 | G18: 19.15 | I18: ROASTED & SALTED CASHEW | J18: 37.18
... A21: 16 | B21: PISTA | C21: PISTA - INSHELL | D21: CALIFORNIA PISTA INSHELL ROASTED AND SALTED | E21: 1.000 | F21: 21 | G21: 21 | I21: WATER MELON SEED | J21: 2.7
A22: TOTAL | F22: 829.94 | G22: 829.94 | I22: Grand Total | J22: 552.91

Sheet Fumigation  Room
A1: Sr. No. | B1: ITEM | C1: FG/RM | D1: GROUP | E1: Sub-Group | F1: PACK SIZE | G1: unit | H1: In kg
A2: 1 | B2: Almond Blanched Sliced | C2: RM | D2: ALMOND | E2: Almond - Broken | F2: 1
A3: 2 | B3: Almond Powder | C3: RM | D3: ALMOND | E3: Almond - Broken | F3: 1 | H3: =6+20.15 -> 26.15 | I3: Rejction
A4: 3 | B4: Almond Sliced | C4: RM | D4: ALMOND | E4: Almond - Broken | F4: 1
A5: 4 | B5: Almonds Kernel Cube Cut | C5: RM | D5: ALMOND | E5: Almond - Broken | F5: 1 | H5: 0.6 | I5: Rejction
A6: 5 | B6: American Almonds Tukda | C6: RM | D6: ALMOND | E6: Almond - Broken | F6: 1
A7: 6 | B7: BLANCHED ALMOND FLOUR | C7: RM | D7: ALMOND | E7: Almond - Broken | F7: 1
A8: 7 | B8: Diced Almond | C8: RM | D8: ALMOND | E8: Almond - Broken | F8: 1
A9: 8 | B9: Slivered Almonds | C9: RM | D9: ALMOND | E9: Almond - Broken | F9: 1
A10: 9 | B10: AUSTRALIAN ALMOND INSHELL | C10: RM | D10: ALMOND | E10: Almond - Inshell | F10: 1
A11: 10 | B11: California Inshell Almonds | C11: RM | D11: ALMOND | E11: Almond - Inshell | F11: 1
A12: 11 | B12: Independent Almond Inshell | C12: RM | D12: ALMOND | E12: Almond - Inshell | F12: 1
A13: 12 | B13: Almond Blanched, whole | C13: RM | D13: ALMOND | E13: Almond - Kernels | F13: 1
A14: 13 | B14: Almond Kernel | C14: RM | D14: ALMOND | E14: Almond - Kernels | F14: 1
A15: 14 | B15: American Almond Double Tonch | C15: RM | D15: ALMOND | E15: Almond - Kernels | F15: 1
A16: 15 | B16: American Almonds ( 18-20 Count) | C16: RM | D16: ALMOND | E16: Almond - Kernels | F16: 1
A17: 16 | B17: American Almonds (22-23 Count) | C17: RM | D17: ALMOND | E17: Almond - Kernels | F17: 1
... A28: 27 | B28: American Almonds Running [28-30 Count] | C28: RM | D28: ALMOND | E28: Almond - Kernels | F28: 1
A29: 28 | B29: American Almonds Running 25-27 count | C29: RM | D29: ALMOND | E29: Almond - Kernels | F29: 1 | H29: =1.3+1.1 -> 2.4 | I29: Rejction
A30: 29 | B30: American Almonds Special | C30: RM | D30: ALMOND | E30: Almond - Kernels | F30: 1
A31: 30 | B31: American Almonds Tonch | C31: RM | D31: ALMOND | E31: Almond - Kernels | F31: 1
A32: 31 | B32: Honey Roast Almonds | C32: RM | D32: ALMOND | E32: Almond - Kernels | F32: 1
A33: 32 | B33: Independence Almonds | C33: RM | D33: ALMOND | E33: Almond - Kernels | F33: 1
A34: 33 | B34: Almond Mamra Touch | C34: RM | D34: ALMOND | E34: Almond - Mamra | F34: 1
A35: 34 | B35: Mamra Almonds 1A | C35: RM | D35: ALMOND | E35: Almond - Mamra | F35: 1
A36: 35 | B36: Mamra Almonds 2A | C36: RM | D36: ALMOND | E36: Almond - Mamra | F36: 1
A37: 36 | B37: Mamra Almonds 3A | C37: RM | D37: ALMOND | E37: Almond - Mamra | F37: 1
A38: 37 | B38: Mamra Almonds 4A | C38: RM | D38: ALMOND | E38: Almond - Mamra | F38: 1
A39: 38 | B39: Mamra Almonds 5A | C39: RM | D39: ALMOND | E39: Almond - Mamra | F39: 1
A40: 39 | B40: Mamra Almonds 6A | C40: RM | D40: ALMOND | E40: Almond - Mamra | F40: 1
A41: 40 | B41: Mamra Almonds 7A | C41: RM | D41: ALMOND | E41: Almond - Mamra | F41: 1
... A134: 133 | B134: PREMIA ALMONDS SMOKD-100G | C134: FG | D134: ALMOND | E134: Almond - Kernels | F134: 0.1
A135: 134 | B135: Roasted & Salted Almonds | C135: FG | D135: ALMOND | E135: Almond - Kernels | F135: 1 | H135: 12.5 | I135: Rejction
A136: 135 | B136: Roasted & Salted Almonds 140g | C136: FG | D136: ALMOND | E136: Almond - Kernels | F136: 0.14
A137: 136 | B137: Roasted & Salted Almonds 75g | C137: FG | D137: ALMOND | E137: Almond - Kernels | F137: 0.075
A138: 137 | B138: Roasted & Salted Almonds 90g | C138: FG | D138: ALMOND | E138: Almond - Kernels | F138: 0.09
A139: 138 | B139: Roasted & Salted Almonds Bulk | C139: FG | D139: ALMOND | E139: Almond - Kernels | F139: 1
A140: 139 | B140: Roasted Independence Almonds Bulk | C140: FG | D140: ALMOND | E140: Almond - Kernels | F140: 1
A141: 140 | B141: Royal Traditions Almond 100g | C141: FG | D141: ALMOND | E141: Almond - Kernels | F141: 0.1
A142: 141 | B142: Royal Traditions Almonds Salted 100g | C142: FG | D142: ALMOND | E142: Almond - Kernels | F142: 0.1
...

Sheet Rack And Dock Area
A1: Fresh Stock Entries
A2: Warehouse: | D2: Floor:
A3: Submitted By: | D3: Submitted At:
A5: S.No | B5: Category (Group) | C5: Subcategory | D5: Item Description | E5: UOM (kg) | F5: Units | G5: Total Weight (kg) | I5: Row Labels | J5: Sum of Units | K5: Sum of Total Weight (kg)
A6: 1 | B6: SEEDS | C6: CHIA | D6: BLACK CHIA SEEDS | E6: 1.000 | F6: 540 | G6: 540 | I6: AFGHAN BLACK RAISINS SEEDLESS 1*2 | J6: 289.8 | K6: 289.8 | L6: =VLOOKUP(I6,Consolidated!B:B,1,0) -> Afghan Black Raisins Seedless 1*2
A7: 2 | B7: CASHEW | C7: CASHEW - KERNEL | D7: CASHEW 320 | E7: 1.000 | F7: 360 | G7: 360 | I7: AL BARAKAH PREMIUM EMIRATES DATES 500G | J7: 1488 | K7: 744 | L7: =VLOOKUP(I7,Consolidated!B:B,1,0) -> #N/A
A8: 3 | B8: SEEDS | C8: FLAX | D8: FLAX SEEDS (ALSI) | E8: 1.000 | F8: 500 | G8: 500 | I8: AL BARAKAH PREMIUM SEEDLESS DATES 500G | J8: 2656 | K8: 1328 | L8: =VLOOKUP(I8,Consolidated!B:B,1,0) -> AL BARAKAH PREMIUM SEEDLESS DATES 500G
A9: 4 | B9: SEEDS | C9: FLAX | D9: FLAX SEEDS (ALSI) | E9: 1.000 | F9: 500 | G9: 500 | I9: AMERICAN ALMONDS RUNNING 25-27 COUNT | J9: 1834.5 | K9: 1834.5 | L9: =VLOOKUP(I9,Consolidated!B:B,1,0) -> American Almonds Running 25-27 count
A10: 5 | B10: MISCELLANEOUS - RM | C10: FLOUR | D10: RICE ATTA | E10: 1.000 | F10: 400 | G10: 400 | I10: BARBEQUE SEASONING | J10: 25 | K10: 25 | L10: =VLOOKUP(I10,Consolidated!B:B,1,0) -> Barbeque seasoning
A11: 6 | B11: SEEDS | C11: CHIA | D11: BLACK CHIA SEEDS | E11: 1.000 | F11: 2000 | G11: 2000 | I11: BLACK CHIA SEEDS | J11: 12015 | K11: 12015 | L11: =VLOOKUP(I11,Consolidated!B:B,1,0) -> Black Chia Seeds
A12: 7 | B12: CASHEW | C12: CASHEW - KERNEL | D12: CASHEW 320 | E12: 1.000 | F12: 350 | G12: 350 | I12: CALIFORNIA PISTA INSHELL | J12: 8464.64 | K12: 8464.64 | L12: =VLOOKUP(I12,Consolidated!B:B,1,0) -> California Pista Inshell
A13: 8 | B13: SEEDS | C13: CHIA | D13: BLACK CHIA SEEDS | E13: 1.000 | F13: 500 | G13: 500 | I13: CALIFORNIA PISTA INSHELL ROASTED AND SALTED | J13: 15.4 | K13: 15.4 | L13: =VLOOKUP(I13,Consolidated!B:B,1,0) -> California Pista Inshell Roasted and Salted
A14: 9 | B14: MISCELLANEOUS - RM | C14: OTHER MISC | D14: SUGAR POWDER | E14: 1.000 | F14: 200 | G14: 200 | I14: CANOLA OIL | J14: 185 | K14: 185 | L14: =VLOOKUP(I14,Consolidated!B:B,1,0) -> Canola Oil
A15: 10 | B15: SEEDS | C15: WATERMELON | D15: WATER MELON SEED | E15: 1.000 | F15: 1400 | G15: 1400 | I15: CARNIVAL ALMONDS 250 GM | J15: 6 | K15: 1.5 | L15: =VLOOKUP(I15,Consolidated!B:B,1,0) -> Carnival Almonds 250 Gm
A16: 11 | B16: SEEDS | C16: PUMPKIN | D16: PUMPKIN SEED ( 5% ) | E16: 1.000 | F16: 3600 | G16: 3600 | I16: CASHEW 240 | J16: 10 | K16: 10 | L16: =VLOOKUP(I16,Consolidated!B:B,1,0) -> Cashew 240
A17: 12 | B17: SEEDS | C17: SUNFLOWER | D17: SUNFLOWER SEEDS | E17: 1.000 | F17: 900 | G17: 900 | I17: CASHEW 320 | J17: 716.5 | K17: 716.5 | L17: =VLOOKUP(I17,Consolidated!B:B,1,0) -> Cashew 320
... A21: 16 | B21: SEEDS | C21: SUNFLOWER | D21: SUNFLOWER SEEDS | E21: 1.000 | F21: 900 | G21: 900 | I21: CITRIC ACID | J21: 25 | K21: 25 | L21: =VLOOKUP(I21,Consolidated!B:B,1,0) -> Citric Acid
A22: 17 | B22: TAJIR | C22: TAJIR - OTHER | D22: MAIZE STARCH | E22: 1.000 | F22: 500 | G22: 500 | I22: Cocktail Mix | K22: 5.18 | L22: =VLOOKUP(I22,Consolidated!B:B,1,0) -> Cocktail Mix
A23: 18 | B23: SEEDS | C23: SUNFLOWER | D23: SUNFLOWER SEEDS | E23: 1.000 | F23: 450 | G23: 450 | I23: CORN GRITS / MEAL | J23: 50 | K23: 50 | L23: =VLOOKUP(I23,Consolidated!B:B,1,0) -> Corn Grits / Meal
A24: 19 | B24: SEEDS | C24: FLAX | D24: FLAX SEEDS (ALSI) | E24: 1.000 | F24: 1250 | G24: 1250 | I24: FLAX SEEDS (ALSI) | J24: 2750 | K24: 2750 | L24: =VLOOKUP(I24,Consolidated!B:B,1,0) -> Flax Seeds (Alsi)
A25: 20 | B25: SEEDS | C25: SUNFLOWER | D25: SUNFLOWER SEEDS | E25: 1.000 | F25: 450 | G25: 450 | I25: GLUCOSE SYRUP / LIQUID GLUCOSE | J25: 300 | K25: 300 | L25: =VLOOKUP(I25,Consolidated!B:B,1,0) -> Glucose Syrup / Liquid Glucose
A26: 21 | B26: SEEDS | C26: CHIA | D26: BLACK CHIA SEEDS | E26: 1.000 | F26: 500 | G26: 500 | I26: HEALTHY CHOICE ROASTED PUMPKIN SEEDS 100 G | J26: 30 | K26: 3 | L26: =VLOOKUP(I26,Consolidated!B:B,1,0) -> Healthy Choice Roasted Pumpkin Seeds 100 g
A27: 22 | B27: SEEDS | C27: SUNFLOWER | D27: SUNFLOWER SEEDS | E27: 1.000 | F27: 900 | G27: 900 | I27: HEALTHY CHOICE ROASTED PUMPKIN SEEDS 200 G | J27: 50 | K27: 10 | L27: =VLOOKUP(I27,Consolidated!B:B,1,0) -> Healthy Choice Roasted Pumpkin Seeds 200 g
A28: 23 | B28: SEEDS | C28: WATERMELON | D28: WATER MELON SEED | E28: 1.000 | F28: 2400 | G28: 2400 | I28: HEALTHY CHOICE ROASTED SUNFLOWER SEEDS 200 G | J28: 100 | K28: 20 | L28: =VLOOKUP(I28,Consolidated!B:B,1,0) -> Healthy Choice Roasted Sunflower Seeds 200 g
A29: 24 | B29: SEEDS | C29: SUNFLOWER | D29: SUNFLOWER SEEDS | E29: 1.000 | F29: 450 | G29: 450 | I29: INDIAN GREEN RAISINS | J29: 10 | K29: 10 | L29: =VLOOKUP(I29,Consolidated!B:B,1,0) -> Indian Green Raisins
A30: 25 | B30: SEEDS | C30: PUMPKIN | D30: PUMPKIN SEED ( 5% ) | E30: 1.000 | F30: 900 | G30: 900 | I30: MAIZE STARCH | J30: 500 | K30: 500 | L30: =VLOOKUP(I30,Consolidated!B:B,1,0) -> Maize Starch
A31: 26 | B31: SEEDS | C31: CHIA | D31: BLACK CHIA SEEDS | E31: 1.000 | F31: 1000 | G31: 1000 | I31: NACHNI ATTA | J31: 30 | K31: 30 | L31: =VLOOKUP(I31,Consolidated!B:B,1,0) -> Nachni Atta
A32: 27 | B32: SEEDS | C32: SUNFLOWER | D32: SUNFLOWER SEEDS | E32: 1.000 | F32: 450 | G32: 450 | I32: NUTS & SEED MIX | J32: 5.18 | K32: 5.18 | L32: =VLOOKUP(I32,Consolidated!B:B,1,0) -> Nuts & Seed Mix
A33: 28 | B33: SEEDS | C33: PUMPKIN | D33: PUMPKIN SEED ( 5% ) | E33: 1.000 | F33: 1050 | G33: 1050 | I33: PALM OIL | J33: 13 | K33: 13 | L33: =VLOOKUP(I33,Consolidated!B:B,1,0) -> Palm Oil
A34: 29 | B34: ALMOND | C34: ALMOND - KERNELS | D34: AMERICAN ALMONDS RUNNING 25-27 COUNT | E34: 1.000 | F34: 360 | G34: 360 | I34: PISTA MAGAZ SPLIT CALIFORNIA | J34: 110 | K34: 110 | L34: =VLOOKUP(I34,Consolidated!B:B,1,0) -> Pista Magaz Split California
... A44: 39 | B44: ALMOND | C44: ALMOND - KERNELS | D44: CARNIVAL ALMONDS 250 GM | E44: 0.250 | F44: 6 | G44: 1.5 | I44: WHEAT ATTA | J44: 1111 | K44: 1139.7 | L44: =VLOOKUP(I44,Consolidated!B:B,1,0) -> Wheat Atta
A45: 40 | B45: PISTA | C45: PISTA - KERNEL | D45: PISTA MAGAZ SPLIT CALIFORNIA | E45: 1.000 | F45: 45 | G45: 45 | I45: Grand Total | J45: 68809.02 | K45: 65088.4
A46: 41 | B46: DATES | C46: SEEDLESS | D46: AL BARAKAH PREMIUM SEEDLESS DATES 500G | E46: 0.500 | F46: 1456 | G46: 728
A47: 42 | B47: SEEDS | C47: PUMPKIN | D47: PUMPKIN SEED ( 5% ) | E47: 1.000 | F47: 2375 | G47: 2375
A48: 43 | B48: DATES | C48: SEEDLESS | D48: AL BARAKAH PREMIUM SEEDLESS DATES 500G | E48: 0.500 | F48: 768 | G48: 384
A49: 44 | B49: ALMOND | C49: ALMOND - KERNELS | D49: AMERICAN ALMONDS RUNNING 25-27 COUNT | E49: 1.000 | F49: 64.5 | G49: 64.5
A50: 45 | B50: PISTA | C50: PISTA - INSHELL | D50: CALIFORNIA PISTA INSHELL ROASTED AND SALTED | E50: 1.000 | F50: 7 | G50: 7
A51: 46 | B51: DATES | C51: EMIRATES | D51: AL BARAKAH PREMIUM EMIRATES DATES 500G | E51: 0.500 | F51: 1456 | G51: 728
A52: 47 | B52: DATES | C52: SEEDLESS | D52: AL BARAKAH PREMIUM SEEDLESS DATES 500G | E52: 0.500 | F52: 432 | G52: 216
A53: 48 | B53: SEEDS | C53: CHIA | D53: BLACK CHIA SEEDS | E53: 1.000 | F53: 500 | G53: 500
...

Sheet Production
A1: Fresh Stock Entries
A2: Warehouse: | D2: Floor:
A3: Submitted By: | D3: Submitted At:
A5: S.No | B5: Category (Group) | C5: Subcategory | D5: Item Description | E5: UOM (kg) | F5: Units | G5: Total Weight (kg) | J5: Row Labels | K5: Sum of Units | L5: Sum of Total Weight (kg)
A6: 1 | B6: PEANUTS | C6: PEANUT - COATED | D6: COATED PEANUT BASE | E6: 1.000 | F6: 617 | G6: 617 | J6: AMERICAN ALMONDS RUNNING 25-27 COUNT | K6: 270 | L6: 270 | M6: =VLOOKUP(J6,Consolidated!B:B,1,0) -> American Almonds Running 25-27 count
A7: 2 | B7: SEEDS | C7: SUNFLOWER | D7: SUNFLOWER SEEDS ROASTED | E7: 1.000 | F7: 229 | G7: 229 | J7: BARBEQUE SEASONING | K7: 19 | L7: 19 | M7: =VLOOKUP(J7,Consolidated!B:B,1,0) -> Barbeque seasoning
A8: 3 | B8: SEEDS | C8: PUMPKIN | D8: PUMPKIN SEEDS ROASTED | E8: 1.000 | F8: 179 | G8: 179 | J8: BLACK CHIA SEEDS | K8: 60 | L8: 60 | M8: =VLOOKUP(J8,Consolidated!B:B,1,0) -> Black Chia Seeds
A9: 4 | B9: ALMOND | C9: ALMOND - KERNELS | D9: AMERICAN ALMONDS RUNNING 25-27 COUNT | E9: 1.000 | F9: 270 | G9: 270 | J9: CASHEW 240 | K9: 20 | L9: 20 | M9: =VLOOKUP(J9,Consolidated!B:B,1,0) -> Cashew 240
A10: 5 | B10: DEHYDRATED FRUITS | C10: DF - BERRIES | D10: DRIED GOJI BERRY | E10: 1.000 | F10: 12 | G10: 12 | J10: CASHEW 320 | K10: 240 | L10: 240 | M10: =VLOOKUP(J10,Consolidated!B:B,1,0) -> Cashew 320
A11: 6 | B11: ALMOND | C11: ALMOND - KERNELS | D11: ROASTED & SALTED ALMONDS | E11: 1.000 | F11: 8 | G11: =8+60+48 -> 116 | H11: Addedd 60+48 kg witch is missing | J11: CASHEW TUKDA | K11: 2.4 | L11: 2.4 | M11: =VLOOKUP(J11,Consolidated!B:B,1,0) -> Cashew Tukda
A12: 7 | B12: APRICOT | C12: APRICOT - TURKEY | D12: TURKEY APRICOT NO 3 | E12: 1.000 | F12: 13 | G12: 13 | H12: Please Remove This… This in Service Material - 125 kg Recived And 115 Kg Was Dispatch To The Customer | J12: CHATPATA SEASONING | K12: 74.4 | L12: 74.4 | M12: =VLOOKUP(J12,Consolidated!B:B,1,0) -> Chatpata Seasoning
A13: 8 | B13: RAISIN | C13: RAISIN - INDIAN | D13: INDIAN GREEN RAISINS | E13: 1.000 | F13: 6 | G13: 6 | J13: Cocktail Mix | K13: 170 | L13: 170 | M13: =VLOOKUP(J13,Consolidated!B:B,1,0) -> Cocktail Mix
A14: 9 | B14: CRANBERRY | C14: CRANBERRY - WHOLE | D14: CHATPATA CRANBERRY | E14: 1.000 | F14: 334.08 | G14: 334.08 | J14: FLAX SEEDS (ALSI) | K14: 310 | L14: 310 | M14: =VLOOKUP(J14,Consolidated!B:B,1,0) -> Flax Seeds (Alsi)
A15: 10 | B15: CASHEW | C15: CASHEW - KERNEL | D15: BLACK PEPPER CASHEW | E15: 1.000 | F15: 249 | G15: 249 | J15: GLUCOSE SYRUP / LIQUID GLUCOSE | K15: 100 | L15: 100 | M15: =VLOOKUP(J15,Consolidated!B:B,1,0) -> Glucose Syrup / Liquid Glucose
A16: 11 | B16: TRAIL MIX | C16: TRAIL MIX | D16: BREAKFAST MIX BULK | E16: 1.000 | F16: 200 | G16: 200 | J16: INDIAN GREEN RAISINS | K16: 6 | L16: 6 | M16: =VLOOKUP(J16,Consolidated!B:B,1,0) -> Indian Green Raisins
A17: 12 | B17: ALMOND | C17: ALMOND - KERNELS | D17: SMOKED ALMONDS | E17: 1.000 | F17: 128.2 | G17: 128.2 | J17: REFINED FINE POWDER IODIZED SALT PRIME - TPL | K17: 45 | L17: 45 | M17: =VLOOKUP(J17,Consolidated!B:B,1,0) -> Refined Fine Powder Iodized Salt Prime - TPL
A18: 13 | B18: MISCELLANEOUS - RM | C18: OTHER MISC | D18: GLUCOSE SYRUP / LIQUID GLUCOSE | E18: 1.000 | F18: 100 | G18: 100 | J18: RICE ATTA | K18: 50 | L18: 50 | M18: =VLOOKUP(J18,Consolidated!B:B,1,0) -> Rice Atta
A19: 14 | B19: CASHEW | C19: CASHEW - KERNEL | D19: ROASTED & SALTED CASHEW | E19: 1.000 | F19: 200 | G19: 200 | J19: TURKEY APRICOT NO 3 | K19: 13 | L19: 13 | M19: =VLOOKUP(J19,Consolidated!B:B,1,0) -> Turkey Apricot No 3
A20: 15 | B20: CASHEW | C20: CASHEW - KERNEL | D20: BLACK PEPPER CASHEW | E20: 1.000 | F20: 332 | G20: 332 | J20: COATED PEANUT BASE | K20: 617 | L20: 617 | M20: =VLOOKUP(J20,Consolidated!B:B,1,0) -> Coated Peanut Base
A21: 16 | B21: SEASONING | C21: SEASONING | D21: BLACK PEPPER SEASONING | E21: 1.000 | F21: 3 | G21: 3 | J21: SUNFLOWER SEEDS ROASTED | K21: 229 | L21: 229 | M21: =VLOOKUP(J21,Consolidated!B:B,1,0) -> Sunflower Seeds Roasted
A22: 17 | B22: SEASONING | C22: SEASONING | D22: PUDINA SEASONING | E22: 1.000 | F22: 3.1 | G22: 3.1 | J22: PUMPKIN SEEDS ROASTED | K22: 179 | L22: 179 | M22: =VLOOKUP(J22,Consolidated!B:B,1,0) -> Pumpkin Seeds Roasted
A23: 18 | B23: SALT | C23: SALT | D23: PINK SALT. | E23: 1.000 | F23: 1.4 | G23: 1.4 | J23: DRIED GOJI BERRY | K23: 12 | L23: 12 | M23: =VLOOKUP(J23,Consolidated!B:B,1,0) -> Dried Goji Berry
A24: 19 | B24: SEASONING | C24: SEASONING | D24: URBAN PLATTER ARABIC GUM POWDER | E24: 1.000 | F24: 2.1 | G24: 2.1 | J24: ROASTED & SALTED ALMONDS | K24: 8 | L24: 116 | M24: =VLOOKUP(J24,Consolidated!B:B,1,0) -> Roasted & Salted Almonds
... A45: 40 | B45: PEANUTS | C45: PEANUT - WHOLE | D45: PEANUTS | E45: 1.000 | F45: 550 | G45: 550 | J45: Black Raisin Seedless | K45: 0.25 | L45: 0.25 | M45: =VLOOKUP(J45,Consolidated!B:B,1,0) -> #N/A
A46: 41 | B46: MISCELLANEOUS - RM | C46: FLOUR | D46: RICE ATTA | E46: 1.000 | F46: 50 | G46: 50 | J46: Grand Total | K46: 4894.54 | L46: 5002.54
D47: Black Raisin Seedless | F47: 0.25 | G47: 0.25 | H47: Missing Item
D48: Cocktail Mix | F48: 170 | G48: 170 | H48: Missing Item
A49: TOTAL | F49: 4724.29 | G49: 4724.29

Sheet Packing Area
A1: Fresh Stock Entries
A2: Warehouse: | D2: Floor:
A3: Submitted By: | D3: Submitted At:
A5: S.No | B5: Category (Group) | C5: Subcategory | D5: Item Description | E5: UOM (kg) | F5: Units | G5: Total Weight (kg) | J5: Row Labels | K5: Sum of Units | L5: Sum of Total Weight (kg)
A6: 1 | B6: SEEDS | C6: WATERMELON | D6: WATERMELON SEEDS ROASTED | E6: 1.000 | F6: 291.28 | G6: 291.28 | J6: BLACK CHIA SEEDS | K6: 157.03 | L6: 157.03 | M6: =VLOOKUP(J6,Consolidated!B:B,1,0) -> Black Chia Seeds
A7: 2 | B7: SEEDS | C7: WATERMELON | D7: WATERMELON SEEDS ROASTED | E7: 1.000 | F7: 297.4 | G7: 297.4 | J7: SUNFLOWER SEEDS ROASTED | K7: 2325.65 | L7: 2325.65 | M7: =VLOOKUP(J7,Consolidated!B:B,1,0) -> Sunflower Seeds Roasted
A8: 3 | B8: SEEDS | C8: WATERMELON | D8: WATERMELON SEEDS ROASTED | E8: 1.000 | F8: 269.2 | G8: 269.2 | J8: ROASTED & SALTED ALMONDS | K8: 36.64 | L8: 36.64 | M8: =VLOOKUP(J8,Consolidated!B:B,1,0) -> Roasted & Salted Almonds
A9: 4 | B9: SEEDS | C9: WATERMELON | D9: WATERMELON SEEDS ROASTED | E9: 1.000 | F9: 291.06 | G9: 291.06 | J9: CHATPATA CRANBERRY | K9: 126.88 | L9: 126.88 | M9: =VLOOKUP(J9,Consolidated!B:B,1,0) -> Chatpata Cranberry
A10: 5 | B10: SEEDS | C10: WATERMELON | D10: WATERMELON SEEDS ROASTED | E10: 1.000 | F10: 233.46 | G10: 233.46 | J10: BLACK PEPPER CASHEW | K10: 12.29 | L10: 12.29 | M10: =VLOOKUP(J10,Consolidated!B:B,1,0) -> BLACK PEPPER CASHEW
A11: 6 | B11: SEEDS | C11: WATERMELON | D11: WATERMELON SEEDS ROASTED | E11: 1.000 | F11: 340.48 | G11: 340.48 | J11: BREAKFAST MIX BULK | K11: 30.66 | L11: 30.66 | M11: =VLOOKUP(J11,Consolidated!B:B,1,0) -> Breakfast Mix Bulk
A12: 7 | B12: SEEDS | C12: PUMPKIN | D12: PUMPKIN SEED ( 5% ) | E12: 1.000 | F12: 254.29 | G12: 254.29 | J12: ROASTED & SALTED CASHEW | K12: 94.67 | L12: 94.67 | M12: =VLOOKUP(J12,Consolidated!B:B,1,0) -> Roasted & Salted Cashew
A13: 8 | B13: SEEDS | C13: PUMPKIN | D13: PUMPKIN SEED ( 5% ) | E13: 1.000 | F13: 201.6 | G13: 201.6 | J13: DRIED BLUEBERRY | K13: 28.9 | L13: 28.9 | M13: =VLOOKUP(J13,Consolidated!B:B,1,0) -> Dried Blueberry
A14: 9 | B14: SEEDS | C14: PUMPKIN | D14: PUMPKIN SEED ( 5% ) | E14: 1.000 | F14: 156.1 | G14: 156.1 | J14: WATERMELON SEEDS ROASTED | K14: 2585.84 | L14: 2585.84 | M14: =VLOOKUP(J14,Consolidated!B:B,1,0) -> Watermelon Seeds Roasted
A15: 10 | B15: PISTA | C15: PISTA - INSHELL | D15: CALIFORNIA PISTA INSHELL ROASTED AND SALTED | E15: 1.000 | F15: 36.4 | G15: 36.4 | J15: PUMPKIN SEED ( 5% ) | K15: 851.9 | L15: 851.9 | M15: =VLOOKUP(J15,Consolidated!B:B,1,0) -> Pumpkin Seed ( 5% )
A16: 11 | B16: SEEDS | C16: SUNFLOWER | D16: SUNFLOWER SEEDS ROASTED | E16: 1.000 | F16: 234.62 | G16: 234.62 | J16: CALIFORNIA PISTA INSHELL ROASTED AND SALTED | K16: 44.08 | L16: 44.08 | M16: =VLOOKUP(J16,Consolidated!B:B,1,0) -> California Pista Inshell Roasted and Salted
A17: 12 | B17: SEEDS | C17: SUNFLOWER | D17: SUNFLOWER SEEDS ROASTED | E17: 1.000 | F17: 102.9 | G17: 102.9 | J17: AL BARAKAH PREMIUM EMIRATE DATE SEEDLESS 500GM | K17: 68 | L17: 34 | M17: =VLOOKUP(J17,Consolidated!B:B,1,0) -> Al Barakah Premium Emirate Date Seedless 500gm
... A32: 27 | B32: DATES | C32: KHALAS | D32: Al Barakah Emirates Dates 500 Gm | E32: 0.500 | F32: 3818 | G32: 1909 | J32: PREMIA CASHEW SALTED 100 GM | K32: 3321 | L32: 332.1 | M32: =VLOOKUP(J32,Consolidated!B:B,1,0) -> Premia Cashew Salted 100 Gm
A33: 28 | B33: DATES | C33: EMIRATES | D33: PL CLASSIC DATES 500G | E33: 0.500 | F33: 1760 | G33: 880 | H33: this is classic Date | J33: PREMIA CASHEW BLACK PEPPER 100 GM | K33: 4067 | L33: 406.7 | M33: =VLOOKUP(J33,Consolidated!B:B,1,0) -> Premia Cashew Black Pepper 100 Gm
B34: DATES | D34: PL CLASSIC DATES 500G | E34: 0.500 | F34: 51 | G34: =+F34*E34 -> 25.5 | H34: Missing Qty | J34: PREMIA ALMOND SALTED 100 GM | K34: 144 | L34: 14.4 | M34: =VLOOKUP(J34,Consolidated!B:B,1,0) -> Premia Almond Salted 100 Gm
A35: 29 | B35: SEEDS | C35: CHIA | D35: HEALTHY CHOICE CHIA SEEDS 200 G | E35: 0.200 | F35: 2000 | G35: 400 | J35: PREMIA ALMONDS SMOKD-100G | K35: 1956 | L35: 195.6 | M35: =VLOOKUP(J35,Consolidated!B:B,1,0) -> PREMIA ALMONDS SMOKD-100G
A36: 30 | B36: SEEDS | C36: PUMPKIN | D36: HEALTHY CHOICE ROASTED PUMPKIN SEEDS 200 G | E36: 0.200 | F36: 8200 | G36: 1640 | J36: PREMIA CHATPATA CRANBERRY 100GM | K36: 11880 | L36: 1188 | M36: =VLOOKUP(J36,Consolidated!B:B,1,0) -> Premia Chatpata Cranberry 100gm
A37: 31 | B37: SEEDS | C37: SUNFLOWER | D37: HEALTHY CHOICE ROASTED SUNFLOWER SEEDS 200 G | E37: 0.200 | F37: 6600 | G37: 1320 | J37: HEALTHY CHOICE ROASTED PUMPKIN SEEDS 100 G | K37: 16150 | L37: 1615 | M37: =VLOOKUP(J37,Consolidated!B:B,1,0) -> Healthy Choice Roasted Pumpkin Seeds 100 g
A38: 32 | B38: SEEDS | C38: WATERMELON | D38: HEALTHY CHOICE ROASTED WATERMELON SEEDS 200 G | E38: 0.200 | F38: 2050 | G38: 410 | J38: HEALTHY CHOICE ROASTED SUNFLOWER SEEDS 100 G | K38: 6395 | L38: 639.5 | M38: =VLOOKUP(J38,Consolidated!B:B,1,0) -> Healthy Choice Roasted Sunflower Seeds 100 g
A39: 33 | B39: SEEDS | C39: WATERMELON | D39: HEALTHY CHOICE ROASTED WATERMELON SEEDS 100 G | E39: 0.100 | F39: 2900 | G39: 290 | J39: GOOD LIFE ALMOND 500 G PP | K39: 100 | L39: 50 | M39: =VLOOKUP(J39,Consolidated!B:B,1,0) -> GOOD LIFE ALMOND 500 g PP
A40: 34 | B40: TRAIL MIX | C40: TRAIL MIX | D40: PREMIA BREAKFAST MIX 100G (100005226) | E40: 0.100 | F40: 2150 | G40: 215 | J40: HEALTHY CHOICE CHIA SEEDS 100 G | K40: 30 | L40: 3 | M40: =VLOOKUP(J40,Consolidated!B:B,1,0) -> Healthy Choice Chia Seeds 100 g
A41: 35 | B41: TRAIL MIX | C41: TRAIL MIX | D41: PREMIA NUTS & SEEDS MIX 100G (100005422) | E41: 0.100 | F41: 450 | G41: 45 | J41: HEALTHY CHOICE 5 IN 1 SEEDS MIX BULK | K41: 634.87 | L41: 634.87 | M41: =VLOOKUP(J41,Consolidated!B:B,1,0) -> Healthy Choice 5 in 1 Seeds Mix Bulk
A42: 36 | B42: TRAIL MIX | C42: TRAIL MIX | D42: PREMIA TRAIL MIX 100G (100005227) | E42: 0.100 | F42: 50 | G42: 5 | J42: NUTS & SEED MIX | K42: 177.13 | L42: 177.13 | M42: =VLOOKUP(J42,Consolidated!B:B,1,0) -> Nuts & Seed Mix
A43: 37 | B43: PRUNES | C43: PRUNES - PITTED | D43: PREMIA PRUNES 100GM | E43: 0.100 | F43: 195 | G43: 19.5 | J43: CALIFORNIA PISTA INSHELL | K43: 342.95 | L43: 342.95 | M43: =VLOOKUP(J43,Consolidated!B:B,1,0) -> California Pista Inshell
A44: 38 | B44: CRANBERRY | C44: CRANBERRY - WHOLE | D44: DRIED CRANBERRY 100GM | E44: 0.100 | F44: 96 | G44: 9.6 | J44: AFGHAN MUNAKKA / ABJOSH 1X2 | K44: 94.3 | L44: 94.3 | M44: =VLOOKUP(J44,Consolidated!B:B,1,0) -> Afghan Munakka / Abjosh 1X2
A45: 39 | B45: BLUEBERRY | C45: BLUEBERRY - PLAIN | D45: DRIED BLUEBERRY 100GM | E45: 0.100 | F45: 192 | G45: 19.2 | J45: DRIED CRANBERRY WHOLE | K45: 117.39 | L45: 117.39 | M45: =VLOOKUP(J45,Consolidated!B:B,1,0) -> Dried Cranberry Whole
A46: 40 | B46: CRANBERRY | C46: CRANBERRY - SLICED | D46: QWIKSNAX CRANBERRIES CHTPTA MIX-30G | E46: 0.030 | F46: 850 | G46: 25.5 | J46: DRIED CRANBERRY SLICED | K46: 14.2 | L46: 14.2 | M46: =VLOOKUP(J46,Consolidated!B:B,1,0) -> Dried Cranberry Sliced
... A58: 52 | B58: SEEDS | C58: CHIA | D58: HEALTHY CHOICE CHIA SEEDS 100 G | E58: 0.100 | F58: 30 | G58: 3 | J58: CHEESE MAKHANA | K58: 1.4 | L58: 1.4 | M58: =VLOOKUP(J58,Consolidated!B:B,1,0) -> Cheese Makhana
A59: 53 | D59: HEALTHY CHOICE 5 IN 1 SEEDS MIX BULK | E59: 1.000 | F59: 225.49 | G59: 225.49 | J59: CHATPATA SNACK MIX | K59: 1.4 | L59: 1.4 | M59: =VLOOKUP(J59,Consolidated!B:B,1,0) -> CHATPATA SNACK MIX
A60: 54 | D60: HEALTHY CHOICE 5 IN 1 SEEDS MIX BULK | E60: 1.000 | F60: 167.39 | G60: 167.39 | J60: PIZZA FLAVOURED COATED PEANUTS | K60: 2.1 | L60: 2.1 | M60: =VLOOKUP(J60,Consolidated!B:B,1,0) -> Pizza Flavoured Coated Peanuts
A61: 55 | D61: HEALTHY CHOICE 5 IN 1 SEEDS MIX BULK | E61: 1.000 | F61: 241.99 | G61: 241.99 | J61: MEXICAN FLAVOURED COATED PEANUTS | K61: 1.25 | L61: 1.25 | M61: =VLOOKUP(J61,Consolidated!B:B,1,0) -> Mexican Flavoured Coated Peanuts
A62: 56 | B62: TRAIL MIX | C62: TRAIL MIX | D62: NUTS & SEED MIX | E62: 1.000 | F62: 177.13 | G62: 177.13 | J62: CHEESE TOMATO FLAVOURED COATED PEANUTS | K62: 30.15 | L62: 30.15 | M62: =VLOOKUP(J62,Consolidated!B:B,1,0) -> Cheese Tomato Flavoured Coated Peanuts
A63: 57 | B63: CRANBERRY | C63: CRANBERRY - SLICED | D63: CHATPATA CRANBERRY | E63: 1.000 | F63: 126.88 | G63: 126.88 | J63: KRACK NUT COATED PEANUTS THAI FIRANGI 1 KG | K63: 10 | L63: 10 | M63: =VLOOKUP(J63,Consolidated!B:B,1,0) -> Krack Nut Coated Peanuts Thai Firangi 1 Kg
A64: 58 | B64: CASHEW | C64: CASHEW - KERNEL | D64: ROASTED & SALTED CASHEW | E64: 1.000 | F64: 61.87 | G64: 61.87 | J64: PUDINA COATED KRACKNUT | K64: 4.48 | L64: 4.48 | M64: =VLOOKUP(J64,Consolidated!B:B,1,0) -> PUDINA COATED KRACKNUT
A65: 59 | B65: PISTA | C65: PISTA - INSHELL | D65: CALIFORNIA PISTA INSHELL | E65: 1.000 | F65: 332.95 | G65: 332.95 | J65: PL CLASSIC DATES 500G | K65: 1811 | L65: 905.5 | M65: =VLOOKUP(J65,Consolidated!B:B,1,0) -> PL CLASSIC DATES 500G
A66: 60 | B66: RAISIN | C66: RAISIN - ABJOSH | D66: AFGHAN MUNAKKA / ABJOSH 1X2 | E66: 1.000 | F66: 82.3 | G66: 82.3 | J66: Al Barakah Emirates Dates 500 Gm | K66: 3818 | L66: 1909 | M66: =VLOOKUP(J66,Consolidated!B:B,1,0) -> Al Barakah Emirates Dates 500 Gm
...

Sheet Cold Rej
A1: Off Grade Rejection - A185 - COLD
A3: Category | B3: Subcategory | C3: Description | D3: Package Size (kg) | E3: Units | F3: Total Weight (kg) | G3: Date Submitted | H3: Submitted By
A4: ALMOND | B4: ALMOND - KERNELS | C4: AMERICAN ALMONDS RUNNING 25-27 COUNT | D4: 1.000 | E4: 20 | F4: 19.80 | G4: 2/22/2026, 8:18:55 PM | H4: RAJUPAIKRAO
C6: TOTAL: | E6: 20 | F6: 19.80

Sheet Cold Area
A1: Category | B1: Subcategory | C1: Description | D1: Package Size (kg) | E1: Units | F1: Total Weight (kg) | G1: Date Submitted | H1: Submitted By | J1: Row Labels | K1: Sum of Total Weight (kg)
A2: SEASONING | B2: SEASONING | C2: LIME CHILLI SEASONING | D2: 1.000 | E2: 5 | F2: 5 | G2: 2/22/2026, 8:18:55 PM | H2: RAJUPAIKRAO | J2: 10KG AL BARAKAH DATE POWDER V2 | K2: 70 | L2: =VLOOKUP(J2,[1]CFPL!$B:$E,1,0) -> #N/A
A3: SEASONING | B3: SEASONING | C3: URBAN PLATTER CHIPOTLE SEASONING | D3: 1.000 | E3: 4 | F3: 4 | G3: 2/22/2026, 8:18:55 PM | H3: RAJUPAIKRAO | J3: AFGHAN BLACK RAISINS SEEDLESS 1*2 | K3: 3000 | L3: =VLOOKUP(J3,[1]CFPL!$B:$E,1,0) -> Afghan Black Raisins Seedless 1*2
A4: ALMOND | B4: ALMOND - KERNELS | C4: SMOKED ALMONDS | D4: 1.000 | E4: 201 | F4: 201 | G4: 2/22/2026, 8:18:55 PM | H4: RAJUPAIKRAO | J4: AFGHAN MUNAKKA / ABJOSH 1X2 | K4: 146.8 | L4: =VLOOKUP(J4,[1]CFPL!$B:$E,1,0) -> Afghan Munakka / Abjosh 1X2
A5: PREMIUM NUTS | B5: PECAN NUTS | C5: PECANS NUTS INSHELL | D5: 1.000 | E5: 75 | F5: 75 | G5: 2/22/2026, 8:18:55 PM | H5: RAJUPAIKRAO | J5: AFGHAN SHANDUKHANI GREEN RAISINS | K5: 0.95 | L5: =VLOOKUP(J5,[1]CFPL!$B:$E,1,0) -> Afghan Shandukhani Green Raisins
A6: GENERAL | B6: OTHER | C6: KOKAM PHOOL | D6: 1.000 | E6: 12 | F6: 12 | G6: 2/22/2026, 8:18:55 PM | H6: RAJUPAIKRAO | J6: AL BARAKAH DATE SYRUP(1.15KG X 12) | K6: 2939.4 | L6: =VLOOKUP(J6,[1]CFPL!$B:$E,1,0) -> AL BARAKAH DATE SYRUP(1.15KG X 12)
A7: TRAIL MIX | B7: TRAIL MIX | C7: CRUNCHY CARAMEL TRAIL MIX | D7: 1.000 | E7: 144 | F7: 143.7 | G7: 2/22/2026, 8:18:55 PM | H7: RAJUPAIKRAO | J7: AL BARAKAH DATES SYRUP (400G PACKING) | K7: 104 | L7: =VLOOKUP(J7,[1]CFPL!$B:$E,1,0) -> AL BARAKAH DATES SYRUP (400G Packing)
A8: BLUEBERRY | B8: BLUEBERRY - PLAIN | C8: DRIED BLUEBERRY | D8: 1.000 | E8: 2 | F8: 1.5 | G8: 2/22/2026, 8:18:55 PM | H8: RAJUPAIKRAO | J8: ALMOND BLANCHED, WHOLE | K8: 10 | L8: =VLOOKUP(J8,[1]CFPL!$B:$E,1,0) -> Almond Blanched, whole
A9: MISCELLANEOUS - RM | B9: OTHER MISC | C9: PURE MAPLE SYRUP | D9: 1.000 | E9: 8 | F9: 8 | G9: 2/22/2026, 8:18:55 PM | H9: RAJUPAIKRAO | J9: ALMONDS KERNEL CUBE CUT | K9: 3.97 | L9: =VLOOKUP(J9,[1]CFPL!$B:$E,1,0) -> Almonds Kernel Cube Cut
A10: DEHYDRATED FRUITS | B10: DF - ORANGE | C10: DRIED ORANGE PEEL | D10: 1.000 | E10: 10 | F10: 9.7 | G10: 2/22/2026, 8:18:55 PM | H10: RAJUPAIKRAO | J10: AMERICAN ALMOND DOUBLE TONCH | K10: 60.12 | L10: =VLOOKUP(J10,[1]CFPL!$B:$E,1,0) -> American Almond Double Tonch
A11: DEHYDRATED FRUITS | B11: DF - MANGO | C11: DEHYDRATED MANGO | D11: 1.000 | E11: 82 | F11: 82.2 | G11: 2/22/2026, 8:18:55 PM | H11: RAJUPAIKRAO | J11: AMERICAN ALMONDS KERNAL SANORA | K11: 50 | L11: =VLOOKUP(J11,[1]CFPL!$B:$E,1,0) -> American Almonds Kernal Sanora
A12: MISCELLANEOUS - RM | B12: OTHER MISC | C12: COCOA POWDER | D12: 1.000 | E12: 4 | F12: 4 | G12: 2/22/2026, 8:18:55 PM | H12: RAJUPAIKRAO | J12: AMERICAN ALMONDS RUNNING 25-27 COUNT | K12: 336.2 | L12: =VLOOKUP(J12,[1]CFPL!$B:$E,1,0) -> American Almonds Running 25-27 count
A13: SEASONING | B13: SEASONING | C13: CHILLI POWDER | D13: 1.000 | E13: 1 | F13: 1 | G13: 2/22/2026, 8:18:55 PM | H13: RAJUPAIKRAO | J13: ANARDANA CHURAN | K13: 50 | L13: =VLOOKUP(J13,[1]CFPL!$B:$E,1,0) -> Anardana Churan
... A19: PRUNES | B19: PRUNES - PITTED | C19: DRIED PRUNES (PITTED) | D19: 1.000 | E19: 23 | F19: 22.68 | G19: 2/22/2026, 8:18:55 PM | H19: RAJUPAIKRAO | J19: CASHEW KERNEL | K19: 20 | L19: =VLOOKUP(J19,[1]CFPL!$B:$E,1,0) -> Cashew Kernel
A20: SEASONING | B20: SEASONING | C20: SMOKEY BBQ SEASONING | D20: 1.000 | E20: 25 | F20: 25 | G20: 2/22/2026, 8:18:55 PM | H20: RAJUPAIKRAO | I20: Please Change Add- Chilli Garlic Seassoning | J20: CHAT MASALA MDH | K20: 1.5 | L20: =VLOOKUP(J20,[1]CFPL!$B:$E,1,0) -> CHAT MASALA MDH
A21: SEASONING | B21: SEASONING | C21: PIZZA SEASONING | D21: 1.000 | E21: 1 | F21: 1 | G21: 2/22/2026, 8:18:55 PM | H21: RAJUPAIKRAO | J21: CHATPATA CRANBERRY | K21: 1.1 | L21: =VLOOKUP(J21,[1]CFPL!$B:$E,1,0) -> Chatpata Cranberry
A22: SEASONING | B22: SEASONING | C22: CHILLI GARLIC MASALA SEASONING | D22: 1.000 | E22: 25 | F22: 25 | G22: 2/22/2026, 8:18:55 PM | H22: RAJUPAIKRAO | J22: CHATPATA SEASONING | K22: 37.4 | L22: =VLOOKUP(J22,[1]CFPL!$B:$E,1,0) -> Chatpata Seasoning
A23: PISTA | B23: PISTA - KERNEL | C23: PISTA KERNEL | D23: 1.000 | E23: 275 | F23: 274.62 | G23: 2/22/2026, 8:18:55 PM | H23: RAJUPAIKRAO | J23: CHEESY TOMATO SEASONING 2 (PR01895/001) | K23: 10 | L23: =VLOOKUP(J23,[1]CFPL!$B:$E,1,0) -> Cheesy Tomato Seasoning 2 (PR01895/001)
A24: DEHYDRATED FRUITS | B24: DF - ORANGE | C24: ORANGE PEEL | D24: 1.000 | E24: 195 | F24: 195 | G24: 2/22/2026, 8:18:55 PM | H24: RAJUPAIKRAO | J24: CHILLI GARLIC MASALA SEASONING | K24: 25 | L24: =VLOOKUP(J24,[1]CFPL!$B:$E,1,0) -> Chilli Garlic Masala Seasoning
A25: ALMOND | B25: ALMOND - BROKEN | C25: ALMONDS KERNEL CUBE CUT | D25: 1.000 | E25: 4 | F25: 3.97 | G25: 2/22/2026, 8:18:55 PM | H25: RAJUPAIKRAO | J25: CHILLI POWDER | K25: 1 | L25: =VLOOKUP(J25,[1]CFPL!$B:$E,1,0) -> Chilli Powder
A26: CASHEW | B26: CASHEW - KERNEL | C26: CASHEW KERNEL | D26: 1.000 | E26: 10 | F26: 10 | G26: 2/22/2026, 8:18:55 PM | H26: RAJUPAIKRAO | J26: CHIPOTLE HONEY SEASONING | K26: 135 | L26: =VLOOKUP(J26,[1]CFPL!$B:$E,1,0) -> Chipotle Honey Seasoning
A27: ALMOND | B27: ALMOND - KERNELS | C27: ALMOND BLANCHED, WHOLE | D27: 1.000 | E27: 10 | F27: 10 | G27: 2/22/2026, 8:18:55 PM | H27: RAJUPAIKRAO | J27: COATING MIX | K27: 25 | L27: =VLOOKUP(J27,[1]CFPL!$B:$E,1,0) -> Coating Mix
A28: SEEDS | B28: HEMP | C28: HEMP SEEDS | D28: 1.000 | E28: 52 | F28: 52.45 | G28: 2/22/2026, 8:18:55 PM | H28: RAJUPAIKRAO | J28: COCKTAIL MIX | K28: 1.9 | L28: =VLOOKUP(J28,[1]CFPL!$B:$E,1,0) -> Cocktail Mix
A29: PREMIUM NUTS | B29: PECAN NUTS | C29: PECAN NUTS | D29: 1.000 | E29: 37 | F29: 37.2 | G29: 2/22/2026, 8:18:55 PM | H29: RAJUPAIKRAO | J29: COCOA POWDER | K29: 4 | L29: =VLOOKUP(J29,[1]CFPL!$B:$E,1,0) -> Cocoa Powder
A30: RAISIN | B30: RAISIN - SHANDUKHANI | C30: AFGHAN SHANDUKHANI GREEN RAISINS | D30: 1.000 | E30: 1 | F30: 0.95 | G30: 2/22/2026, 8:18:55 PM | H30: RAJUPAIKRAO | J30: CRANBERRY SLICE APPLE INFUSED | K30: 215.46 | L30: =VLOOKUP(J30,[1]CFPL!$B:$E,1,0) -> Cranberry Slice Apple Infused
A31: CRANBERRY | B31: CRANBERRY - WHOLE | C31: CHATPATA CRANBERRY | D31: 1.000 | E31: 1 | F31: 1.1 | G31: 2/22/2026, 8:18:55 PM | H31: RAJUPAIKRAO | J31: CRUNCHY CARAMEL TRAIL MIX | K31: 143.7 | L31: =VLOOKUP(J31,[1]CFPL!$B:$E,1,0) -> Crunchy Caramel Trail Mix
A32: WALNUT | B32: WALNUT - KERNEL | C32: EZ WALNUT WHOLE LOOSE | D32: 1.000 | E32: 1 | F32: 0.85 | G32: 2/22/2026, 8:18:55 PM | H32: RAJUPAIKRAO | J32: DARK COMPOUND CHIPS | K32: 51.2 | L32: =VLOOKUP(J32,[1]CFPL!$B:$E,1,0) -> Dark Compound Chips
... A63: BLUEBERRY | B63: BLUEBERRY - APPLE INFUSED | C63: DRIED BLUEBERRY APPLE INFUSED | D63: 1.000 | E63: 45 | F63: 45.35 | G63: 2/22/2026, 8:18:55 PM | H63: RAJUPAIKRAO | J63: PECANS NUTS INSHELL | K63: 129.4 | L63: =VLOOKUP(J63,[1]CFPL!$B:$E,1,0) -> Pecans Nuts Inshell
A64: SEASONING | B64: SEASONING | C64: TANDOORI SEASONING | D64: 1.000 | E64: 2 | F64: 2 | G64: 2/22/2026, 8:18:55 PM | H64: RAJUPAIKRAO | I64: 2 kg only | J64: PERI PERI MARINATION SEASONING | K64: 76.5 | L64: =VLOOKUP(J64,[1]CFPL!$B:$E,1,0) -> Peri Peri Marination Seasoning
A65: SEASONING | B65: SEASONING | C65: URBAN PLATTER CHIPOTLE SEASONING | D65: 1.000 | E65: 1 | F65: 0.9 | G65: 2/22/2026, 8:18:55 PM | H65: RAJUPAIKRAO | J65: PINK SALT. | K65: 5 | L65: =VLOOKUP(J65,[1]CFPL!$B:$E,1,0) -> Pink Salt.
A66: PREMIUM NUTS | B66: PECAN NUTS | C66: PECAN NUTS | D66: 1.000 | E66: 141 | F66: 141 | G66: 2/22/2026, 8:18:55 PM | H66: RAJUPAIKRAO | J66: PISTA IRANI INSHELL ROASTED AND SALTED | K66: 50 | L66: =VLOOKUP(J66,[1]CFPL!$B:$E,1,0) -> Pista Irani Inshell Roasted and Salted
A67: SEASONING | B67: SEASONING | C67: URBAN PLATTER SOYA CHAAP SEASONING | D67: 1.000 | E67: 2 | F67: 1.6 | G67: 2/22/2026, 8:18:55 PM | H67: RAJUPAIKRAO | J67: PISTA KERNEL | K67: 376.52 | L67: =VLOOKUP(J67,[1]CFPL!$B:$E,1,0) -> Pista Kernel
A68: RAISIN | B68: RAISIN - ABJOSH | C68: AFGHAN MUNAKKA / ABJOSH 1X2 | D68: 1.000 | E68: 2 | F68: 2.4 | G68: 2/22/2026, 8:18:55 PM | H68: RAJUPAIKRAO | J68: PIZZA SEASONING | K68: 26 | L68: =VLOOKUP(J68,[1]CFPL!$B:$E,1,0) -> Pizza Seasoning
A69: ALMOND | B69: ALMOND - KERNELS | C69: SMOKED ALMONDS | D69: 1.000 | E69: 440 | F69: 440 | G69: 2/22/2026, 8:18:55 PM | H69: RAJUPAIKRAO | J69: PREGEFLO C100 | K69: 1340 | L69: =VLOOKUP(J69,[1]CFPL!$B:$E,1,0) -> PREGEFLO C100
A70: MISCELLANEOUS - RM | B70: OTHER MISC | C70: DARK COMPOUND CHIPS | D70: 1.000 | E70: 51 | F70: 51.2 | G70: 2/22/2026, 8:18:55 PM | H70: RAJUPAIKRAO | J70: PUDINA SEASONING | K70: 155 | L70: =VLOOKUP(J70,[1]CFPL!$B:$E,1,0) -> Pudina seasoning
A71: SALT | B71: SALT | C71: BLACK SALT, KALA NAMAK - CRYSTAL | D71: 1.000 | E71: 14 | F71: 14 | G71: 2/22/2026, 8:18:55 PM | H71: RAJUPAIKRAO | J71: PUMPKIN SEED ( 5% ) | K71: 25500 | L71: =VLOOKUP(J71,[1]CFPL!$B:$E,1,0) -> Pumpkin Seed ( 5% )
A72: SALT | B72: SALT | C72: BLACK SALT, KALA NAMAK - CRYSTAL | D72: 1.000 | E72: 18 | F72: 18 | G72: 2/22/2026, 8:18:55 PM | H72: RAJUPAIKRAO | J72: PURE MAPLE SYRUP | K72: 8 | L72: =VLOOKUP(J72,[1]CFPL!$B:$E,1,0) -> Pure Maple Syrup
A73: PREMIUM NUTS | B73: MACADAMIA NUTS | C73: MACADAMIA ROASTED - SIZE 4L | D73: 1.000 | E73: 11 | F73: 11.34 | G73: 2/22/2026, 8:18:55 PM | H73: RAJUPAIKRAO | J73: ROASTED BLANCHED PEANUT WHOLE | K73: 535 | L73: =VLOOKUP(J73,[1]CFPL!$B:$E,1,0) -> ROASTED BLANCHED PEANUT WHOLE
A74: SEASONING | B74: SEASONING | C74: CHAT MASALA MDH | D74: 1.000 | E74: 2 | F74: 1.5 | G74: 2/22/2026, 8:18:55 PM | H74: RAJUPAIKRAO | J74: SIDCOT STARCH | K74: 900 | L74: =VLOOKUP(J74,[1]CFPL!$B:$E,1,0) -> SIDCOT STARCH
A75: SEASONING | B75: SEASONING | C75: PUDINA SEASONING | D75: 1.000 | E75: 35 | F75: 35 | G75: 2/22/2026, 8:18:55 PM | H75: RAJUPAIKRAO | J75: SMOKED ALMONDS | K75: 641 | L75: =VLOOKUP(J75,[1]CFPL!$B:$E,1,0) -> Smoked Almonds
...
