Workbook

Sheet Compiled
H1: =SUBTOTAL(9,H4:H20119) -> 249547.49 | I1: =SUBTOTAL(9,I4:I20119) -> 993777.59 | J1: =SUBTOTAL(9,J4:J20119) -> 0 | K1: =SUBTOTAL(9,K4:K20119) -> 0 | L1: =SUBTOTAL(9,L4:L20119) -> 0 | M1: =SUBTOTAL(9,M4:M20119) -> 0 | N1: =SUBTOTAL(9,N4:N20119) -> 249547.49 | O1: =SUBTOTAL(9,O4:O20119) -> 993777.59
C2: Physical Closing Stock as on 22nd Feb, 2026. | H2: Units/Factories Stock | J2: Inovice done but material not dispatched | L2: Material Dispatched W/O Invoice | N2: Total
A3: Company | B3: Sr.No. | C3: ITEM | D3: FG/RM | E3: GROUP | F3: Sub-group | G3: PACK SIZE | H3: Total Qty. in Units | I3: Total Qty. in KG | J3: Total Qty. in Units | K3: Total Qty. in KG | L3: Total Qty. in Units | M3: Total Qty. in KG | N3: Total Qty. in Units | O3: Total Qty. in KG
A4: CDPL | B4: 1 | C4: AFREEN DATES | D4: RM | E4: DATES | F4: Afreen | G4: 1 | H4: {=VLOOKUP(C4,CDPL!B:AN,{38,39},0)} -> 0 | I4: 0 | J4: 0 | K4: 0 | L4: 0 | M4: 0 | N4: =(H4+L4)-J4 -> 0 | O4: =(I4+M4)-K4 -> 0
A5: CDPL | B5: 2 | C5: Al Barakah Ajwa Jumbo Dates | D5: RM | E5: DATES | F5: Ajwa | G5: 1 | H5: {=VLOOKUP(C5,CDPL!B:AN,{38,39},0)} -> 0 | I5: 0 | J5: 0 | K5: 0 | L5: 0 | M5: 0 | N5: =(H5+L5)-J5 -> 0 | O5: =(I5+M5)-K5 -> 0
A6: CDPL | B6: 3 | C6: Royal Delight Ajwa Dates 5 Kgs | D6: RM | E6: DATES | F6: Ajwa | G6: 1 | H6: {=VLOOKUP(C6,CDPL!B:AN,{38,39},0)} -> 0 | I6: 365 | J6: 0 | K6: 0 | L6: 0 | M6: 0 | N6: =(H6+L6)-J6 -> 0 | O6: =(I6+M6)-K6 -> 365
A7: CDPL | B7: 4 | C7: Wet Dates Ajwa | D7: RM | E7: DATES | F7: Ajwa | G7: 1 | H7: {=VLOOKUP(C7,CDPL!B:AN,{38,39},0)} -> 0 | I7: 6410 | J7: 0 | K7: 0 | L7: 0 | M7: 0 | N7: =(H7+L7)-J7 -> 0 | O7: =(I7+M7)-K7 -> 6410
A8: CDPL | B8: 5 | C8: Wet Dates Ajwa Premium | D8: RM | E8: DATES | F8: Ajwa | G8: 1 | H8: {=VLOOKUP(C8,CDPL!B:AN,{38,39},0)} -> 0 | I8: 0 | J8: 0 | K8: 0 | L8: 0 | M8: 0 | N8: =(H8+L8)-J8 -> 0 | O8: =(I8+M8)-K8 -> 0
A9: CDPL | B9: 6 | C9: CURATE DATES AJWA IMP SAUDI 500G | D9: FG | E9: DATES | F9: Ajwa | G9: 0.5 | H9: {=VLOOKUP(C9,CDPL!B:AN,{38,39},0)} -> 13 | I9: 6.5 | J9: 0 | K9: 0 | L9: 0 | M9: 0 | N9: =(H9+L9)-J9 -> 13 | O9: =(I9+M9)-K9 -> 6.5
A10: CDPL | B10: 7 | C10: Royal Delight Ajwa Dates 400gm | D10: FG | E10: DATES | F10: Ajwa | G10: 0.4 | H10: {=VLOOKUP(C10,CDPL!B:AN,{38,39},0)} -> 0 | I10: 0 | J10: 0 | K10: 0 | L10: 0 | M10: 0 | N10: =(H10+L10)-J10 -> 0 | O10: =(I10+M10)-K10 -> 0
A11: CDPL | B11: 8 | C11: Royal Delight Ajwa Dates 500 Gm | D11: FG | E11: DATES | F11: Ajwa | G11: 0.5 | H11: {=VLOOKUP(C11,CDPL!B:AN,{38,39},0)} -> 0 | I11: 0 | J11: 0 | K11: 0 | L11: 0 | M11: 0 | N11: =(H11+L11)-J11 -> 0 | O11: =(I11+M11)-K11 -> 0
A12: CDPL | B12: 9 | C12: Royal Delight Ajwa Large 250g | D12: FG | E12: DATES | F12: Ajwa | G12: 0.25 | H12: {=VLOOKUP(C12,CDPL!B:AN,{38,39},0)} -> 0 | I12: 0 | J12: 0 | K12: 0 | L12: 0 | M12: 0 | N12: =(H12+L12)-J12 -> 0 | O12: =(I12+M12)-K12 -> 0
A13: CDPL | B13: 10 | C13: UP Ajwa Dates 500gm | D13: FG | E13: DATES | F13: Ajwa | G13: 0.5 | H13: {=VLOOKUP(C13,CDPL!B:AN,{38,39},0)} -> 0 | I13: 0 | J13: 0 | K13: 0 | L13: 0 | M13: 0 | N13: =(H13+L13)-J13 -> 0 | O13: =(I13+M13)-K13 -> 0
A14: CDPL | B14: 11 | C14: KINGDOM OF DATES AMARY DATES | D14: RM | E14: DATES | F14: Amary | G14: 1 | H14: {=VLOOKUP(C14,CDPL!B:AN,{38,39},0)} -> 0 | I14: 0 | J14: 0 | K14: 0 | L14: 0 | M14: 0 | N14: =(H14+L14)-J14 -> 0 | O14: =(I14+M14)-K14 -> 0
A15: CDPL | B15: 12 | C15: Wet Dates (Amary) | D15: RM | E15: DATES | F15: Amary | G15: 1 | H15: {=VLOOKUP(C15,CDPL!B:AN,{38,39},0)} -> 0 | I15: 0 | J15: 0 | K15: 0 | L15: 0 | M15: 0 | N15: =(H15+L15)-J15 -> 0 | O15: =(I15+M15)-K15 -> 0
... A277: CDPL | B277: 269 | C277: Organic Wanan Premium Large | D277: RM | E277: DATES | F277: Wanan | G277: 1 | H277: {=VLOOKUP(C277,CDPL!B:AN,{38,39},0)} -> 0 | I277: 162.5 | J277: 0 | K277: 0 | L277: 0 | M277: 0 | N277: =(H277+L277)-J277 -> 0 | O277: =(I277+M277)-K277 -> 162.5
A278: CFPL | B278: 1 | C278: Almond Blanched Sliced | D278: RM | E278: ALMOND | F278: Almond - Broken | G278: 1 | H278: {=VLOOKUP(C278,CFPL!B:AN,{38,39},0)} -> 8.24 | I278: 20.24 | J278: 0 | K278: 0 | L278: 0 | M278: 0 | N278: =(H278+L278)-J278 -> 8.24 | O278: =(I278+M278)-K278 -> 20.24
A279: CFPL | B279: 2 | C279: Almond Powder | D279: RM | E279: ALMOND | F279: Almond - Broken | G279: 1 | H279: {=VLOOKUP(C279,CFPL!B:AN,{38,39},0)} -> 130.39 | I279: 210.68 | J279: 0 | K279: 0 | L279: 0 | M279: 0 | N279: =(H279+L279)-J279 -> 130.39 | O279: =(I279+M279)-K279 -> 210.68
A280: CFPL | B280: 3 | C280: Almond Sliced | D280: RM | E280: ALMOND | F280: Almond - Broken | G280: 1 | H280: {=VLOOKUP(C280,CFPL!B:AN,{38,39},0)} -> 159.67 | I280: 159.67 | J280: 0 | K280: 0 | L280: 0 | M280: 0 | N280: =(H280+L280)-J280 -> 159.67 | O280: =(I280+M280)-K280 -> 159.67
A281: CFPL | B281: 4 | C281: Almonds Kernel Cube Cut | D281: RM | E281: ALMOND | F281: Almond - Broken | G281: 1 | H281: {=VLOOKUP(C281,CFPL!B:AN,{38,39},0)} -> 0 | I281: 29.17 | J281: 0 | K281: 0 | L281: 0 | M281: 0 | N281: =(H281+L281)-J281 -> 0 | O281: =(I281+M281)-K281 -> 29.17
A282: CFPL | B282: 5 | C282: American Almonds Tukda | D282: RM | E282: ALMOND | F282: Almond - Broken | G282: 1 | H282: {=VLOOKUP(C282,CFPL!B:AN,{38,39},0)} -> 0 | I282: 30.4 | J282: 0 | K282: 0 | L282: 0 | M282: 0 | N282: =(H282+L282)-J282 -> 0 | O282: =(I282+M282)-K282 -> 30.4
A283: CFPL | B283: 6 | C283: BLANCHED ALMOND FLOUR | D283: RM | E283: ALMOND | F283: Almond - Broken | G283: 1 | H283: {=VLOOKUP(C283,CFPL!B:AN,{38,39},0)} -> 0 | I283: 0 | J283: 0 | K283: 0 | L283: 0 | M283: 0 | N283: =(H283+L283)-J283 -> 0 | O283: =(I283+M283)-K283 -> 0
A284: CFPL | B284: 7 | C284: Diced Almond | D284: RM | E284: ALMOND | F284: Almond - Broken | G284: 1 | H284: {=VLOOKUP(C284,CFPL!B:AN,{38,39},0)} -> 539.368 | I284: 539.32 | J284: 0 | K284: 0 | L284: 0 | M284: 0 | N284: =(H284+L284)-J284 -> 539.368 | O284: =(I284+M284)-K284 -> 539.32
A285: CFPL | B285: 8 | C285: Slivered Almonds | D285: RM | E285: ALMOND | F285: Almond - Broken | G285: 1 | H285: {=VLOOKUP(C285,CFPL!B:AN,{38,39},0)} -> 0 | I285: 0 | J285: 0 | K285: 0 | L285: 0 | M285: 0 | N285: =(H285+L285)-J285 -> 0 | O285: =(I285+M285)-K285 -> 0
A286: CFPL | B286: 9 | C286: AUSTRALIAN ALMOND INSHELL | D286: RM | E286: ALMOND | F286: Almond - Inshell | G286: 1 | H286: {=VLOOKUP(C286,CFPL!B:AN,{38,39},0)} -> 0 | I286: 0 | J286: 0 | K286: 0 | L286: 0 | M286: 0 | N286: =(H286+L286)-J286 -> 0 | O286: =(I286+M286)-K286 -> 0
A287: CFPL | B287: 10 | C287: California Inshell Almonds | D287: RM | E287: ALMOND | F287: Almond - Inshell | G287: 1 | H287: {=VLOOKUP(C287,CFPL!B:AN,{38,39},0)} -> 0 | I287: 0 | J287: 0 | K287: 0 | L287: 0 | M287: 0 | N287: =(H287+L287)-J287 -> 0 | O287: =(I287+M287)-K287 -> 0
A288: CFPL | B288: 11 | C288: Independent Almond Inshell | D288: RM | E288: ALMOND | F288: Almond - Inshell | G288: 1 | H288: {=VLOOKUP(C288,CFPL!B:AN,{38,39},0)} -> 0 | I288: 0 | J288: 0 | K288: 0 | L288: 0 | M288: 0 | N288: =(H288+L288)-J288 -> 0 | O288: =(I288+M288)-K288 -> 0
A289: CFPL | B289: 12 | C289: Almond Blanched, whole | D289: RM | E289: ALMOND | F289: Almond - Kernels | G289: 1 | H289: {=VLOOKUP(C289,CFPL!B:AN,{38,39},0)} -> 160.44 | I289: 477.535 | J289: 0 | K289: 0 | L289: 0 | M289: 0 | N289: =(H289+L289)-J289 -> 160.44 | O289: =(I289+M289)-K289 -> 477.535
... A2194: CFPL | B2194: 1897 | C2194: Dry Kokam Phool | D2194: RM | E2194: DEHYDRATED FRUITS | F2194: DF - Other | G2194: 1 | H2194: {=VLOOKUP(C2194,CFPL!B:AN,{38,39},0)} -> 0 | I2194: 12 | J2194: 0 | K2194: 0 | L2194: 0 | M2194: 0 | N2194: =(H2194+L2194)-J2194 -> 0 | O2194: =(I2194+M2194)-K2194 -> 12
A2195: CFPL | B2195: 1898 | C2195: Organic Cinnamon-Samruddhi Organic | E2195: SPICES | F2195: Whole Spices | G2195: 1 | H2195: {=VLOOKUP(C2195,CFPL!B:AN,{38,39},0)} -> 0 | I2195: 0 | J2195: 0 | K2195: 0 | L2195: 0 | M2195: 0 | N2195: =(H2195+L2195)-J2195 -> 0 | O2195: =(I2195+M2195)-K2195 -> 0
A2196: CFPL | B2196: 1899 | C2196: Smoke BBQ Coated Peanut | D2196: FG | E2196: PEANUTS | F2196: Peanut - Coated | G2196: 1 | H2196: {=VLOOKUP(C2196,CFPL!B:AN,{38,39},0)} -> 0 | I2196: 0 | J2196: 0 | K2196: 0 | L2196: 0 | M2196: 0 | N2196: =(H2196+L2196)-J2196 -> 0 | O2196: =(I2196+M2196)-K2196 -> 0
A2197: CFPL | B2197: 1900 | C2197: SNACK MASALA MIX | D2197: FG | E2197: TRAIL MIX | F2197: Trail Mix | G2197: 0.25 | H2197: {=VLOOKUP(C2197,CFPL!B:AN,{38,39},0)} -> 1.7 | I2197: 1.7 | J2197: 0 | K2197: 0 | L2197: 0 | M2197: 0 | N2197: =(H2197+L2197)-J2197 -> 1.7 | O2197: =(I2197+M2197)-K2197 -> 1.7
A2198: CFPL | B2198: 1901 | C2198: Udid dal | D2198: RM | E2198: MISCELLANEOUS - RM | F2198: Other Misc | G2198: 1 | H2198: {=VLOOKUP(C2198,CFPL!B:AN,{38,39},0)} -> 0 | I2198: 0 | J2198: 0 | K2198: 0 | L2198: 0 | M2198: 0 | N2198: =(H2198+L2198)-J2198 -> 0 | O2198: =(I2198+M2198)-K2198 -> 0
A2199: CFPL | B2199: 1902 | C2199: Rhine Valley Barbeque Trail Mix | D2199: FG | E2199: TRAIL MIX | F2199: Trail Mix | G2199: 1 | H2199: {=VLOOKUP(C2199,CFPL!B:AN,{38,39},0)} -> 0 | I2199: 0 | J2199: 0 | K2199: 0 | L2199: 0 | M2199: 0 | N2199: =(H2199+L2199)-J2199 -> 0 | O2199: =(I2199+M2199)-K2199 -> 0
A2200: CFPL | B2200: 1903 | C2200: Rhine Valley Black Pepper Trail Mix | D2200: FG | E2200: TRAIL MIX | F2200: Trail Mix | G2200: 1 | H2200: {=VLOOKUP(C2200,CFPL!B:AN,{38,39},0)} -> 0 | I2200: 0 | J2200: 0 | K2200: 0 | L2200: 0 | M2200: 0 | N2200: =(H2200+L2200)-J2200 -> 0 | O2200: =(I2200+M2200)-K2200 -> 0
A2201: CFPL | B2201: 1904 | C2201: Rhine Valley Peri Peri Trail Mix | D2201: FG | E2201: TRAIL MIX | F2201: Trail Mix | G2201: 1 | H2201: {=VLOOKUP(C2201,CFPL!B:AN,{38,39},0)} -> 0 | I2201: 0 | J2201: 0 | K2201: 0 | L2201: 0 | M2201: 0 | N2201: =(H2201+L2201)-J2201 -> 0 | O2201: =(I2201+M2201)-K2201 -> 0
A2202: CFPL | B2202: 1905 | C2202: Rhine Valley Himalayan Pink Salt Trail Mix | D2202: FG | E2202: TRAIL MIX | F2202: Trail Mix | G2202: 1 | H2202: {=VLOOKUP(C2202,CFPL!B:AN,{38,39},0)} -> 0 | I2202: 0 | J2202: 0 | K2202: 0 | L2202: 0 | M2202: 0 | N2202: =(H2202+L2202)-J2202 -> 0 | O2202: =(I2202+M2202)-K2202 -> 0
A2203: CFPL | B2203: 1906 | C2203: Bluberry Powder | D2203: RM | E2203: MISCELLANEOUS - RM | F2203: Other Misc | G2203: 1 | H2203: {=VLOOKUP(C2203,CFPL!B:AN,{38,39},0)} -> 0 | I2203: 0 | J2203: 0 | K2203: 0 | L2203: 0 | M2203: 0 | N2203: =(H2203+L2203)-J2203 -> 0 | O2203: =(I2203+M2203)-K2203 -> 0
A2204: CFPL | B2204: 1907 | C2204: PEPPER PEANUT | D2204: FG | E2204: PEANUTS | F2204: Peanut - Whole | G2204: 1 | H2204: {=VLOOKUP(C2204,CFPL!B:AN,{38,39},0)} -> 0 | I2204: 0 | J2204: 0 | K2204: 0 | L2204: 0 | M2204: 0 | N2204: =(H2204+L2204)-J2204 -> 0 | O2204: =(I2204+M2204)-K2204 -> 0
A2205: CFPL | B2205: 1908 | C2205: Roasted salted peanuts | D2205: FG | E2205: PEANUTS | F2205: Peanut - Whole | G2205: 1 | H2205: {=VLOOKUP(C2205,CFPL!B:AN,{38,39},0)} -> 0 | I2205: 0 | J2205: 0 | K2205: 0 | L2205: 0 | M2205: 0 | N2205: =(H2205+L2205)-J2205 -> 0 | O2205: =(I2205+M2205)-K2205 -> 0
...

Sheet CFPL
B1: CANDOR FOODS PVT LTD | G1: =SUBTOTAL(9,G4:G149027) -> 3945 | H1: =SUBTOTAL(9,H4:H149027) -> 10585.853 | I1: =SUBTOTAL(9,I4:I149027) -> 17422 | J1: =SUBTOTAL(9,J4:J149027) -> 10940.685 | K1: =SUBTOTAL(9,K4:K149027) -> 18804.4 | L1: =SUBTOTAL(9,L4:L149027) -> 9925.4 | M1: =SUBTOTAL(9,M4:M149027) -> 12630.95 | N1: =SUBTOTAL(9,N4:N149027) -> 8365.15 | ... AN1: =SUBTOTAL(9,AN4:AN149027) -> 425317.54 | AO1: =AN1+CDPL!AN1 -> 993777.59
B2: Stock Take Compilation | D2: 46075 | E2: Location: | G2: W-202 Store | I2: W-202 Lower | K2: W-202 Upper | M2: W-202 1st Floor | O2: W-202 2nd Floor | Q2: W-202 Barline | S2: W-202 Terrace | U2: W-202-Off Grade | W2: A-185 | Y2: A-185 Cold | AA2: A-185 Off-Grade | AC2: A-101 | AE2: Ajustment Pending | AG2: APMC | AI2: Rishi | AK2: Savla | AM2: Total Stock
A3: Sr. No. | B3: ITEM | C3: FG/RM | D3: GROUP | E3: Sub-Group | F3: PACK SIZE | G3: Total Quantity | H3: Qty. in KG | I3: Total Quantity | J3: Qty. in KG | K3: Total Quantity | L3: Qty. in KG | M3: Total Quantity | N3: Qty. in KG | O3: Total Quantity | P3: Qty. in KG | Q3: Total Quantity | R3: Qty. in KG | S3: Total Quantity | T3: Qty. in KG | U3: Total Quantity | V3: Qty. in KG | W3: Total Quantity | X3: Qty. in KG | Y3: Total Quantity | Z3: Qty. in KG | AA3: Total Quantity | AB3: Qty. in KG | AC3: Total Quantity | AD3: Qty. in KG | AE3: Total Quantity | AF3: Qty. in KG | AG3: Total Quantity | AH3: Qty. in KG | AI3: Total Quantity | AJ3: Qty. in KG | AK3: Total Quantity | AL3: Qty. in KG | AM3: Total Quantity | AN3: Qty. in KG
A4: 1 | B4: Almond Blanched Sliced | C4: RM | D4: ALMOND | E4: Almond - Broken | F4: 1 | G4: 0 | H4: 0 | I4: 0 | J4: 0 | K4: 0 | L4: 0 | M4: 0 | N4: 0 | O4: 0 | P4: 0 | Q4: 0 | R4: 0 | S4: 8.24 | T4: 8.24 | U4: 0 | V4: 0 | W4: 0 | X4: 0 | Y4: 0 | Z4: 0 | AA4: 0 | AB4: 0 | AC4: 0 | AD4: 0 | AE4: 0 | AF4: 0 | AG4: 0 | AH4: 12 | AI4: 0 | AJ4: 0 | AK4: 0 | AL4: 0 | AM4: =G4+I4+K4+M4+O4+Q4+S4+AA4+AC4+AE4+AG4+AI4+AK4+U4+W4+Y4 -> 8.24 | AN4: =H4+J4+L4+N4+P4+R4+T4+AB4+AD4+AF4+AH4+AJ4+AL4+V4+X4+Z4 -> 20.24
A5: 2 | B5: Almond Powder | C5: RM | D5: ALMOND | E5: Almond - Broken | F5: 1 | G5: 0 | H5: 0 | I5: 0 | J5: 0 | K5: 0 | L5: 0 | M5: 0 | N5: 0 | O5: 0 | P5: 0 | Q5: 0 | R5: 54.14 | S5: 130.39 | T5: 130.39 | U5: 0 | V5: 0 | W5: 0 | X5: 0 | Y5: 0 | Z5: 0 | AA5: 0 | AB5: 26.15 | AC5: 0 | AD5: 0 | AE5: 0 | AF5: 0 | AG5: 0 | AH5: 0 | AI5: 0 | AJ5: 0 | AK5: 0 | AL5: 0 | AM5: =G5+I5+K5+M5+O5+Q5+S5+AA5+AC5+AE5+AG5+AI5+AK5+U5+W5+Y5 -> 130.39 | AN5: =H5+J5+L5+N5+P5+R5+T5+AB5+AD5+AF5+AH5+AJ5+AL5+V5+X5+Z5 -> 210.68
A6: 3 | B6: Almond Sliced | C6: RM | D6: ALMOND | E6: Almond - Broken | F6: 1 | G6: 0 | H6: 0 | I6: 0 | J6: 0 | K6: 0 | L6: 0 | M6: 0 | N6: 0 | O6: 0 | P6: 0 | Q6: 0 | R6: 0 | S6: 159.67 | T6: 159.67 | U6: 0 | V6: 0 | W6: 0 | X6: 0 | Y6: 0 | Z6: 0 | AA6: 0 | AB6: 0 | AC6: 0 | AD6: 0 | AE6: 0 | AF6: 0 | AG6: 0 | AH6: 0 | AI6: 0 | AJ6: 0 | AK6: 0 | AL6: 0 | AM6: =G6+I6+K6+M6+O6+Q6+S6+AA6+AC6+AE6+AG6+AI6+AK6+U6+W6+Y6 -> 159.67 | AN6: =H6+J6+L6+N6+P6+R6+T6+AB6+AD6+AF6+AH6+AJ6+AL6+V6+X6+Z6 -> 159.67
A7: 4 | B7: Almonds Kernel Cube Cut | C7: RM | D7: ALMOND | E7: Almond - Broken | F7: 1 | G7: 0 | H7: 0 | I7: 0 | J7: 0 | K7: 0 | L7: 0 | M7: 0 | N7: 0 | O7: 0 | P7: 0 | Q7: 0 | R7: 0 | S7: 0 | T7: 0 | U7: 0 | V7: 0 | W7: 0 | X7: 4.6 | Y7: 0 | Z7: 3.97 | AA7: 0 | AB7: 0.6 | AC7: 0 | AD7: 0 | AE7: 0 | AF7: 0 | AG7: 0 | AH7: 20 | AI7: 0 | AJ7: 0 | AK7: 0 | AL7: 0 | AM7: =G7+I7+K7+M7+O7+Q7+S7+AA7+AC7+AE7+AG7+AI7+AK7+U7+W7+Y7 -> 0 | AN7: =H7+J7+L7+N7+P7+R7+T7+AB7+AD7+AF7+AH7+AJ7+AL7+V7+X7+Z7 -> 29.17
A8: 5 | B8: American Almonds Tukda | C8: RM | D8: ALMOND | E8: Almond - Broken | F8: 1 | G8: 0 | H8: 0 | I8: 0 | J8: 0 | K8: 0 | L8: 0 | M8: 0 | N8: 0 | O8: 0 | P8: 0 | Q8: 0 | R8: 0.4 | S8: 0 | T8: 0 | U8: 0 | V8: 0 | W8: 0 | X8: 0 | Y8: 0 | Z8: 0 | AA8: 0 | AB8: 0 | AC8: 0 | AD8: 0 | AE8: 0 | AF8: 0 | AG8: 0 | AH8: 30 | AI8: 0 | AJ8: 0 | AK8: 0 | AL8: 0 | AM8: =G8+I8+K8+M8+O8+Q8+S8+AA8+AC8+AE8+AG8+AI8+AK8+U8+W8+Y8 -> 0 | AN8: =H8+J8+L8+N8+P8+R8+T8+AB8+AD8+AF8+AH8+AJ8+AL8+V8+X8+Z8 -> 30.4
A9: 6 | B9: BLANCHED ALMOND FLOUR | C9: RM | D9: ALMOND | E9: Almond - Broken | F9: 1 | G9: 0 | H9: 0 | I9: 0 | J9: 0 | K9: 0 | L9: 0 | M9: 0 | N9: 0 | O9: 0 | P9: 0 | Q9: 0 | R9: 0 | S9: 0 | T9: 0 | U9: 0 | V9: 0 | W9: 0 | X9: 0 | Y9: 0 | Z9: 0 | AA9: 0 | AB9: 0 | AC9: 0 | AD9: 0 | AE9: 0 | AF9: 0 | AG9: 0 | AH9: 0 | AI9: 0 | AJ9: 0 | AK9: 0 | AL9: 0 | AM9: =G9+I9+K9+M9+O9+Q9+S9+AA9+AC9+AE9+AG9+AI9+AK9+U9+W9+Y9 -> 0 | AN9: =H9+J9+L9+N9+P9+R9+T9+AB9+AD9+AF9+AH9+AJ9+AL9+V9+X9+Z9 -> 0
A10: 7 | B10: Diced Almond | C10: RM | D10: ALMOND | E10: Almond - Broken | F10: 1 | G10: 0 | H10: 0 | I10: 0 | J10: 0 | K10: 0 | L10: 0 | M10: 0 | N10: 0 | O10: 0 | P10: 0 | Q10: 0 | R10: 0 | S10: 539.368 | T10: 539.32 | U10: 0 | V10: 0 | W10: 0 | X10: 0 | Y10: 0 | Z10: 0 | AA10: 0 | AB10: 0 | AC10: 0 | AD10: 0 | AE10: 0 | AF10: 0 | AG10: 0 | AH10: 0 | AI10: 0 | AJ10: 0 | AK10: 0 | AL10: 0 | AM10: =G10+I10+K10+M10+O10+Q10+S10+AA10+AC10+AE10+AG10+AI10+AK10+U10+W10+Y10 -> 539.368 | AN10: =H10+J10+L10+N10+P10+R10+T10+AB10+AD10+AF10+AH10+AJ10+AL10+V10+X10+Z10 -> 539.32
A11: 8 | B11: Slivered Almonds | C11: RM | D11: ALMOND | E11: Almond - Broken | F11: 1 | G11: 0 | H11: 0 | I11: 0 | J11: 0 | K11: 0 | L11: 0 | M11: 0 | N11: 0 | O11: 0 | P11: 0 | Q11: 0 | R11: 0 | S11: 0 | T11: 0 | U11: 0 | V11: 0 | W11: 0 | X11: 0 | Y11: 0 | Z11: 0 | AA11: 0 | AB11: 0 | AC11: 0 | AD11: 0 | AE11: 0 | AF11: 0 | AG11: 0 | AH11: 0 | AI11: 0 | AJ11: 0 | AK11: 0 | AL11: 0 | AM11: =G11+I11+K11+M11+O11+Q11+S11+AA11+AC11+AE11+AG11+AI11+AK11+U11+W11+Y11 -> 0 | AN11: =H11+J11+L11+N11+P11+R11+T11+AB11+AD11+AF11+AH11+AJ11+AL11+V11+X11+Z11 -> 0
A12: 9 | B12: AUSTRALIAN ALMOND INSHELL | C12: RM | D12: ALMOND | E12: Almond - Inshell | F12: 1 | G12: 0 | H12: 0 | I12: 0 | J12: 0 | K12: 0 | L12: 0 | M12: 0 | N12: 0 | O12: 0 | P12: 0 | Q12: 0 | R12: 0 | S12: 0 | T12: 0 | U12: 0 | V12: 0 | W12: 0 | X12: 0 | Y12: 0 | Z12: 0 | AA12: 0 | AB12: 0 | AC12: 0 | AD12: 0 | AE12: 0 | AF12: 0 | AG12: 0 | AH12: 0 | AI12: 0 | AJ12: 0 | AK12: 0 | AL12: 0 | AM12: =G12+I12+K12+M12+O12+Q12+S12+AA12+AC12+AE12+AG12+AI12+AK12+U12+W12+Y12 -> 0 | AN12: =H12+J12+L12+N12+P12+R12+T12+AB12+AD12+AF12+AH12+AJ12+AL12+V12+X12+Z12 -> 0
A13: 10 | B13: California Inshell Almonds | C13: RM | D13: ALMOND | E13: Almond - Inshell | F13: 1 | G13: 0 | H13: 0 | I13: 0 | J13: 0 | K13: 0 | L13: 0 | M13: 0 | N13: 0 | O13: 0 | P13: 0 | Q13: 0 | R13: 0 | S13: 0 | T13: 0 | U13: 0 | V13: 0 | W13: 0 | X13: 0 | Y13: 0 | Z13: 0 | AA13: 0 | AB13: 0 | AC13: 0 | AD13: 0 | AE13: 0 | AF13: 0 | AG13: 0 | AH13: 0 | AI13: 0 | AJ13: 0 | AK13: 0 | AL13: 0 | AM13: =G13+I13+K13+M13+O13+Q13+S13+AA13+AC13+AE13+AG13+AI13+AK13+U13+W13+Y13 -> 0 | AN13: =H13+J13+L13+N13+P13+R13+T13+AB13+AD13+AF13+AH13+AJ13+AL13+V13+X13+Z13 -> 0
A14: 11 | B14: Independent Almond Inshell | C14: RM | D14: ALMOND | E14: Almond - Inshell | F14: 1 | G14: 0 | H14: 0 | I14: 0 | J14: 0 | K14: 0 | L14: 0 | M14: 0 | N14: 0 | O14: 0 | P14: 0 | Q14: 0 | R14: 0 | S14: 0 | T14: 0 | U14: 0 | V14: 0 | W14: 0 | X14: 0 | Y14: 0 | Z14: 0 | AA14: 0 | AB14: 0 | AC14: 0 | AD14: 0 | AE14: 0 | AF14: 0 | AG14: 0 | AH14: 0 | AI14: 0 | AJ14: 0 | AK14: 0 | AL14: 0 | AM14: =G14+I14+K14+M14+O14+Q14+S14+AA14+AC14+AE14+AG14+AI14+AK14+U14+W14+Y14 -> 0 | AN14: =H14+J14+L14+N14+P14+R14+T14+AB14+AD14+AF14+AH14+AJ14+AL14+V14+X14+Z14 -> 0
A15: 12 | B15: Almond Blanched, whole | C15: RM | D15: ALMOND | E15: Almond - Kernels | F15: 1 | G15: 0 | H15: 0 | I15: 0 | J15: 0 | K15: 0 | L15: 0 | M15: 0 | N15: 0 | O15: 0 | P15: 0 | Q15: 0 | R15: 1.675 | S15: 160.44 | T15: 160.44 | U15: 0 | V15: 303.92 | W15: 0 | X15: 0 | Y15: 0 | Z15: 10 | AA15: 0 | AB15: 0 | AC15: 0 | AD15: 0 | AE15: 0 | AF15: 0 | AG15: 0 | AH15: 1.5 | AI15: 0 | AJ15: 0 | AK15: 0 | AL15: 0 | AM15: =G15+I15+K15+M15+O15+Q15+S15+AA15+AC15+AE15+AG15+AI15+AK15+U15+W15+Y15 -> 160.44 | AN15: =H15+J15+L15+N15+P15+R15+T15+AB15+AD15+AF15+AH15+AJ15+AL15+V15+X15+Z15 -> 477.535
... A732: 729 | B732: King Solomon Medjoul Super Jumbo 500gm | C732: FG | D732: DATES | E732: Medjoul-Super Jumbo | F732: 0.5 | G732: 0 | H732: 0 | I732: 0 | J732: 0 | K732: 0 | L732: 0 | M732: 0 | N732: 0 | O732: 0 | P732: 0 | Q732: 0 | R732: 0 | S732: 0 | T732: 0 | U732: 0 | V732: 0 | W732: 0 | X732: 0 | Y732: 0 | Z732: 0 | AA732: 0 | AB732: 0 | AC732: 0 | AD732: 0 | AE732: 0 | AF732: 0 | AG732: 0 | AH732: 0 | AI732: 0 | AJ732: 0 | AK732: 0 | AL732: 0 | AM732: =G732+I732+K732+M732+O732+Q732+S732+AA732+AC732+AE732+AG732+AI732+AK732+U732+W732+Y732 -> 0 | AN732: =H732+J732+L732+N732+P732+R732+T732+AB732+AD732+AF732+AH732+AJ732+AL732+V732+X732+Z732 -> 0
A733: 730 | B733: OFF-GRADE DATES | C733: RM | D733: DATES | E733: OFF-GRADE DATES | F733: 1 | G733: 0 | H733: 0 | I733: 0 | J733: 0 | K733: 0 | L733: 0 | M733: 0 | N733: 0 | O733: 0 | P733: 0 | Q733: 0 | R733: 0 | S733: 0 | T733: 0 | U733: 0 | V733: 5 | W733: 0 | X733: 0 | Y733: 0 | Z733: 0 | AA733: 0 | AB733: 0 | AD733: 9 | AE733: 0 | AF733: 0 | AG733: 0 | AH733: 0 | AI733: 0 | AJ733: 0 | AK733: 0 | AL733: 1835 | AM733: =G733+I733+K733+M733+O733+Q733+S733+AA733+AC733+AE733+AG733+AI733+AK733+U733+W733+Y733 -> 0 | AN733: =H733+J733+L733+N733+P733+R733+T733+AB733+AD733+AF733+AH733+AJ733+AL733+V733+X733+Z733 -> 1849
A734: 731 | B734: Al Barakah Oman 600g | C734: FG | D734: DATES | E734: Oman | F734: 0.6 | G734: 0 | H734: 0 | I734: 0 | J734: 0 | K734: 0 | L734: 0 | M734: 0 | N734: 0 | O734: 0 | P734: 0 | Q734: 0 | R734: 0 | S734: 0 | T734: 0 | U734: 0 | V734: 0 | W734: 0 | X734: 0 | Y734: 0 | Z734: 0 | AA734: 0 | AB734: 0 | AC734: 0 | AD734: 0 | AE734: 0 | AF734: 0 | AG734: 59 | AH734: 35.4 | AI734: 0 | AJ734: 0 | AK734: 0 | AL734: 0 | AM734: =G734+I734+K734+M734+O734+Q734+S734+AA734+AC734+AE734+AG734+AI734+AK734+U734+W734+Y734 -> 59 | AN734: =H734+J734+L734+N734+P734+R734+T734+AB734+AD734+AF734+AH734+AJ734+AL734+V734+X734+Z734 -> 35.4
A735: 732 | B735: Al Barakah Oman Dates 400g | C735: FG | D735: DATES | E735: Oman | F735: 0.4 | G735: 0 | H735: 0 | I735: 0 | J735: 0 | K735: 0 | L735: 0 | M735: 0 | N735: 0 | O735: 0 | P735: 0 | Q735: 0 | R735: 0 | S735: 0 | T735: 0 | U735: 0 | V735: 0 | W735: 0 | X735: 0 | Y735: 0 | Z735: 0 | AA735: 0 | AB735: 0 | AC735: 0 | AD735: 0 | AE735: 0 | AF735: 0 | AG735: 0 | AH735: 0 | AI735: 0 | AJ735: 0 | AK735: 0 | AL735: 0 | AM735: =G735+I735+K735+M735+O735+Q735+S735+AA735+AC735+AE735+AG735+AI735+AK735+U735+W735+Y735 -> 0 | AN735: =H735+J735+L735+N735+P735+R735+T735+AB735+AD735+AF735+AH735+AJ735+AL735+V735+X735+Z735 -> 0
A736: 733 | B736: Al Barakah Oman Dates 500gm Tub | C736: FG | D736: DATES | E736: Oman | F736: 0.5 | G736: 0 | H736: 0 | I736: 0 | J736: 0 | K736: 0 | L736: 0 | M736: 0 | N736: 0 | O736: 0 | P736: 0 | Q736: 0 | R736: 0 | S736: 0 | T736: 0 | U736: 0 | V736: 0 | W736: 0 | X736: 0 | Y736: 0 | Z736: 0 | AA736: 0 | AB736: 0 | AC736: 0 | AD736: 0 | AE736: 0 | AF736: 0 | AG736: 0 | AH736: 0 | AI736: 0 | AJ736: 0 | AK736: 0 | AL736: 0 | AM736: =G736+I736+K736+M736+O736+Q736+S736+AA736+AC736+AE736+AG736+AI736+AK736+U736+W736+Y736 -> 0 | AN736: =H736+J736+L736+N736+P736+R736+T736+AB736+AD736+AF736+AH736+AJ736+AL736+V736+X736+Z736 -> 0
A737: 734 | B737: Bb Royal Omani Dates 500gm | C737: FG | D737: DATES | E737: Oman | F737: 0.5 | G737: 0 | H737: 0 | I737: 0 | J737: 0 | K737: 0 | L737: 0 | M737: 0 | N737: 0 | O737: 0 | P737: 0 | Q737: 0 | R737: 0 | S737: 0 | T737: 0 | U737: 0 | V737: 0 | W737: 0 | X737: 0 | Y737: 0 | Z737: 0 | AA737: 0 | AB737: 0 | AC737: 0 | AD737: 0 | AE737: 0 | AF737: 0 | AG737: 0 | AH737: 0 | AI737: 0 | AJ737: 0 | AK737: 0 | AL737: 0 | AM737: =G737+I737+K737+M737+O737+Q737+S737+AA737+AC737+AE737+AG737+AI737+AK737+U737+W737+Y737 -> 0 | AN737: =H737+J737+L737+N737+P737+R737+T737+AB737+AD737+AF737+AH737+AJ737+AL737+V737+X737+Z737 -> 0
A738: 735 | B738: Carnival Oman Dates 250g | C738: FG | D738: DATES | E738: Oman | F738: 0.25 | G738: 0 | H738: 0 | I738: 0 | J738: 0 | K738: 0 | L738: 0 | M738: 0 | N738: 0 | O738: 0 | P738: 0 | Q738: 0 | R738: 0 | S738: 0 | T738: 0 | U738: 0 | V738: 0 | W738: 0 | X738: 0 | Y738: 0 | Z738: 0 | AA738: 0 | AB738: 0 | AC738: 0 | AD738: 0 | AE738: 0 | AF738: 0 | AG738: 0 | AH738: 0 | AI738: 0 | AJ738: 0 | AK738: 0 | AL738: 0 | AM738: =G738+I738+K738+M738+O738+Q738+S738+AA738+AC738+AE738+AG738+AI738+AK738+U738+W738+Y738 -> 0 | AN738: =H738+J738+L738+N738+P738+R738+T738+AB738+AD738+AF738+AH738+AJ738+AL738+V738+X738+Z738 -> 0
A739: 736 | B739: Oman Dates 250g (1356292) | C739: FG | D739: DATES | E739: Oman | F739: 0.25 | G739: 0 | H739: 0 | I739: 12 | J739: 3 | K739: 0 | L739: 0 | M739: 0 | N739: 0 | O739: 0 | P739: 0 | Q739: 0 | R739: 0 | S739: 0 | T739: 0 | U739: 0 | V739: 0 | W739: 0 | X739: 0 | Y739: 0 | Z739: 0 | AA739: 0 | AB739: 0 | AC739: 0 | AD739: 0 | AE739: 0 | AF739: 0 | AG739: 0 | AH739: 0 | AI739: 0 | AJ739: 0 | AK739: 0 | AL739: 0 | AM739: =G739+I739+K739+M739+O739+Q739+S739+AA739+AC739+AE739+AG739+AI739+AK739+U739+W739+Y739 -> 12 | AN739: =H739+J739+L739+N739+P739+R739+T739+AB739+AD739+AF739+AH739+AJ739+AL739+V739+X739+Z739 -> 3
A740: 737 | B740: Royal Delight Oman Dates 1 Kgs | C740: FG | D740: DATES | E740: Oman | F740: 1 | G740: 0 | H740: 0 | I740: 0 | J740: 0 | K740: 0 | L740: 0 | M740: 0 | N740: 0 | O740: 0 | P740: 0 | Q740: 0 | R740: 0 | S740: 0 | T740: 0 | U740: 0 | V740: 0 | W740: 0 | X740: 0 | Y740: 0 | Z740: 0 | AA740: 0 | AB740: 0 | AC740: 0 | AD740: 0 | AE740: 0 | AF740: 0 | AG740: 0 | AH740: 0 | AI740: 0 | AJ740: 0 | AK740: 0 | AL740: 0 | AM740: =G740+I740+K740+M740+O740+Q740+S740+AA740+AC740+AE740+AG740+AI740+AK740+U740+W740+Y740 -> 0 | AN740: =H740+J740+L740+N740+P740+R740+T740+AB740+AD740+AF740+AH740+AJ740+AL740+V740+X740+Z740 -> 0
A741: 738 | B741: AL Barakah Date Paste | C741: RM | D741: DATES | E741: Paste | F741: 1 | G741: 0 | H741: 0 | I741: 0 | J741: 0 | K741: 0 | L741: 0 | M741: 0 | N741: 0 | O741: 0 | P741: 0 | Q741: 0 | R741: 575 | S741: 0 | T741: 0 | U741: 0 | V741: 0 | W741: 0 | X741: 0 | Y741: 0 | Z741: 0 | AA741: 0 | AB741: 0 | AC741: 0 | AD741: 0 | AE741: 0 | AF741: 0 | AG741: 0 | AH741: 0 | AI741: 0 | AJ741: 0 | AK741: 0 | AL741: 0 | AM741: =G741+I741+K741+M741+O741+Q741+S741+AA741+AC741+AE741+AG741+AI741+AK741+U741+W741+Y741 -> 0 | AN741: =H741+J741+L741+N741+P741+R741+T741+AB741+AD741+AF741+AH741+AJ741+AL741+V741+X741+Z741 -> 575
A742: 739 | B742: AL BARAKAH DATE PASTE (1 KG packing) | C742: RM | D742: DATES | E742: Paste | F742: 1 | G742: 0 | H742: 0 | I742: 0 | J742: 0 | K742: 0 | L742: 0 | M742: 0 | N742: 0 | O742: 0 | P742: 0 | Q742: 0 | R742: 0 | S742: 0 | T742: 0 | U742: 0 | V742: 0 | W742: 0 | X742: 0 | Y742: 0 | Z742: 0 | AA742: 0 | AB742: 0 | AC742: 0 | AD742: 0 | AE742: 0 | AF742: 0 | AG742: 0 | AH742: 0 | AI742: 0 | AJ742: 0 | AK742: 0 | AL742: 0 | AM742: =G742+I742+K742+M742+O742+Q742+S742+AA742+AC742+AE742+AG742+AI742+AK742+U742+W742+Y742 -> 0 | AN742: =H742+J742+L742+N742+P742+R742+T742+AB742+AD742+AF742+AH742+AJ742+AL742+V742+X742+Z742 -> 0
A743: 740 | B743: AL BARAKAH DEHYDRATED DATE POWDER - BULK PACK 10KG | C743: RM | D743: DATES | E743: Powder | F743: 1 | G743: 0 | H743: 970 | I743: 449 | J743: 4490 | K743: 0 | L743: 0 | M743: 0 | N743: 0 | O743: 0 | P743: 0 | Q743: 0 | R743: 0 | S743: 0 | T743: 0 | U743: 0 | V743: 0 | W743: 0 | X743: 0 | Y743: 0 | Z743: 70 | AA743: 0 | AB743: 0 | AC743: 0 | AD743: 0 | AE743: 0 | AF743: 0 | AG743: 0 | AH743: 0 | AI743: 0 | AJ743: 0 | AK743: 0 | AL743: 0 | AM743: =G743+I743+K743+M743+O743+Q743+S743+AA743+AC743+AE743+AG743+AI743+AK743+U743+W743+Y743 -> 449 | AN743: =H743+J743+L743+N743+P743+R743+T743+AB743+AD743+AF743+AH743+AJ743+AL743+V743+X743+Z743 -> 5530
A744: 741 | B744: Al Barakah Dehydrated Date Powder 250g | C744: FG | D744: DATES | E744: Powder | F744: 0.25 | G744: 0 | H744: 0 | I744: 0 | J744: 0 | K744: 0 | L744: 0 | M744: 0 | N744: 0 | O744: 0 | P744: 0 | Q744: 0 | R744: 0 | S744: 0 | T744: 0 | U744: 0 | V744: 14 | W744: 0 | X744: 0 | Y744: 0 | Z744: 0 | AA744: 0 | AB744: 0 | AC744: 0 | AD744: 0 | AE744: 0 | AF744: 0 | AG744: 0 | AH744: 0 | AI744: 0 | AJ744: 0 | AK744: 0 | AL744: 0 | AM744: =G744+I744+K744+M744+O744+Q744+S744+AA744+AC744+AE744+AG744+AI744+AK744+U744+W744+Y744 -> 0 | AN744: =H744+J744+L744+N744+P744+R744+T744+AB744+AD744+AF744+AH744+AJ744+AL744+V744+X744+Z744 -> 14
A745: 742 | B745: Amazon Brand- Vedaka Dry Dates powder 200g | C745: FG | D745: DATES | E745: Powder | F745: 0.2 | G745: 0 | H745: 0 | I745: 0 | J745: 0 | K745: 0 | L745: 0 | M745: 0 | N745: 0 | O745: 0 | P745: 0 | Q745: 0 | R745: 0 | S745: 0 | T745: 0 | U745: 0 | V745: 0 | W745: 0 | X745: 0 | Y745: 0 | Z745: 0 | AA745: 0 | AB745: 0 | AC745: 0 | AD745: 0 | AE745: 0 | AF745: 0 | AG745: 0 | AH745: 0 | AI745: 0 | AJ745: 0 | AK745: 0 | AL745: 0 | AM745: =G745+I745+K745+M745+O745+Q745+S745+AA745+AC745+AE745+AG745+AI745+AK745+U745+W745+Y745 -> 0 | AN745: =H745+J745+L745+N745+P745+R745+T745+AB745+AD745+AF745+AH745+AJ745+AL745+V745+X745+Z745 -> 0
... A1920: 1897 | B1920: Dry Kokam Phool | C1920: RM | D1920: DEHYDRATED FRUITS | E1920: DF - Other | F1920: 1 | G1920: 0 | H1920: 0 | I1920: 0 | J1920: 0 | K1920: 0 | L1920: 0 | M1920: 0 | N1920: 0 | O1920: 0 | P1920: 0 | Q1920: 0 | R1920: 0 | S1920: 0 | T1920: 0 | U1920: 0 | V1920: 0 | W1920: 0 | X1920: 0 | Y1920: 0 | Z1920: 12 | AA1920: 0 | AB1920: 0 | AC1920: 0 | AD1920: 0 | AE1920: 0 | AF1920: 0 | AG1920: 0 | AH1920: 0 | AI1920: 0 | AJ1920: 0 | AK1920: 0 | AL1920: 0 | AM1920: =G1920+I1920+K1920+M1920+O1920+Q1920+S1920+AA1920+AC1920+AE1920+AG1920+AI1920+AK1920+U1920+W1920+Y1920 -> 0 | AN1920: =H1920+J1920+L1920+N1920+P1920+R1920+T1920+AB1920+AD1920+AF1920+AH1920+AJ1920+AL1920+V1920+X1920+Z1920 -> 12
A1921: 1898 | B1921: Organic Cinnamon-Samruddhi Organic | D1921: SPICES | E1921: Whole Spices | F1921: 1 | G1921: 0 | H1921: 0 | I1921: 0 | J1921: 0 | K1921: 0 | L1921: 0 | M1921: 0 | N1921: 0 | O1921: 0 | P1921: 0 | Q1921: 0 | R1921: 0 | S1921: 0 | T1921: 0 | U1921: 0 | V1921: 0 | W1921: 0 | X1921: 0 | Y1921: 0 | Z1921: 0 | AA1921: 0 | AB1921: 0 | AC1921: 0 | AD1921: 0 | AE1921: 0 | AF1921: 0 | AG1921: 0 | AH1921: 0 | AI1921: 0 | AJ1921: 0 | AK1921: 0 | AL1921: 0 | AM1921: =G1921+I1921+K1921+M1921+O1921+Q1921+S1921+AA1921+AC1921+AE1921+AG1921+AI1921+AK1921+U1921+W1921+Y1921 -> 0 | AN1921: =H1921+J1921+L1921+N1921+P1921+R1921+T1921+AB1921+AD1921+AF1921+AH1921+AJ1921+AL1921+V1921+X1921+Z1921 -> 0
A1922: 1899 | B1922: Smoke BBQ Coated Peanut | C1922: FG | D1922: PEANUTS | E1922: Peanut - Coated | F1922: 1 | G1922: 0 | H1922: 0 | I1922: 0 | J1922: 0 | K1922: 0 | L1922: 0 | M1922: 0 | N1922: 0 | O1922: 0 | P1922: 0 | Q1922: 0 | R1922: 0 | S1922: 0 | T1922: 0 | U1922: 0 | V1922: 0 | W1922: 0 | X1922: 0 | Y1922: 0 | Z1922: 0 | AA1922: 0 | AB1922: 0 | AC1922: 0 | AD1922: 0 | AE1922: 0 | AF1922: 0 | AG1922: 0 | AH1922: 0 | AI1922: 0 | AJ1922: 0 | AK1922: 0 | AL1922: 0 | AM1922: =G1922+I1922+K1922+M1922+O1922+Q1922+S1922+AA1922+AC1922+AE1922+AG1922+AI1922+AK1922+U1922+W1922+Y1922 -> 0 | AN1922: =H1922+J1922+L1922+N1922+P1922+R1922+T1922+AB1922+AD1922+AF1922+AH1922+AJ1922+AL1922+V1922+X1922+Z1922 -> 0
A1923: 1900 | B1923: SNACK MASALA MIX | C1923: FG | D1923: TRAIL MIX | E1923: Trail Mix | F1923: 0.25 | G1923: 0 | H1923: 0 | I1923: 0 | J1923: 0 | K1923: 0 | L1923: 0 | M1923: 0 | N1923: 0 | O1923: 0 | P1923: 0 | Q1923: 0 | R1923: 0 | S1923: 0 | T1923: 0 | U1923: 0 | V1923: 0 | W1923: 1.7 | X1923: 1.7 | Y1923: 0 | Z1923: 0 | AA1923: 0 | AB1923: 0 | AC1923: 0 | AD1923: 0 | AE1923: 0 | AF1923: 0 | AG1923: 0 | AH1923: 0 | AI1923: 0 | AJ1923: 0 | AK1923: 0 | AL1923: 0 | AM1923: =G1923+I1923+K1923+M1923+O1923+Q1923+S1923+AA1923+AC1923+AE1923+AG1923+AI1923+AK1923+U1923+W1923+Y1923 -> 1.7 | AN1923: =H1923+J1923+L1923+N1923+P1923+R1923+T1923+AB1923+AD1923+AF1923+AH1923+AJ1923+AL1923+V1923+X1923+Z1923 -> 1.7
A1924: 1901 | B1924: Udid dal | C1924: RM | D1924: MISCELLANEOUS - RM | E1924: Other Misc | F1924: 1 | G1924: 0 | H1924: 0 | I1924: 0 | J1924: 0 | K1924: 0 | L1924: 0 | M1924: 0 | N1924: 0 | O1924: 0 | P1924: 0 | Q1924: 0 | R1924: 0 | S1924: 0 | T1924: 0 | U1924: 0 | V1924: 0 | W1924: 0 | X1924: 0 | Y1924: 0 | Z1924: 0 | AA1924: 0 | AB1924: 0 | AC1924: 0 | AD1924: 0 | AE1924: 0 | AF1924: 0 | AG1924: 0 | AH1924: 0 | AI1924: 0 | AJ1924: 0 | AK1924: 0 | AL1924: 0 | AM1924: =G1924+I1924+K1924+M1924+O1924+Q1924+S1924+AA1924+AC1924+AE1924+AG1924+AI1924+AK1924+U1924+W1924+Y1924 -> 0 | AN1924: =H1924+J1924+L1924+N1924+P1924+R1924+T1924+AB1924+AD1924+AF1924+AH1924+AJ1924+AL1924+V1924+X1924+Z1924 -> 0
A1925: 1902 | B1925: Rhine Valley Barbeque Trail Mix | C1925: FG | D1925: TRAIL MIX | E1925: Trail Mix | F1925: 1 | G1925: 0 | H1925: 0 | I1925: 0 | J1925: 0 | K1925: 0 | L1925: 0 | M1925: 0 | N1925: 0 | O1925: 0 | P1925: 0 | Q1925: 0 | R1925: 0 | S1925: 0 | T1925: 0 | U1925: 0 | V1925: 0 | W1925: 0 | X1925: 0 | Y1925: 0 | Z1925: 0 | AA1925: 0 | AB1925: 0 | AC1925: 0 | AD1925: 0 | AE1925: 0 | AF1925: 0 | AG1925: 0 | AH1925: 0 | AI1925: 0 | AJ1925: 0 | AK1925: 0 | AL1925: 0 | AM1925: =G1925+I1925+K1925+M1925+O1925+Q1925+S1925+AA1925+AC1925+AE1925+AG1925+AI1925+AK1925+U1925+W1925+Y1925 -> 0 | AN1925: =H1925+J1925+L1925+N1925+P1925+R1925+T1925+AB1925+AD1925+AF1925+AH1925+AJ1925+AL1925+V1925+X1925+Z1925 -> 0
A1926: 1903 | B1926: Rhine Valley Black Pepper Trail Mix | C1926: FG | D1926: TRAIL MIX | E1926: Trail Mix | F1926: 1 | G1926: 0 | H1926: 0 | I1926: 0 | J1926: 0 | K1926: 0 | L1926: 0 | M1926: 0 | N1926: 0 | O1926: 0 | P1926: 0 | Q1926: 0 | R1926: 0 | S1926: 0 | T1926: 0 | U1926: 0 | V1926: 0 | W1926: 0 | X1926: 0 | Y1926: 0 | Z1926: 0 | AA1926: 0 | AB1926: 0 | AC1926: 0 | AD1926: 0 | AE1926: 0 | AF1926: 0 | AG1926: 0 | AH1926: 0 | AI1926: 0 | AJ1926: 0 | AK1926: 0 | AL1926: 0 | AM1926: =G1926+I1926+K1926+M1926+O1926+Q1926+S1926+AA1926+AC1926+AE1926+AG1926+AI1926+AK1926+U1926+W1926+Y1926 -> 0 | AN1926: =H1926+J1926+L1926+N1926+P1926+R1926+T1926+AB1926+AD1926+AF1926+AH1926+AJ1926+AL1926+V1926+X1926+Z1926 -> 0
A1927: 1904 | B1927: Rhine Valley Peri Peri Trail Mix | C1927: FG | D1927: TRAIL MIX | E1927: Trail Mix | F1927: 1 | G1927: 0 | H1927: 0 | I1927: 0 | J1927: 0 | K1927: 0 | L1927: 0 | M1927: 0 | N1927: 0 | O1927: 0 | P1927: 0 | Q1927: 0 | R1927: 0 | S1927: 0 | T1927: 0 | U1927: 0 | V1927: 0 | W1927: 0 | X1927: 0 | Y1927: 0 | Z1927: 0 | AA1927: 0 | AB1927: 0 | AC1927: 0 | AD1927: 0 | AE1927: 0 | AF1927: 0 | AG1927: 0 | AH1927: 0 | AI1927: 0 | AJ1927: 0 | AK1927: 0 | AL1927: 0 | AM1927: =G1927+I1927+K1927+M1927+O1927+Q1927+S1927+AA1927+AC1927+AE1927+AG1927+AI1927+AK1927+U1927+W1927+Y1927 -> 0 | AN1927: =H1927+J1927+L1927+N1927+P1927+R1927+T1927+AB1927+AD1927+AF1927+AH1927+AJ1927+AL1927+V1927+X1927+Z1927 -> 0
A1928: 1905 | B1928: Rhine Valley Himalayan Pink Salt Trail Mix | C1928: FG | D1928: TRAIL MIX | E1928: Trail Mix | F1928: 1 | G1928: 0 | H1928: 0 | I1928: 0 | J1928: 0 | K1928: 0 | L1928: 0 | M1928: 0 | N1928: 0 | O1928: 0 | P1928: 0 | Q1928: 0 | R1928: 0 | S1928: 0 | T1928: 0 | U1928: 0 | V1928: 0 | W1928: 0 | X1928: 0 | Y1928: 0 | Z1928: 0 | AA1928: 0 | AB1928: 0 | AC1928: 0 | AD1928: 0 | AE1928: 0 | AF1928: 0 | AG1928: 0 | AH1928: 0 | AI1928: 0 | AJ1928: 0 | AK1928: 0 | AL1928: 0 | AM1928: =G1928+I1928+K1928+M1928+O1928+Q1928+S1928+AA1928+AC1928+AE1928+AG1928+AI1928+AK1928+U1928+W1928+Y1928 -> 0 | AN1928: =H1928+J1928+L1928+N1928+P1928+R1928+T1928+AB1928+AD1928+AF1928+AH1928+AJ1928+AL1928+V1928+X1928+Z1928 -> 0
A1929: 1906 | B1929: Bluberry Powder | C1929: RM | D1929: MISCELLANEOUS - RM | E1929: Other Misc | F1929: 1 | G1929: 0 | H1929: 0 | I1929: 0 | J1929: 0 | K1929: 0 | L1929: 0 | M1929: 0 | N1929: 0 | O1929: 0 | P1929: 0 | Q1929: 0 | R1929: 0 | S1929: 0 | T1929: 0 | U1929: 0 | V1929: 0 | W1929: 0 | X1929: 0 | Y1929: 0 | Z1929: 0 | AA1929: 0 | AB1929: 0 | AC1929: 0 | AD1929: 0 | AE1929: 0 | AF1929: 0 | AG1929: 0 | AH1929: 0 | AI1929: 0 | AJ1929: 0 | AK1929: 0 | AL1929: 0 | AM1929: =G1929+I1929+K1929+M1929+O1929+Q1929+S1929+AA1929+AC1929+AE1929+AG1929+AI1929+AK1929+U1929+W1929+Y1929 -> 0 | AN1929: =H1929+J1929+L1929+N1929+P1929+R1929+T1929+AB1929+AD1929+AF1929+AH1929+AJ1929+AL1929+V1929+X1929+Z1929 -> 0
A1930: 1907 | B1930: PEPPER PEANUT | C1930: FG | D1930: PEANUTS | E1930: Peanut - Whole | F1930: 1 | G1930: 0 | H1930: 0 | I1930: 0 | J1930: 0 | K1930: 0 | L1930: 0 | M1930: 0 | N1930: 0 | O1930: 0 | P1930: 0 | Q1930: 0 | R1930: 0 | S1930: 0 | T1930: 0 | U1930: 0 | V1930: 0 | W1930: 0 | X1930: 0 | Y1930: 0 | Z1930: 0 | AA1930: 0 | AB1930: 0 | AC1930: 0 | AD1930: 0 | AE1930: 0 | AF1930: 0 | AG1930: 0 | AH1930: 0 | AI1930: 0 | AJ1930: 0 | AK1930: 0 | AL1930: 0 | AM1930: =G1930+I1930+K1930+M1930+O1930+Q1930+S1930+AA1930+AC1930+AE1930+AG1930+AI1930+AK1930+U1930+W1930+Y1930 -> 0 | AN1930: =H1930+J1930+L1930+N1930+P1930+R1930+T1930+AB1930+AD1930+AF1930+AH1930+AJ1930+AL1930+V1930+X1930+Z1930 -> 0
...

Sheet CDPL
B1: CANDOR DATES PVT LTD | G1: =SUBTOTAL(9,G4:G2348) -> 0 | H1: =SUBTOTAL(9,H4:H2348) -> 394 | I1: =SUBTOTAL(9,I4:I2348) -> 0 | J1: =SUBTOTAL(9,J4:J2348) -> 0 | K1: =SUBTOTAL(9,K4:K2348) -> 0 | L1: =SUBTOTAL(9,L4:L2348) -> 0 | M1: =SUBTOTAL(9,M4:M2348) -> 0 | N1: =SUBTOTAL(9,N4:N2348) -> 10.21 | ... AN1: =SUBTOTAL(9,AN4:AN2348) -> 568460.05 | AO1: =AN1+CFPL!AN1 -> 993777.59
B2: Stock Take Compilation | D2: 46075 | E2: Location: | G2: W-202 Store | I2: W-202 Lower | K2: W-202 Upper | M2: W-202 1st Floor | O2: W-202 2nd Floor | Q2: W-202 Barline | S2: W-202 Terrace | U2: W-202 Off-Grade | W2: A-185 | Y2: A-185 Cold | AA2: A-185 Off-grade | AC2: A-101 | AE2: Ajustment Pending | AG2: APMC | AI2: Rishi | AK2: Savla | AM2: Total Stock
A3: Sr. No. | B3: ITEM | C3: FG/RM | D3: GROUP | E3: Sub-Group | F3: PACK SIZE | G3: Total Quantity | H3: Qty. in KG | I3: Total Quantity | J3: Qty. in KG | K3: Total Quantity | L3: Qty. in KG | M3: Total Quantity | N3: Qty. in KG | O3: Total Quantity | P3: Qty. in KG | Q3: Total Quantity | R3: Qty. in KG | S3: Total Quantity | T3: Qty. in KG | U3: Total Quantity | V3: Qty. in KG | W3: Total Quantity | X3: Qty. in KG | Y3: Total Quantity | Z3: Qty. in KG | AA3: Total Quantity | AB3: Qty. in KG | AC3: Total Quantity | AD3: Qty. in KG | AE3: Total Quantity | AF3: Qty. in KG | AG3: Total Quantity | AH3: Qty. in KG | AI3: Total Quantity | AJ3: Qty. in KG | AK3: Total Quantity | AL3: Qty. in KG | AM3: Total Quantity | AN3: Qty. in KG
A4: 1 | B4: AFREEN DATES | C4: RM | D4: DATES | E4: Afreen | F4: 1 | G4: 0 | H4: 0 | I4: 0 | J4: 0 | K4: 0 | L4: 0 | M4: 0 | N4: 0 | O4: 0 | P4: 0 | Q4: 0 | R4: 0 | S4: 0 | T4: 0 | U4: 0 | V4: 0 | W4: 0 | X4: 0 | Y4: 0 | Z4: 0 | AA4: 0 | AB4: 0 | AC4: 0 | AD4: 0 | AE4: 0 | AF4: 0 | AG4: 0 | AH4: 0 | AI4: 0 | AJ4: 0 | AK4: 0 | AL4: 0 | AM4: =G4+I4+K4+M4+O4+Q4+S4+AA4+AC4+AE4+AG4+AI4+AK4+U4+W4+Y4 -> 0 | AN4: =H4+J4+L4+N4+P4+R4+T4+AB4+AD4+AF4+AH4+AJ4+AL4+V4+X4+Z4 -> 0
A5: 2 | B5: Al Barakah Ajwa Jumbo Dates | C5: RM | D5: DATES | E5: Ajwa | F5: 1 | G5: 0 | H5: 0 | I5: 0 | J5: 0 | K5: 0 | L5: 0 | M5: 0 | N5: 0 | O5: 0 | P5: 0 | Q5: 0 | R5: 0 | S5: 0 | T5: 0 | U5: 0 | V5: 0 | W5: 0 | X5: 0 | Y5: 0 | Z5: 0 | AA5: 0 | AB5: 0 | AC5: 0 | AD5: 0 | AE5: 0 | AF5: 0 | AG5: 0 | AH5: 0 | AI5: 0 | AJ5: 0 | AK5: 0 | AL5: 0 | AM5: =G5+I5+K5+M5+O5+Q5+S5+AA5+AC5+AE5+AG5+AI5+AK5+U5+W5+Y5 -> 0 | AN5: =H5+J5+L5+N5+P5+R5+T5+AB5+AD5+AF5+AH5+AJ5+AL5+V5+X5+Z5 -> 0
A6: 3 | B6: Royal Delight Ajwa Dates 5 Kgs | C6: RM | D6: DATES | E6: Ajwa | F6: 1 | G6: 0 | H6: 0 | I6: 0 | J6: 0 | K6: 0 | L6: 0 | M6: 0 | N6: 0 | O6: 0 | P6: 0 | Q6: 0 | R6: 0 | S6: 0 | T6: 0 | U6: 0 | V6: 0 | W6: 0 | X6: 0 | Y6: 0 | Z6: 0 | AA6: 0 | AB6: 0 | AC6: 0 | AD6: 0 | AE6: 0 | AF6: 0 | AG6: 0 | AH6: 0 | AI6: 0 | AJ6: 0 | AK6: 0 | AL6: 365 | AM6: =G6+I6+K6+M6+O6+Q6+S6+AA6+AC6+AE6+AG6+AI6+AK6+U6+W6+Y6 -> 0 | AN6: =H6+J6+L6+N6+P6+R6+T6+AB6+AD6+AF6+AH6+AJ6+AL6+V6+X6+Z6 -> 365
A7: 4 | B7: Wet Dates Ajwa | C7: RM | D7: DATES | E7: Ajwa | F7: 1 | G7: 0 | H7: 5 | I7: 0 | J7: 0 | K7: 0 | L7: 0 | M7: 0 | N7: 0 | O7: 0 | P7: 0 | Q7: 0 | R7: 0 | S7: 0 | T7: 0 | U7: 0 | V7: 0 | W7: 0 | X7: 0 | Y7: 0 | Z7: 0 | AA7: 0 | AB7: 0 | AC7: 0 | AD7: 0 | AE7: 0 | AF7: 0 | AG7: 0 | AH7: 0 | AI7: 0 | AJ7: 140 | AK7: 0 | AL7: 6265 | AM7: =G7+I7+K7+M7+O7+Q7+S7+AA7+AC7+AE7+AG7+AI7+AK7+U7+W7+Y7 -> 0 | AN7: =H7+J7+L7+N7+P7+R7+T7+AB7+AD7+AF7+AH7+AJ7+AL7+V7+X7+Z7 -> 6410
A8: 5 | B8: Wet Dates Ajwa Premium | C8: RM | D8: DATES | E8: Ajwa | F8: 1 | G8: 0 | H8: 0 | I8: 0 | J8: 0 | K8: 0 | L8: 0 | M8: 0 | N8: 0 | O8: 0 | P8: 0 | Q8: 0 | R8: 0 | S8: 0 | T8: 0 | U8: 0 | V8: 0 | W8: 0 | X8: 0 | Y8: 0 | Z8: 0 | AA8: 0 | AB8: 0 | AC8: 0 | AD8: 0 | AE8: 0 | AF8: 0 | AG8: 0 | AH8: 0 | AI8: 0 | AJ8: 0 | AK8: 0 | AL8: 0 | AM8: =G8+I8+K8+M8+O8+Q8+S8+AA8+AC8+AE8+AG8+AI8+AK8+U8+W8+Y8 -> 0 | AN8: =H8+J8+L8+N8+P8+R8+T8+AB8+AD8+AF8+AH8+AJ8+AL8+V8+X8+Z8 -> 0
A9: 6 | B9: CURATE DATES AJWA IMP SAUDI 500G | C9: FG | D9: DATES | E9: Ajwa | F9: 0.5 | G9: 0 | H9: 0 | I9: 0 | J9: 0 | K9: 0 | L9: 0 | M9: 0 | N9: 0 | O9: 13 | P9: 6.5 | Q9: 0 | R9: 0 | S9: 0 | T9: 0 | U9: 0 | V9: 0 | W9: 0 | X9: 0 | Y9: 0 | Z9: 0 | AA9: 0 | AB9: 0 | AC9: 0 | AD9: 0 | AE9: 0 | AF9: 0 | AG9: 0 | AH9: 0 | AI9: 0 | AJ9: 0 | AK9: 0 | AL9: 0 | AM9: =G9+I9+K9+M9+O9+Q9+S9+AA9+AC9+AE9+AG9+AI9+AK9+U9+W9+Y9 -> 13 | AN9: =H9+J9+L9+N9+P9+R9+T9+AB9+AD9+AF9+AH9+AJ9+AL9+V9+X9+Z9 -> 6.5
A10: 7 | B10: Royal Delight Ajwa Dates 400gm | C10: FG | D10: DATES | E10: Ajwa | F10: 0.4 | G10: 0 | H10: 0 | I10: 0 | J10: 0 | K10: 0 | L10: 0 | M10: 0 | N10: 0 | O10: 0 | P10: 0 | Q10: 0 | R10: 0 | S10: 0 | T10: 0 | U10: 0 | V10: 0 | W10: 0 | X10: 0 | Y10: 0 | Z10: 0 | AA10: 0 | AB10: 0 | AC10: 0 | AD10: 0 | AE10: 0 | AF10: 0 | AG10: 0 | AH10: 0 | AI10: 0 | AJ10: 0 | AK10: 0 | AL10: 0 | AM10: =G10+I10+K10+M10+O10+Q10+S10+AA10+AC10+AE10+AG10+AI10+AK10+U10+W10+Y10 -> 0 | AN10: =H10+J10+L10+N10+P10+R10+T10+AB10+AD10+AF10+AH10+AJ10+AL10+V10+X10+Z10 -> 0
A11: 8 | B11: Royal Delight Ajwa Dates 500 Gm | C11: FG | D11: DATES | E11: Ajwa | F11: 0.5 | G11: 0 | H11: 0 | I11: 0 | J11: 0 | K11: 0 | L11: 0 | M11: 0 | N11: 0 | O11: 0 | P11: 0 | Q11: 0 | R11: 0 | S11: 0 | T11: 0 | U11: 0 | V11: 0 | W11: 0 | X11: 0 | Y11: 0 | Z11: 0 | AA11: 0 | AB11: 0 | AC11: 0 | AD11: 0 | AE11: 0 | AF11: 0 | AG11: 0 | AH11: 0 | AI11: 0 | AJ11: 0 | AK11: 0 | AL11: 0 | AM11: =G11+I11+K11+M11+O11+Q11+S11+AA11+AC11+AE11+AG11+AI11+AK11+U11+W11+Y11 -> 0 | AN11: =H11+J11+L11+N11+P11+R11+T11+AB11+AD11+AF11+AH11+AJ11+AL11+V11+X11+Z11 -> 0
A12: 9 | B12: Royal Delight Ajwa Large 250g | C12: FG | D12: DATES | E12: Ajwa | F12: 0.25 | G12: 0 | H12: 0 | I12: 0 | J12: 0 | K12: 0 | L12: 0 | M12: 0 | N12: 0 | O12: 0 | P12: 0 | Q12: 0 | R12: 0 | S12: 0 | T12: 0 | U12: 0 | V12: 0 | W12: 0 | X12: 0 | Y12: 0 | Z12: 0 | AA12: 0 | AB12: 0 | AC12: 0 | AD12: 0 | AE12: 0 | AF12: 0 | AG12: 0 | AH12: 0 | AI12: 0 | AJ12: 0 | AK12: 0 | AL12: 0 | AM12: =G12+I12+K12+M12+O12+Q12+S12+AA12+AC12+AE12+AG12+AI12+AK12+U12+W12+Y12 -> 0 | AN12: =H12+J12+L12+N12+P12+R12+T12+AB12+AD12+AF12+AH12+AJ12+AL12+V12+X12+Z12 -> 0
A13: 10 | B13: UP Ajwa Dates 500gm | C13: FG | D13: DATES | E13: Ajwa | F13: 0.5 | G13: 0 | H13: 0 | I13: 0 | J13: 0 | K13: 0 | L13: 0 | M13: 0 | N13: 0 | O13: 0 | P13: 0 | Q13: 0 | R13: 0 | S13: 0 | T13: 0 | U13: 0 | V13: 0 | W13: 0 | X13: 0 | Y13: 0 | Z13: 0 | AA13: 0 | AB13: 0 | AC13: 0 | AD13: 0 | AE13: 0 | AF13: 0 | AG13: 0 | AH13: 0 | AI13: 0 | AJ13: 0 | AK13: 0 | AL13: 0 | AM13: =G13+I13+K13+M13+O13+Q13+S13+AA13+AC13+AE13+AG13+AI13+AK13+U13+W13+Y13 -> 0 | AN13: =H13+J13+L13+N13+P13+R13+T13+AB13+AD13+AF13+AH13+AJ13+AL13+V13+X13+Z13 -> 0
A14: 11 | B14: KINGDOM OF DATES AMARY DATES | C14: RM | D14: DATES | E14: Amary | F14: 1 | G14: 0 | H14: 0 | I14: 0 | J14: 0 | K14: 0 | L14: 0 | M14: 0 | N14: 0 | O14: 0 | P14: 0 | Q14: 0 | R14: 0 | S14: 0 | T14: 0 | U14: 0 | V14: 0 | W14: 0 | X14: 0 | Y14: 0 | Z14: 0 | AA14: 0 | AB14: 0 | AC14: 0 | AD14: 0 | AE14: 0 | AF14: 0 | AG14: 0 | AH14: 0 | AI14: 0 | AJ14: 0 | AK14: 0 | AL14: 0 | AM14: =G14+I14+K14+M14+O14+Q14+S14+AA14+AC14+AE14+AG14+AI14+AK14+U14+W14+Y14 -> 0 | AN14: =H14+J14+L14+N14+P14+R14+T14+AB14+AD14+AF14+AH14+AJ14+AL14+V14+X14+Z14 -> 0
A15: 12 | B15: Wet Dates (Amary) | C15: RM | D15: DATES | E15: Amary | F15: 1 | G15: 0 | H15: 0 | I15: 0 | J15: 0 | K15: 0 | L15: 0 | M15: 0 | N15: 0 | O15: 0 | P15: 0 | Q15: 0 | R15: 0 | S15: 0 | T15: 0 | U15: 0 | V15: 0 | W15: 0 | X15: 0 | Y15: 0 | Z15: 0 | AA15: 0 | AB15: 0 | AC15: 0 | AD15: 0 | AE15: 0 | AF15: 0 | AG15: 0 | AH15: 0 | AI15: 0 | AJ15: 0 | AK15: 0 | AL15: 0 | AM15: =G15+I15+K15+M15+O15+Q15+S15+AA15+AC15+AE15+AG15+AI15+AK15+U15+W15+Y15 -> 0 | AN15: =H15+J15+L15+N15+P15+R15+T15+AB15+AD15+AF15+AH15+AJ15+AL15+V15+X15+Z15 -> 0
... A277: 269 | B277: Organic Wanan Premium Large | C277: RM | D277: DATES | E277: Wanan | F277: 1 | G277: 0 | H277: 0 | I277: 0 | J277: 0 | K277: 0 | L277: 0 | M277: 0 | N277: 0 | O277: 0 | P277: 0 | Q277: 0 | R277: 0 | S277: 0 | T277: 0 | U277: 0 | V277: 0 | W277: 0 | X277: 0 | Y277: 0 | Z277: 0 | AA277: 0 | AB277: 0 | AC277: 0 | AD277: 0 | AE277: 0 | AF277: 0 | AG277: 0 | AH277: 0 | AI277: 0 | AJ277: 0 | AK277: 0 | AL277: 162.5 | AM277: =G277+I277+K277+M277+O277+Q277+S277+AA277+AC277+AE277+AG277+AI277+AK277+U277+W277+Y277 -> 0 | AN277: =H277+J277+L277+N277+P277+R277+T277+AB277+AD277+AF277+AH277+AJ277+AL277+V277+X277+Z277 -> 162.5
