Workbook

Sheet Pivot CFPL
A1: Company Name | B1: CFPL | F1: =GETPIVOTDATA("Total Inventory Kgs",$A$3)+GETPIVOTDATA("Total Inventory Kgs",'Pivot CDPL'!$A$3) -> 930621.34
B2: Total (CFPL+CDPL) KGS | C2: =GETPIVOTDATA("Total Inventory Kgs",$A$3,"Storage Location","A-185 Cold") -> 29739.92 | D2: =GETPIVOTDATA("Total Inventory Kgs",$A$3,"Storage Location","Savla") -> 79093.82 | E2: =GETPIVOTDATA("Total Inventory Kgs",$A$3,"Storage Location","Savla Bond") -> 7500 | F2: =GETPIVOTDATA("Total Inventory Kgs",$A$3) -> 116333.74
A3: Sum of Total Inventory Kgs | C3: Storage Location
A4: Group Name* | B4: Tally Name | C4: A-185 Cold | D4: Savla | E4: Savla Bond | F4: Grand Total
A5: Apricot | B5: Turkey Apricot No 3 | D5: 488 | F5: 488
B6: Turkey Apricot No. 0 | D6: 325 | F6: 325
A7: Apricot Total | D7: 813 | F7: 813
A8: Blueberry | B8: Dried Blueberry | C8: 1098.68 | D8: 908 | F8: 2006.68
B9: Dried Blueberry Apple Infused | D9: 99.88 | F9: 99.88
A10: Blueberry Total | C10: 1098.68 | D10: 1007.88 | F10: 2106.56
A11: Cashew Kernel | B11: BLACK PEPPER CASHEW | C11: 10 | F11: 10
B12: Roasted & Salted Cashew | C12: 10 | F12: 10
B13: Cashew Kernel | C13: 0 | F13: 0
A14: Cashew Kernel Total | C14: 20 | F14: 20
A15: Cranberry | B15: Dried Cranberry Sliced | C15: 4456.62 | D15: 4536 | F15: 8992.62
B16: Dried Cranberry Whole | C16: 2787.5 | D16: 3268.44 | F16: 6055.94
B17: Chatpata Cranberry | C17: 31.5 | F17: 31.5
B18: Pan Cranberry | C18: 21.8 | F18: 21.8
A19: Cranberry Total | C19: 7297.42 | D19: 7804.44 | F19: 15101.86
A20: Date Powder | B20: AL BARAKAH DEHYDRATED DATE POWDER - BULK PACK 10KG | C20: 80 | F20: 80
A21: Date Powder Total | C21: 80 | F21: 80
A22: Date Syrup | B22: AL BARAKAH DATE SYRUP(1.15KG X 12) | C22: 3105 | F22: 3105
B23: AL BARAKAH DATES SYRUP (400G Packing) | C23: 684 | F23: 684
A24: Date Syrup Total | C24: 3789 | F24: 3789
A25: Dehydrated Fruits | B25: Dried Orange Peel | C25: 7 | F25: 7
B26: Dried Mango Loose | C26: 10 | F26: 10
B27: Dried Goji Berry | D27: 64 | F27: 64
A28: Dehydrated Fruits Total | C28: 17 | D28: 64 | F28: 81
A29: Dry Dates | B29: DRY DATES-GRADE 2 | C29: 3530 | F29: 3530
B30: Red Kharek Cut | C30: 80 | F30: 80
A31: Dry Dates Total | C31: 3610 | F31: 3610
A32: Economical Dates | B32: AL BARAKAH KHALAS PREMIUM DATES | C32: 57.7 | F32: 57.7
B33: Wet Dates (Deri) | D33: 3580 | F33: 3580
B34: Oriental Dates | C34: 50 | F34: 50
B35: Wet Date Sayer ( Unpitted ) | C35: 40 | F35: 40
B36: Fresho Kimia Dates 500 Gm | C36: 45 | F36: 45
A37: Economical Dates Total | C37: 192.7 | D37: 3580 | F37: 3772.7
A38: Hazelnut | B38: Hazelnut Kernal | C38: 8 | D38: 210 | F38: 218
A39: Hazelnut Total | C39: 8 | D39: 210 | F39: 218
A40: Macadamia Paste | B40: Macadamia Paste | D40: 180 | F40: 180
...

Sheet Pivot CDPL
A1: Company Name | B1: CDPL | E1: =GETPIVOTDATA("Total Inventory Kgs",$A$3)+GETPIVOTDATA("Total Inventory Kgs",'Pivot CFPL'!$A$3) -> 930621.34
B2: Total (CDPL+CFPL) KGS | C2: =GETPIVOTDATA("Total Inventory Kgs",$A$3,"Storage Location","Rishi") -> 459647 | D2: =GETPIVOTDATA("Total Inventory Kgs",$A$3,"Storage Location","Savla") -> 354640.6 | E2: =GETPIVOTDATA("Total Inventory Kgs",$A$3) -> 814287.6
A3: Sum of Total Inventory Kgs | C3: Storage Location
A4: Group Name* | B4: Tally Name | C4: Rishi | D4: Savla | E4: Grand Total
A5: Date Paste | B5: AL BARAKAH DATE PASTE 12.5KG | D5: 120687.5 | E5: 120687.5
A6: Date Paste Total | D6: 120687.5 | E6: 120687.5
A7: Date Powder | B7: 10KG AL BARAKAH DATE POWDER V1 | D7: 90790 | E7: 90790
B8: 10KG AL BARAKAH DATE POWDER V2 | D8: 11670 | E8: 11670
A9: Date Powder Total | D9: 102460 | E9: 102460
A10: Date Syrup | B10: 25KG AL BARAKAH DATE SYRUP V1 | C10: 200 | D10: 81650 | E10: 81850
B11: AL BARAKAH DATES SYRUP 400G | D11: 4123.2 | E11: 4123.2
A12: Date Syrup Total | C12: 200 | D12: 85773.2 | E12: 85973.2
A13: Dry Dates | B13: AL BARAKAH CHOPPED DATES | D13: 980 | E13: 980
B14: AL BARAKAH CRUSHED DATES 10KG | D14: 630 | E14: 630
B15: DRY DATES-GRADE 2 | C15: 370 | D15: 546 | E15: 916
B16: Seedless Chopped Red Kharik Dry Dates | D16: 90 | E16: 90
B17: Kharik | C17: 588 | E17: 588
A18: Dry Dates Total | C18: 958 | D18: 2246 | E18: 3204
A19: Economical Dates | B19: AL BARAKAH BARHI DATES 10KG | C19: 50670 | E19: 50670
B20: AL BARAKAH EMIRATES BLACK DATES 10KG | D20: 20 | E20: 20
B21: AL BARAKAH FARD DATES 10KG - EZAD | D21: 10890 | E21: 10890
B22: AL BARAKAH FARD DATES STANDARD | C22: 80270 | D22: 50 | E22: 80320
B23: AL BARAKAH KHALAS DATES | C23: 12000 | E23: 12000
B24: AL BARAKAH KHALAS DATES-AFCTN | D24: 110 | E24: 110
B25: AL BARAKAH KHALAS PREMIUM DATES | C25: 159710 | E25: 159710
B26: AL BARAKAH KHANIZEE DATES 10KG | D26: 230 | E26: 230
B27: AL BARAKAH LULU BLACK DATES-10KG | D27: 170 | E27: 170
B28: AL BARAKAH LULU RED DATES - 10KG | D28: 2400 | E28: 2400
B29: AL BARAKAH REZIZ DATES 10KG | C29: 8950 | E29: 8950
B30: AL BARAKAH SAYER DATES 10KG | D30: 7490 | E30: 7490
B31: AL BARAKAH SUFRI DATES 10KG | C31: 7800 | E31: 7800
B32: BUMAN DATES | D32: 30 | E32: 30
B33: Wet Dates (Mazafati) | C33: 16250 | D33: 5865 | E33: 22115
B34: Wet Dates (Rabia) | D34: 495 | E34: 495
B35: Wet Dates (Sukkary) | D35: 1378 | E35: 1378
B36: Wet Dates Fardh | D36: 425 | E36: 425
B37: Wet Dates Seedless Khalas | C37: 2855 | E37: 2855
B38: Wet Dates (Deri) | D38: 45 | E38: 45
B39: Al Barakah Fard Dates Premium | C39: 102580 | D39: 10 | E39: 102590
B40: Royal Delight Arabian 250gm | D40: 80 | E40: 80
...

Sheet Pivot Other
B2: =TODAY()-1 -> 46153 | C2: Total Stock | F2: CDPL+CFPL | H2: in Kg | I2: In KG | J2: =K2/I2 -> #VALUE! | K2: =GETPIVOTDATA("Sum of Value",$A$3) -> 28169810 | L2: =GETPIVOTDATA("Total Kgs",$A$3) -> 50183.51 | N2: =GETPIVOTDATA("Sum of Value",$A$3) -> 28169810 | O2: =N2/L2 -> 561.33598
C3: Storage Location | D3: Values | Q3: Other than Dates | R3: =TODAY()-1 -> 46153 | S3: Total Stock | T3: CDPL+CFPL | U3: =U4+'Pivot Dates'!Y4 -> 850229.01 | V3: Value/KG | W3: =W4+'Pivot Dates'!AA4 -> 1.8624601e+08
C4: Savla | F4: A-185 Cold | I4: Total Total Kgs | J4: Total Average of Rate | K4: Total Sum of Value | Q4: =TODAY()-1 -> 46153 | R4: Storage Location | S4: Savla | T4: A-185 Cold | U4: =U13+U18+U20+U23+U32+U38+U43+U45+U55+U57+U70+U75+U81+U83+U92+U11+U120+U123+U59+U131+U136+U138+U126 -> 50183.51 | V4: =W4/U4 -> 561.33598 | W4: =W13+W18+W20+W23+W32+W38+W43+W45+W55+W57+W70+W75+W81+W83+W92+W11+W120+W123+W59+W131+W136+W138+W126 -> 28169810
A5: Group Name* | B5: Item Display Name* | C5: Total Kgs | D5: Average of Rate | E5: Sum of Value | F5: Total Kgs | G5: Average of Rate | H5: Sum of Value | Q5: Group Name* | R5: Item Display Name* | S5: Total Kgs | T5: Total Kgs | U5: Total Kgs | V5: Avg Rate/Kg | W5: Approximate Value
A6: Almond | B6: Almond Blanched, whole | F6: 40 | G6: 650 | H6: 26000 | I6: 40 | J6: 650 | K6: 26000 | Q6: Almond | R6: Almond Blanched, whole | S6: =VLOOKUP(R6,B:N,2,0) -> 0 | T6: =VLOOKUP(R6,B:N,5,0) -> 40 | U6: =SUM(S6:T6) -> 40 | V6: =W6/U6 -> 650 | W6: =VLOOKUP(R6,B:N,10,0) -> 26000
B7: Almond Kernels 20-22 | F7: 727 | G7: 750 | H7: 545250 | I7: 727 | J7: 750 | K7: 545250 | R7: Almond Kernels 20-22 | S7: =VLOOKUP(R7,B:N,2,0) -> 0 | T7: =VLOOKUP(R7,B:N,5,0) -> 727 | U7: =SUM(S7:T7) -> 727 | V7: =W7/U7 -> 750 | W7: =VLOOKUP(R7,B:N,10,0) -> 545250
B8: Roasted & Salted Almonds | F8: 118.45 | G8: 650 | H8: 76992.5 | I8: 118.45 | J8: 650 | K8: 76992.5 | R8: California Almond Inshell Blue Diamond | S8: 0 | T8: 0 | U8: 0 | V8: =W8/U8 -> #DIV/0! | W8: 0
B9: Smoked Almonds August RTV | F9: 541 | G9: 595 | H9: 321895 | I9: 541 | J9: 595 | K9: 321895 | R9: Roasted & Salted Almonds | S9: =VLOOKUP(R9,B:N,2,0) -> 0 | T9: =VLOOKUP(R9,B:N,5,0) -> 118.45 | U9: =SUM(S9:T9) -> 118.45 | V9: =W9/U9 -> 650 | W9: =VLOOKUP(R9,B:N,10,0) -> 76992.5
A10: Almond Total | F10: 1426.45 | G10: 661.25 | H10: 970137.5 | I10: 1426.45 | J10: 661.25 | K10: 970137.5 | R10: Smoked Almonds August RTV | S10: =VLOOKUP(R10,B:N,2,0) -> 0 | T10: =VLOOKUP(R10,B:N,5,0) -> 541 | U10: =SUM(S10:T10) -> 541 | V10: =W10/U10 -> 595 | W10: =VLOOKUP(R10,B:N,10,0) -> 321895
A11: Anjeer | B11: Dried Anjeer 200gm RTV | F11: 10.4 | G11: 1100 | H11: 11440 | I11: 10.4 | J11: 1100 | K11: 11440 | Q11: Almond Total | S11: =SUM(S6:S10) -> 0 | T11: =SUM(T6:T10) -> 1426.45 | U11: =SUM(U6:U10) -> 1426.45 | V11: =W11/U11 -> 680.10621 | W11: =SUM(W6:W10) -> 970137.5
A12: Anjeer Total | F12: 10.4 | G12: 1100 | H12: 11440 | I12: 10.4 | J12: 1100 | K12: 11440 | Q12: Anjeer | R12: Dried Anjeer 200gm RTV | S12: =VLOOKUP(R12,B:N,2,0) -> 0 | T12: =VLOOKUP(R12,B:N,5,0) -> 10.4 | U12: =SUM(S12:T12) -> 10.4 | V12: =W12/U12 -> 1100 | W12: =VLOOKUP(R12,B:N,10,0) -> 11440
A13: Apricot | B13: Afghan Apricot 1*2 | F13: 18 | G13: 380 | H13: 6840 | I13: 18 | J13: 380 | K13: 6840 | Q13: Anjeer Total | S13: =SUM(S12:S12) -> 0 | T13: =SUM(T12:T12) -> 10.4 | U13: =SUM(U12:U12) -> 10.4 | V13: =W13/U13 -> 1100 | W13: =SUM(W12:W12) -> 11440
B14: Turkey Apricot No 0 | C14: 310 | D14: 650 | E14: 201500 | I14: 310 | J14: 650 | K14: 201500 | Q14: Apricot | R14: Afghan Apricot 1*2 | S14: =VLOOKUP(R14,B:N,2,0) -> 0 | T14: =VLOOKUP(R14,B:N,5,0) -> 18 | U14: =SUM(S14:T14) -> 18 | V14: =W14/U14 -> 380 | W14: =VLOOKUP(R14,B:N,10,0) -> 6840
B15: Turkey Apricot No 3 | C15: 1904 | D15: 780 | E15: 1485120 | I15: 1904 | J15: 780 | K15: 1485120 | R15: Apricot 1x2 | S15: 0 | T15: 0 | U15: =SUM(S15:T15) -> 0 | V15: =W15/U15 -> #DIV/0! | W15: 0
A16: Apricot Total | C16: 2214 | D16: 736.66667 | E16: 1686620 | F16: 18 | G16: 380 | H16: 6840 | I16: 2232 | J16: 647.5 | K16: 1693460 | R16: Turkey Apricot No 0 | S16: =VLOOKUP(R16,B:N,2,0) -> 310 | T16: =VLOOKUP(R16,B:N,5,0) -> 0 | U16: =SUM(S16:T16) -> 310 | V16: =W16/U16 -> 650 | W16: =VLOOKUP(R16,B:N,10,0) -> 201500
A17: BlackCurrant | B17: Dried Black Current | C17: 375 | D17: 490 | E17: 183750 | F17: 134.1 | G17: 490 | H17: 65709 | I17: 509.1 | J17: 490 | K17: 249459 | R17: Turkey Apricot No 3 | S17: =VLOOKUP(R17,B:N,2,0) -> 1904 | T17: =VLOOKUP(R17,B:N,5,0) -> 0 | U17: =SUM(S17:T17) -> 1904 | V17: =W17/U17 -> 780 | W17: =VLOOKUP(R17,B:N,10,0) -> 1485120
A18: BlackCurrant Total | C18: 375 | D18: 490 | E18: 183750 | F18: 134.1 | G18: 490 | H18: 65709 | I18: 509.1 | J18: 490 | K18: 249459 | Q18: Apricot Total | S18: =SUM(S14:S17) -> 2214 | T18: =SUM(T14:T17) -> 18 | U18: =SUM(U14:U17) -> 2232 | V18: =W18/U18 -> 758.71864 | W18: =SUM(W14:W17) -> 1693460
A19: Blueberry | B19: Dried Blueberry | F19: 194.4 | G19: 1130 | H19: 219672 | I19: 194.4 | J19: 1130 | K19: 219672 | Q19: BlackCurrant | R19: Dried Black Current | S19: =VLOOKUP(R19,B:N,2,0) -> 375 | T19: =VLOOKUP(R19,B:N,5,0) -> 134.1 | U19: =SUM(S19:T19) -> 509.1 | V19: =W19/U19 -> 490 | W19: =VLOOKUP(R19,B:N,10,0) -> 249459
B20: Dried Blueberry Whole-Apple Infused | C20: 99.88 | D20: 1270 | E20: 126847.6 | I20: 99.88 | J20: 1270 | K20: 126847.6 | Q20: BlackCurrant Total | S20: =SUM(S19:S19) -> 375 | T20: =SUM(T19:T19) -> 134.1 | U20: =SUM(U19:U19) -> 509.1 | V20: =W20/U20 -> 490 | W20: =SUM(W19:W19) -> 249459
A21: Blueberry Total | C21: 99.88 | D21: 1270 | E21: 126847.6 | F21: 194.4 | G21: 1130 | H21: 219672 | I21: 294.28 | J21: 1223.3333 | K21: 346519.6 | Q21: Blueberry | R21: Dried Blueberry Whole-Apple Infused | S21: =VLOOKUP(R21,B:N,2,0) -> 99.88 | T21: =VLOOKUP(R21,B:N,5,0) -> 0 | U21: =SUM(S21:T21) -> 99.88 | V21: =W21/U21 -> 1270 | W21: =VLOOKUP(R21,B:N,10,0) -> 126847.6
A22: Brazil Nuts | B22: Brazil Nuts | C22: 200 | D22: 2700 | E22: 540000 | F22: 8.8 | G22: 2800 | H22: 24640 | I22: 208.8 | J22: 2750 | K22: 564640 | R22: Dried Blueberry | S22: =VLOOKUP(R22,B:N,2,0) -> 0 | T22: =VLOOKUP(R22,B:N,5,0) -> 194.4 | U22: =SUM(S22:T22) -> 194.4 | V22: =W22/U22 -> 1130 | W22: =VLOOKUP(R22,B:N,10,0) -> 219672
A23: Brazil Nuts Total | C23: 200 | D23: 2700 | E23: 540000 | F23: 8.8 | G23: 2800 | H23: 24640 | I23: 208.8 | J23: 2750 | K23: 564640 | Q23: Blueberry Total | S23: =SUM(S21:S22) -> 99.88 | T23: =SUM(T21:T22) -> 194.4 | U23: =SUM(U21:U22) -> 294.28 | V23: =W23/U23 -> 1177.5167 | W23: =SUM(W21:W22) -> 346519.6
A24: Cashew Kernel | B24: BLACK PEPPER CASHEW | F24: 22.6 | G24: 900 | H24: 20340 | I24: 22.6 | J24: 900 | K24: 20340 | Q24: Cashew Kernel | R24: Cashew Kernels W 180 | S24: 0 | T24: 0 | U24: =SUM(S24:T24) -> 0 | V24: =W24/U24 -> #DIV/0! | W24: 0
B25: Carnival Roasted & Salted Cashew 200g | F25: 90 | G25: 800 | H25: 72000 | I25: 90 | J25: 800 | K25: 72000 | R25: Cashew Kernels W 210 | S25: 0 | T25: 0 | U25: =SUM(S25:T25) -> 0 | V25: =W25/U25 -> #DIV/0! | W25: 0
B26: Cashew Kernel | F26: 39.3 | G26: 715 | H26: 28099.5 | I26: 39.3 | J26: 715 | K26: 28099.5 | R26: Cashew Kernels W 240 | S26: 0 | T26: 0 | U26: =SUM(S26:T26) -> 0 | V26: =W26/U26 -> #DIV/0! | W26: 0
B27: Cheese Cashew | F27: 1 | G27: 880 | H27: 880 | I27: 1 | J27: 880 | K27: 880 | R27: BLACK PEPPER CASHEW | S27: =VLOOKUP(R27,B:N,2,0) -> 0 | T27: =VLOOKUP(R27,B:N,5,0) -> 22.6 | U27: =SUM(S27:T27) -> 22.6 | V27: =W27/U27 -> 900 | W27: =VLOOKUP(R27,B:N,10,0) -> 20340
B28: Roasted & Salted Cashew | F28: 13.5 | G28: 800 | H28: 10800 | I28: 13.5 | J28: 800 | K28: 10800 | R28: Carnival Roasted & Salted Cashew 200g | S28: =VLOOKUP(R28,B:N,2,0) -> 0 | T28: =VLOOKUP(R28,B:N,5,0) -> 90 | U28: =SUM(S28:T28) -> 90 | V28: =W28/U28 -> 800 | W28: =VLOOKUP(R28,B:N,10,0) -> 72000
A29: Cashew Kernel Total | F29: 166.4 | G29: 819 | H29: 132119.5 | I29: 166.4 | J29: 819 | K29: 132119.5 | R29: Cheese Cashew | S29: =VLOOKUP(R29,B:N,2,0) -> 0 | T29: =VLOOKUP(R29,B:N,5,0) -> 1 | U29: =SUM(S29:T29) -> 1 | V29: =W29/U29 -> 880 | W29: =VLOOKUP(R29,B:N,10,0) -> 880
A30: Cranberry | B30: Chatpata Cranberry | F30: 126.5 | G30: 540 | H30: 68310 | I30: 126.5 | J30: 540 | K30: 68310 | R30: Cashew Kernel | S30: =VLOOKUP(R30,B:N,2,0) -> 0 | T30: =VLOOKUP(R30,B:N,5,0) -> 39.3 | U30: =SUM(S30:T30) -> 39.3 | V30: =W30/U30 -> 715 | W30: =VLOOKUP(R30,B:N,10,0) -> 28099.5
B31: Dried Cranberry Sliced | C31: 2268 | D31: 360 | E31: 816480 | F31: 4581 | G31: 360 | H31: 1649160 | I31: 6849 | J31: 360 | K31: 2465640 | R31: Roasted & Salted Cashew | S31: =VLOOKUP(R31,B:N,2,0) -> 0 | T31: =VLOOKUP(R31,B:N,5,0) -> 13.5 | U31: =SUM(S31:T31) -> 13.5 | V31: =W31/U31 -> 800 | W31: =VLOOKUP(R31,B:N,10,0) -> 10800
B32: Dried Cranberry Whole | C32: 7223.58 | D32: 415 | E32: 2997785.7 | F32: 498.96 | G32: 415 | H32: 207068.4 | I32: 7722.54 | J32: 415 | K32: 3204854.1 | Q32: Cashew Kernel Total | S32: =SUM(S24:S31) -> 0 | T32: =SUM(T24:T31) -> 166.4 | U32: =SUM(U24:U31) -> 166.4 | V32: =W32/U32 -> 793.98738 | W32: =SUM(W24:W31) -> 132119.5
B33: Dried Cranberry Whole - Meduri | C33: 181.6 | D33: 735 | E33: 134111.6 | I33: 181.6 | J33: 735 | K33: 134111.6 | Q33: Cranberry | R33: Dried Cranberry Sliced | S33: =VLOOKUP(R33,B:N,2,0) -> 2268 | T33: =VLOOKUP(R33,B:N,5,0) -> 4581 | U33: =SUM(S33:T33) -> 6849 | V33: =W33/U33 -> 360 | W33: =VLOOKUP(R33,B:N,10,0) -> 2465640
B34: Pan Cranberry | F34: 21.8 | G34: 500 | H34: 10900 | I34: 21.8 | J34: 500 | K34: 10900 | R34: Dried Cranberry Whole | S34: =VLOOKUP(R34,B:N,2,0) -> 7223.58 | T34: =VLOOKUP(R34,B:N,5,0) -> 498.96 | U34: =SUM(S34:T34) -> 7722.54 | V34: =W34/U34 -> 415 | W34: =VLOOKUP(R34,B:N,10,0) -> 3204854.1
A35: Cranberry Total | C35: 9673.18 | D35: 503.33333 | E35: 3948377.3 | F35: 5228.26 | G35: 453.75 | H35: 1935438.4 | I35: 14901.44 | J35: 483.5 | K35: 5883815.7 | R35: Dried Cranberry Whole - Meduri | S35: =VLOOKUP(R35,B:N,2,0) -> 181.6 | T35: =VLOOKUP(R35,B:N,5,0) -> 0 | U35: =SUM(S35:T35) -> 181.6 | V35: =W35/U35 -> 738.5 | W35: =VLOOKUP(R35,B:N,10,0) -> 134111.6
A36: Dehydrated Fruits | B36: Dried Goji Berry RTV Alimento | C36: 64 | D36: 825 | E36: 52800 | I36: 64 | J36: 825 | K36: 52800 | R36: Chatpata Cranberry | S36: =VLOOKUP(R36,B:N,2,0) -> 0 | T36: =VLOOKUP(R36,B:N,5,0) -> 126.5 | U36: =SUM(S36:T36) -> 126.5 | V36: =W36/U36 -> 540 | W36: =VLOOKUP(R36,B:N,10,0) -> 68310
B37: Dried Kiwi | F37: 5 | G37: 330 | H37: 1650 | I37: 5 | J37: 330 | K37: 1650 | R37: Pan Cranberry | S37: =VLOOKUP(R37,B:N,2,0) -> 0 | T37: =VLOOKUP(R37,B:N,5,0) -> 21.8 | U37: =SUM(S37:T37) -> 21.8 | V37: =W37/U37 -> 500 | W37: =VLOOKUP(R37,B:N,10,0) -> 10900
B38: Dried Mango Loose | F38: 3.5 | G38: 465 | H38: 1627.5 | I38: 3.5 | J38: 465 | K38: 1627.5 | Q38: Cranberry Total | S38: =SUM(S33:S37) -> 9673.18 | T38: =SUM(T33:T37) -> 5228.26 | U38: =SUM(U33:U37) -> 14901.44 | V38: =W38/U38 -> 394.8488 | W38: =SUM(W33:W37) -> 5883815.7
B39: Dried Orange Peel | F39: 30 | G39: 750 | H39: 22500 | I39: 30 | J39: 750 | K39: 22500 | Q39: Dehydrated Fruits | R39: Dried Orange Peel | S39: =VLOOKUP(R39,B:N,2,0) -> 0 | T39: =VLOOKUP(R39,B:N,5,0) -> 30 | U39: =SUM(S39:T39) -> 30 | V39: =W39/U39 -> 750 | W39: =VLOOKUP(R39,B:N,10,0) -> 22500
A40: Dehydrated Fruits Total | C40: 64 | D40: 825 | E40: 52800 | F40: 38.5 | G40: 515 | H40: 25777.5 | I40: 102.5 | J40: 592.5 | K40: 78577.5 | R40: Dried Kiwi | S40: =VLOOKUP(R40,B:N,2,0) -> 0 | T40: =VLOOKUP(R40,B:N,5,0) -> 5 | U40: =SUM(S40:T40) -> 5 | V40: =W40/U40 -> 330 | W40: =VLOOKUP(R40,B:N,10,0) -> 1650
A41: Festive Hamper | B41: Mewa Mix Dryfruit Box 580gm | F41: 5.22 | G41: 655 | H41: 3419.1 | I41: 5.22 | J41: 655 | K41: 3419.1 | R41: Dried Goji Berry RTV Alimento | S41: =VLOOKUP(R41,B:N,2,0) -> 64 | T41: =VLOOKUP(R41,B:N,5,0) -> 0 | U41: =SUM(S41:T41) -> 64 | V41: =W41/U41 -> 825 | W41: =VLOOKUP(R41,B:N,10,0) -> 52800
...

Sheet Pivot Dates
B2: =TODAY()-1 -> 46153 | C2: Total Stock | F2: CDPL+CFPL | I2: In Kg | O2: =GETPIVOTDATA("Total Kgs",$A$3) -> 800045.5 | P2: =Q2/O2 -> 197.58401 | Q2: =GETPIVOTDATA("Sum of Value",$A$3) -> 1.580762e+08
C3: Storage Location | D3: Values | S3: For Dates | T3: =TODAY()-1 -> 46153 | U3: Total Stock | V3: CDPL+CFPL | W3: In Kg | Y3: =Y4+'Pivot Other'!U4 -> 850229.01 | Z3: Value/KG | AA3: =AA4+'Pivot Other'!W4 -> 1.8624601e+08
C4: Rishi | F4: Savla | I4: Savla Bond | L4: A-185 Cold | O4: Total Total Kgs | P4: Total Average of Rate | Q4: Total Sum of Value | S4: =TODAY()-1 -> 46153 | T4: Storage Location | U4: Rishi | V4: Savla | W4: Savla Bond | X4: A-185 Cold | Y4: =Y7+Y13+Y17+Y23+Y55+Y67+Y98 -> 800045.5 | Z4: =AA4/Y4 -> 197.58401 | AA4: =AA7+AA13+AA17+AA23+AA55+AA67+AA98 -> 1.580762e+08
A5: Group Name* | B5: Item Display Name* | C5: Total Kgs | D5: Average of Rate | E5: Sum of Value | F5: Total Kgs | G5: Average of Rate | H5: Sum of Value | I5: Total Kgs | J5: Average of Rate | K5: Sum of Value | L5: Total Kgs | M5: Average of Rate | N5: Sum of Value | S5: Group Name* | T5: Item Display Name* | U5: Total Kgs | V5: Total Kgs | W5: Total Kgs | X5: Total Kgs | Y5: Total Kgs | Z5: Avg Rate/Kg | AA5: Approximate Value
A6: Date Paste | B6: Al Barakah Date Paste 12.5KG | F6: 6912.5 | G6: 85 | H6: 587562.5 | I6: 52000 | J6: 85 | K6: 4420000 | O6: 58912.5 | P6: 85 | Q6: 5007562.5 | S6: Date Paste | T6: AL BARAKAH DATE PASTE 12.5KG | U6: =VLOOKUP(T6,B:L,2,0) -> 0 | V6: =VLOOKUP(T6,B:L,5,0) -> 6912.5 | W6: =VLOOKUP(T6,B:L,8,0) -> 52000 | X6: =VLOOKUP(T6,B:L,11,0) -> 0 | Y6: =SUBTOTAL(9,U6:X6) -> 58912.5 | Z6: =AA6/Y6 -> 85 | AA6: =VLOOKUP(T6,B:Q,16,0) -> 5007562.5
A7: Date Paste Total | F7: 6912.5 | G7: 85 | H7: 587562.5 | I7: 52000 | J7: 85 | K7: 4420000 | O7: 58912.5 | P7: 85 | Q7: 5007562.5 | S7: Date Paste Total | U7: =SUM(U6) -> 0 | V7: =SUM(V6) -> 6912.5 | W7: =SUM(W6) -> 52000 | X7: =SUM(X6) -> 0 | Y7: =SUBTOTAL(9,U7:X7) -> 58912.5 | Z7: =AA7/Y7 -> 85 | AA7: =SUM(AA6) -> 5007562.5
A8: Date Powder | B8: 10KG AL BARAKAH DATE POWDER | F8: 66040 | G8: 272.5 | H8: 18090900 | O8: 66040 | P8: 272.5 | Q8: 18090900 | S8: Date Powder | T8: 10KG AL BARAKAH DATE POWDER | U8: =VLOOKUP(T8,B:L,2,0) -> 0 | V8: =VLOOKUP(T8,B:L,5,0) -> 66040 | W8: =VLOOKUP(T8,B:L,8,0) -> 0 | X8: =VLOOKUP(T8,B:L,11,0) -> 0 | Y8: =SUBTOTAL(9,U8:X8) -> 66040 | Z8: =AA8/Y8 -> 273.93852 | AA8: =VLOOKUP(T8,B:Q,16,0) -> 18090900
B9: 10KG AL BARAKAH DATE POWDER V1 | F9: 500 | G9: 270 | H9: 135000 | O9: 500 | P9: 270 | Q9: 135000 | T9: 10KG AL BARAKAH DATE POWDER V1 | U9: =VLOOKUP(T9,B:L,2,0) -> 0 | V9: =VLOOKUP(T9,B:L,5,0) -> 500 | W9: =VLOOKUP(T9,B:L,8,0) -> 0 | X9: =VLOOKUP(T9,B:L,11,0) -> 0 | Y9: =SUBTOTAL(9,U9:X9) -> 500 | Z9: =AA9/Y9 -> 270 | AA9: =VLOOKUP(T9,B:Q,16,0) -> 135000
B10: 10KG AL BARAKAH DATE POWDER V2 | F10: 11670 | G10: 215 | H10: 2509050 | O10: 11670 | P10: 215 | Q10: 2509050 | T10: 10KG AL BARAKAH DATE POWDER V2 | U10: =VLOOKUP(T10,B:L,2,0) -> 0 | V10: =VLOOKUP(T10,B:L,5,0) -> 11670 | W10: =VLOOKUP(T10,B:L,8,0) -> 0 | X10: =VLOOKUP(T10,B:L,11,0) -> 0 | Y10: =SUBTOTAL(9,U10:X10) -> 11670 | Z10: =AA10/Y10 -> 215 | AA10: =VLOOKUP(T10,B:Q,16,0) -> 2509050
B11: AL BARAKAH DATE POWDER | F11: 27700 | G11: 270 | H11: 7479000 | O11: 27700 | P11: 270 | Q11: 7479000 | T11: AL BARAKAH DATE POWDER | U11: =VLOOKUP(T11,B:L,2,0) -> 0 | V11: =VLOOKUP(T11,B:L,5,0) -> 27700 | W11: =VLOOKUP(T11,B:L,8,0) -> 0 | X11: =VLOOKUP(T11,B:L,11,0) -> 0 | Y11: =SUBTOTAL(9,U11:X11) -> 27700 | Z11: =AA11/Y11 -> 270 | AA11: =VLOOKUP(T11,B:Q,16,0) -> 7479000
B12: AL BARAKAH DEHYDRATED DATE POWDER - BULK PACK 10KG | L12: 80 | M12: 270 | N12: 21600 | O12: 80 | P12: 270 | Q12: 21600 | T12: AL BARAKAH DEHYDRATED DATE POWDER - BULK PACK 10KG | U12: =VLOOKUP(T12,B:L,2,0) -> 0 | V12: =VLOOKUP(T12,B:L,5,0) -> 0 | W12: =VLOOKUP(T12,B:L,8,0) -> 0 | X12: =VLOOKUP(T12,B:L,11,0) -> 80 | Y12: =SUBTOTAL(9,U12:X12) -> 80 | Z12: =AA12/Y12 -> 270 | AA12: =VLOOKUP(T12,B:Q,16,0) -> 21600
A13: Date Powder Total | F13: 105910 | G13: 251.07143 | H13: 28213950 | L13: 80 | M13: 270 | N13: 21600 | O13: 105990 | P13: 252.33333 | Q13: 28235550 | S13: Date Powder Total | U13: =SUM(U8:U12) -> 0 | V13: =SUM(V8:V12) -> 105910 | W13: =SUM(W8:W12) -> 0 | X13: =SUM(X12) -> 80 | Y13: =SUBTOTAL(9,U13:X13) -> 105990 | Z13: =AA13/Y13 -> 266.39825 | AA13: =SUM(AA8:AA12) -> 28235550
A14: Date Syrup | B14: AL BARAKAH DATE SYRUP(1.15KG X 12) | L14: 2472 | M14: 190 | N14: 469680 | O14: 2472 | P14: 190 | Q14: 469680 | S14: Date Syrup | T14: AL BARAKAH DATE SYRUP(1.15KG X 12) | U14: =VLOOKUP(T14,B:L,2,0) -> 0 | V14: =VLOOKUP(T14,B:L,5,0) -> 0 | W14: =VLOOKUP(T14,B:L,8,0) -> 0 | X14: =VLOOKUP(T14,B:L,11,0) -> 2472 | Y14: =SUBTOTAL(9,U14:X14) -> 2472 | Z14: =AA14/Y14 -> 190 | AA14: =VLOOKUP(T14,B:Q,16,0) -> 469680
B15: AL BARAKAH DATES SYRUP 25 kg Pack | C15: 200 | D15: 105.8 | E15: 21160 | F15: 45575 | G15: 108.46667 | H15: 4975335 | O15: 45775 | P15: 107.8 | Q15: 4996495 | T15: AL BARAKAH DATES SYRUP 25 kg Pack | U15: =VLOOKUP(T15,B:L,2,0) -> 200 | V15: =VLOOKUP(T15,B:L,5,0) -> 45575 | W15: =VLOOKUP(T15,B:L,8,0) -> 0 | X15: =VLOOKUP(T15,B:L,11,0) -> 0 | Y15: =SUBTOTAL(9,U15:X15) -> 45775 | Z15: =AA15/Y15 -> 109.15336 | AA15: =VLOOKUP(T15,B:Q,16,0) -> 4996495
B16: AL BARAKHA DATE SYRUP ( 400G packing) | F16: 5006.4 | G16: 344.86667 | H16: 1737276.5 | O16: 5006.4 | P16: 344.86667 | Q16: 1737276.5 | T16: AL BARAKHA DATE SYRUP ( 400G packing) | U16: =VLOOKUP(T16,B:L,2,0) -> 0 | V16: =VLOOKUP(T16,B:L,5,0) -> 5006.4 | W16: =VLOOKUP(T16,B:L,8,0) -> 0 | X16: =VLOOKUP(T16,B:L,11,0) -> 0 | Y16: =SUBTOTAL(9,U16:X16) -> 5006.4 | Z16: =AA16/Y16 -> 347.01112 | AA16: =VLOOKUP(T16,B:Q,16,0) -> 1737276.5
A17: Date Syrup Total | C17: 200 | D17: 105.8 | E17: 21160 | F17: 50581.4 | G17: 226.66667 | H17: 6712611.5 | L17: 2472 | M17: 190 | N17: 469680 | O17: 53253.4 | P17: 206.975 | Q17: 7203451.5 | S17: Date Syrup Total | U17: =SUM(U14:U16) -> 200 | V17: =SUM(V14:V16) -> 50581.4 | W17: =SUM(W14:W16) -> 0 | X17: =SUM(X14:X16) -> 2472 | Y17: =SUM(Y14:Y16) -> 53253.4 | Z17: =AA17/Y17 -> 135.26745 | AA17: =SUM(AA14:AA16) -> 7203451.5
A18: Dry Dates | B18: Al Barakah Chopped Dates Dried 10KG | F18: 980 | G18: 110 | H18: 107800 | O18: 980 | P18: 110 | Q18: 107800 | S18: Dry Dates | T18: Al Barakah Chopped Dates Dried 10KG | U18: =VLOOKUP(T18,B:L,2,0) -> 0 | V18: =VLOOKUP(T18,B:L,5,0) -> 980 | W18: =VLOOKUP(T18,B:L,8,0) -> 0 | X18: =VLOOKUP(T18,B:L,11,0) -> 0 | Y18: =SUBTOTAL(9,U18:X18) -> 980 | Z18: =AA18/Y18 -> 110 | AA18: =VLOOKUP(T18,B:Q,16,0) -> 107800
B19: Al Barakah Crushed Dates 10KG | F19: 630 | G19: 121.8 | H19: 73770 | O19: 630 | P19: 121.8 | Q19: 73770 | T19: Al Barakah Crushed Dates 10KG | U19: =VLOOKUP(T19,B:L,2,0) -> 0 | V19: =VLOOKUP(T19,B:L,5,0) -> 630 | W19: =VLOOKUP(T19,B:L,8,0) -> 0 | X19: =VLOOKUP(T19,B:L,11,0) -> 0 | Y19: =SUBTOTAL(9,U19:X19) -> 630 | Z19: =AA19/Y19 -> 117.09524 | AA19: =VLOOKUP(T19,B:Q,16,0) -> 73770
B20: BUSOOR DRY DATES GRADE - 2 | C20: 370 | D20: 241 | E20: 89170 | F20: 546 | G20: 241 | H20: 131586 | L20: 3549 | M20: 241 | N20: 855309 | O20: 4465 | P20: 241 | Q20: 1076065 | T20: BUSOOR DRY DATES GRADE - 2 | U20: =VLOOKUP(T20,B:L,2,0) -> 370 | V20: =VLOOKUP(T20,B:L,5,0) -> 546 | W20: =VLOOKUP(T20,B:L,8,0) -> 0 | X20: =VLOOKUP(T20,B:L,11,0) -> 3549 | Y20: =SUBTOTAL(9,U20:X20) -> 4465 | Z20: =AA20/Y20 -> 241 | AA20: =VLOOKUP(T20,B:Q,16,0) -> 1076065
B21: Dry Dates 12kg | C21: 588 | D21: 250 | E21: 147000 | O21: 588 | P21: 250 | Q21: 147000 | T21: Dry Dates 12kg | U21: =VLOOKUP(T21,B:L,2,0) -> 588 | V21: =VLOOKUP(T21,B:L,5,0) -> 0 | W21: =VLOOKUP(T21,B:L,8,0) -> 0 | X21: =VLOOKUP(T21,B:L,11,0) -> 0 | Y21: =SUBTOTAL(9,U21:X21) -> 588 | Z21: =AA21/Y21 -> 250 | AA21: =VLOOKUP(T21,B:Q,16,0) -> 147000
B22: Red Kharek Cut | F22: 90 | G22: 250 | H22: 22500 | L22: 87 | M22: 250 | N22: 21750 | O22: 177 | P22: 250 | Q22: 44250 | T22: Red Kharek Cut | U22: =VLOOKUP(T22,B:L,2,0) -> 0 | V22: =VLOOKUP(T22,B:L,5,0) -> 90 | W22: =VLOOKUP(T22,B:L,8,0) -> 0 | X22: =VLOOKUP(T22,B:L,11,0) -> 87 | Y22: =SUBTOTAL(9,U22:X22) -> 177 | Z22: =AA22/Y22 -> 250 | AA22: =VLOOKUP(T22,B:Q,16,0) -> 44250
A23: Dry Dates Total | C23: 958 | D23: 245.5 | E23: 236170 | F23: 2246 | G23: 200.95556 | H23: 335656 | L23: 3636 | M23: 245.5 | N23: 877059 | O23: 6840 | P23: 214.66154 | Q23: 1448885 | S23: Dry Dates Total | U23: =SUM(U18:U22) -> 958 | V23: =SUM(V18:V22) -> 2246 | W23: =SUM(W18:W22) -> 0 | X23: =SUM(X18:X22) -> 3636 | Y23: =SUM(Y18:Y22) -> 6840 | Z23: =AA23/Y23 -> 211.82529 | AA23: =SUM(AA18:AA22) -> 1448885
A24: Economical Dates | B24: 10 KG AL BARAKAH EMIRATES BLACK WET DATES | F24: 20 | G24: 172 | H24: 3440 | O24: 20 | P24: 172 | Q24: 3440 | S24: Economical Dates | T24: 10 KG AL BARAKAH EMIRATES BLACK WET DATES | U24: =VLOOKUP(T24,B:L,2,0) -> 0 | V24: =VLOOKUP(T24,B:L,5,0) -> 20 | W24: =VLOOKUP(T24,B:L,8,0) -> 0 | X24: =VLOOKUP(T24,B:L,11,0) -> 0 | Y24: =SUBTOTAL(9,U24:X24) -> 20 | Z24: =AA24/Y24 -> 172 | AA24: =VLOOKUP(T24,B:Q,16,0) -> 3440
B25: 10 KG FARD DATES EZAD | F25: 10890 | G25: 180.6 | H25: 1966734 | O25: 10890 | P25: 180.6 | Q25: 1966734 | T25: 10 KG FARD DATES EZAD | U25: =VLOOKUP(T25,B:L,2,0) -> 0 | V25: =VLOOKUP(T25,B:L,5,0) -> 10890 | W25: =VLOOKUP(T25,B:L,8,0) -> 0 | X25: =VLOOKUP(T25,B:L,11,0) -> 0 | Y25: =SUBTOTAL(9,U25:X25) -> 10890 | Z25: =AA25/Y25 -> 180.6 | AA25: =VLOOKUP(T25,B:Q,16,0) -> 1966734
B26: AL BARAKAH BARHI DATES 10KG | C26: 31700 | D26: 90.5 | E26: 2868850 | O26: 31700 | P26: 90.5 | Q26: 2868850 | T26: AL BARAKAH BARHI DATES 10KG | U26: =VLOOKUP(T26,B:L,2,0) -> 31700 | V26: =VLOOKUP(T26,B:L,5,0) -> 0 | W26: =VLOOKUP(T26,B:L,8,0) -> 0 | X26: =VLOOKUP(T26,B:L,11,0) -> 0 | Y26: =SUBTOTAL(9,U26:X26) -> 31700 | Z26: =AA26/Y26 -> 90.5 | AA26: =VLOOKUP(T26,B:Q,16,0) -> 2868850
B27: AL BARAKAH BARHI DATES 10KG RTV | C27: 690 | D27: 90.5 | E27: 62445 | O27: 690 | P27: 90.5 | Q27: 62445 | T27: AL BARAKAH BARHI DATES 10KG RTV | U27: =VLOOKUP(T27,B:L,2,0) -> 690 | V27: =VLOOKUP(T27,B:L,5,0) -> 0 | W27: =VLOOKUP(T27,B:L,8,0) -> 0 | X27: =VLOOKUP(T27,B:L,11,0) -> 0 | Y27: =SUBTOTAL(9,U27:X27) -> 690 | Z27: =AA27/Y27 -> 90.5 | AA27: =VLOOKUP(T27,B:Q,16,0) -> 62445
B28: AL BARAKAH FARD WET DATES PREMIUM 10KG | C28: 102970 | D28: 233 | E28: 23992010 | F28: 10 | G28: 233 | H28: 2330 | O28: 102980 | P28: 233 | Q28: 23994340 | T28: AL BARAKAH FARD WET DATES PREMIUM 10KG | U28: =VLOOKUP(T28,B:L,2,0) -> 102970 | V28: =VLOOKUP(T28,B:L,5,0) -> 10 | W28: =VLOOKUP(T28,B:L,8,0) -> 0 | X28: =VLOOKUP(T28,B:L,11,0) -> 0 | Y28: =SUBTOTAL(9,U28:X28) -> 102980 | Z28: =AA28/Y28 -> 233 | AA28: =VLOOKUP(T28,B:Q,16,0) -> 23994340
B29: AL BARAKAH FARD WET DATES PREMIUM 10KG RTV | C29: 3000 | D29: 233 | E29: 699000 | O29: 3000 | P29: 233 | Q29: 699000 | T29: AL BARAKAH FARD WET DATES PREMIUM 10KG RTV | U29: =VLOOKUP(T29,B:L,2,0) -> 3000 | V29: =VLOOKUP(T29,B:L,5,0) -> 0 | W29: =VLOOKUP(T29,B:L,8,0) -> 0 | X29: =VLOOKUP(T29,B:L,11,0) -> 0 | Y29: =SUBTOTAL(9,U29:X29) -> 3000 | Z29: =AA29/Y29 -> 233 | AA29: =VLOOKUP(T29,B:Q,16,0) -> 699000
B30: AL BARAKAH FARD WET DATES STANDARD 10KG | C30: 62460 | D30: 208 | E30: 12991680 | F30: 150 | G30: 208 | H30: 31200 | O30: 62610 | P30: 208 | Q30: 13022880 | T30: AL BARAKAH FARD WET DATES STANDARD 10KG | U30: =VLOOKUP(T30,B:L,2,0) -> 62460 | V30: =VLOOKUP(T30,B:L,5,0) -> 150 | W30: =VLOOKUP(T30,B:L,8,0) -> 0 | X30: =VLOOKUP(T30,B:L,11,0) -> 0 | Y30: =SUBTOTAL(9,U30:X30) -> 62610 | Z30: =AA30/Y30 -> 208 | AA30: =VLOOKUP(T30,B:Q,16,0) -> 13022880
B31: AL BARAKAH KHALAS DATES AFCTN-10KG | F31: 110 | G31: 116 | H31: 12760 | O31: 110 | P31: 116 | Q31: 12760 | T31: AL BARAKAH KHALAS DATES AFCTN-10KG | U31: =VLOOKUP(T31,B:L,2,0) -> 0 | V31: =VLOOKUP(T31,B:L,5,0) -> 110 | W31: =VLOOKUP(T31,B:L,8,0) -> 0 | X31: =VLOOKUP(T31,B:L,11,0) -> 0 | Y31: =SUBTOTAL(9,U31:X31) -> 110 | Z31: =AA31/Y31 -> 116 | AA31: =VLOOKUP(T31,B:Q,16,0) -> 12760
B32: AL BARAKAH KHALAS DATES Premium 10kgs | C32: 188720 | D32: 116 | E32: 21891520 | L32: 57.7 | M32: 116 | N32: 6693.2 | O32: 188777.7 | P32: 116 | Q32: 21898213 | T32: AL BARAKAH KHALAS DATES Premium 10kgs | U32: =VLOOKUP(T32,B:L,2,0) -> 188720 | V32: =VLOOKUP(T32,B:L,5,0) -> 0 | W32: =VLOOKUP(T32,B:L,8,0) -> 0 | X32: =VLOOKUP(T32,B:L,11,0) -> 57.7 | Y32: =SUBTOTAL(9,U32:X32) -> 188777.7 | Z32: =AA32/Y32 -> 116 | AA32: =VLOOKUP(T32,B:Q,16,0) -> 21898213
B33: AL BARAKAH KHALAS DATES Premium 10kgs RTV | C33: 0 | D33: 116 | E33: 0 | O33: 0 | P33: 116 | Q33: 0 | T33: AL BARAKAH KHALAS DATES Premium 10kgs RTV | U33: =VLOOKUP(T33,B:L,2,0) -> 0 | V33: =VLOOKUP(T33,B:L,5,0) -> 0 | W33: =VLOOKUP(T33,B:L,8,0) -> 0 | X33: =VLOOKUP(T33,B:L,11,0) -> 0 | Y33: =SUBTOTAL(9,U33:X33) -> 0 | Z33: =AA33/Y33 -> #DIV/0! | AA33: =VLOOKUP(T33,B:Q,16,0) -> 0
B34: AL BARAKAH KHALAS DATES Seedless 10kgs | C34: 2855 | D34: 126 | E34: 359730 | O34: 2855 | P34: 126 | Q34: 359730 | T34: AL BARAKAH KHALAS DATES Seedless 10kgs | U34: =VLOOKUP(T34,B:L,2,0) -> 2855 | V34: =VLOOKUP(T34,B:L,5,0) -> 0 | W34: =VLOOKUP(T34,B:L,8,0) -> 0 | X34: =VLOOKUP(T34,B:L,11,0) -> 0 | Y34: =SUBTOTAL(9,U34:X34) -> 2855 | Z34: =AA34/Y34 -> 126 | AA34: =VLOOKUP(T34,B:Q,16,0) -> 359730
B35: AL BARAKAH KHANEIZI DATES 10 KG | F35: 10 | G35: 205 | H35: 2050 | O35: 10 | P35: 205 | Q35: 2050 | T35: AL BARAKAH KHANEIZI DATES 10 KG | U35: =VLOOKUP(T35,B:L,2,0) -> 0 | V35: =VLOOKUP(T35,B:L,5,0) -> 10 | W35: =VLOOKUP(T35,B:L,8,0) -> 0 | X35: =VLOOKUP(T35,B:L,11,0) -> 0 | Y35: =SUBTOTAL(9,U35:X35) -> 10 | Z35: =AA35/Y35 -> 205 | AA35: =VLOOKUP(T35,B:Q,16,0) -> 2050
B36: AL BARAKAH LULU WET DATES (BLACK) 10KG | F36: 170 | G36: 182 | H36: 30940 | O36: 170 | P36: 182 | Q36: 30940 | T36: AL BARAKAH LULU WET DATES (BLACK) 10KG | U36: =VLOOKUP(T36,B:L,2,0) -> 0 | V36: =VLOOKUP(T36,B:L,5,0) -> 170 | W36: =VLOOKUP(T36,B:L,8,0) -> 0 | X36: =VLOOKUP(T36,B:L,11,0) -> 0 | Y36: =SUBTOTAL(9,U36:X36) -> 170 | Z36: =AA36/Y36 -> 182 | AA36: =VLOOKUP(T36,B:Q,16,0) -> 30940
B37: AL BARAKAH LULU WET DATES (RED) 10KG | F37: 2410 | G37: 157 | H37: 378370 | O37: 2410 | P37: 157 | Q37: 378370 | T37: AL BARAKAH LULU WET DATES (RED) 10KG | U37: =VLOOKUP(T37,B:L,2,0) -> 0 | V37: =VLOOKUP(T37,B:L,5,0) -> 2410 | W37: =VLOOKUP(T37,B:L,8,0) -> 0 | X37: =VLOOKUP(T37,B:L,11,0) -> 0 | Y37: =SUBTOTAL(9,U37:X37) -> 2410 | Z37: =AA37/Y37 -> 157 | AA37: =VLOOKUP(T37,B:Q,16,0) -> 378370
B38: AL BARAKAH REZIZ DATES Premium 10kgs | C38: 8950 | D38: 87.7 | E38: 784915 | O38: 8950 | P38: 87.7 | Q38: 784915 | T38: AL BARAKAH REZIZ DATES Premium 10kgs | U38: =VLOOKUP(T38,B:L,2,0) -> 8950 | V38: =VLOOKUP(T38,B:L,5,0) -> 0 | W38: =VLOOKUP(T38,B:L,8,0) -> 0 | X38: =VLOOKUP(T38,B:L,11,0) -> 0 | Y38: =SUBTOTAL(9,U38:X38) -> 8950 | Z38: =AA38/Y38 -> 87.7 | AA38: =VLOOKUP(T38,B:Q,16,0) -> 784915
B39: AL BARAKAH SUFRI DATES Premium 10kgs | C39: 3400 | D39: 114 | E39: 387600 | O39: 3400 | P39: 114 | Q39: 387600 | T39: AL BARAKAH SUFRI DATES Premium 10kgs | U39: =VLOOKUP(T39,B:L,2,0) -> 3400 | V39: =VLOOKUP(T39,B:L,5,0) -> 0 | W39: =VLOOKUP(T39,B:L,8,0) -> 0 | X39: =VLOOKUP(T39,B:L,11,0) -> 0 | Y39: =SUBTOTAL(9,U39:X39) -> 3400 | Z39: =AA39/Y39 -> 114 | AA39: =VLOOKUP(T39,B:Q,16,0) -> 387600
B40: Buman Dates | F40: 30 | G40: 98.6 | H40: 2958 | O40: 30 | P40: 98.6 | Q40: 2958 | T40: Buman Dates | U40: =VLOOKUP(T40,B:L,2,0) -> 0 | V40: =VLOOKUP(T40,B:L,5,0) -> 30 | W40: =VLOOKUP(T40,B:L,8,0) -> 0 | X40: =VLOOKUP(T40,B:L,11,0) -> 0 | Y40: =SUBTOTAL(9,U40:X40) -> 30 | Z40: =AA40/Y40 -> 98.6 | AA40: =VLOOKUP(T40,B:Q,16,0) -> 2958
B41: Delmonte Royal Arabian dates 500g RTV | C41: 20064 | D41: 116 | E41: 2327424 | O41: 20064 | P41: 116 | Q41: 2327424 | T41: Delmonte Royal Arabian dates 500g RTV | U41: =VLOOKUP(T41,B:L,2,0) -> 20064 | V41: =VLOOKUP(T41,B:L,5,0) -> 0 | W41: =VLOOKUP(T41,B:L,8,0) -> 0 | X41: =VLOOKUP(T41,B:L,11,0) -> 0 | Y41: =SUBTOTAL(9,U41:X41) -> 20064 | Z41: =AA41/Y41 -> 116 | AA41: =VLOOKUP(T41,B:Q,16,0) -> 2327424
...

Sheet 12th May 26
A1: Savla Foods & Rishi Cold Storage Pvt Ltd | AA1: Overdays | AB1: Bucket | AD1: Overdays | AE1: Bucket
A2: Report Date : | B2: =TODAY() -> 46154 | AA2: 0 | AB2: < 6 Months | AD2: 0 | AE2: <30 Days
A3: As On Date : | B3: =TODAY()-1 -> 46153 | AA3: 180 | AB3: 06-12 Months | AD3: 30 | AE3: 30-60 Days
A4: Stock Details Report | J4: =TODAY()-1 -> 46153 | W4: =TODAY() -> 46154 | AA4: 365 | AB4: 12-18 Months | AD4: 60 | AE4: 60-90 Days
H5: =SUBTOTAL(9,H7:H1000033) -> 84890.5 | J5: =SUBTOTAL(9,J7:J1000033) -> 713510.3 | K5: 46153 | V5: =SUBTOTAL(9,V7:V1000033) -> 2.9335049e+08 | AA5: 540 | AB5: 18-24 Months | AD5: 90 | AE5: 90-180 Days
A6: Inward Dt | B6: Unit | C6: Inward No | D6: Item Description | E6: Item Mark | F6: Vakkal | G6: Lot No | H6: Net Qty On Cartons | I6: Weight KG | J6: Total Inventory Kgs | K6: Item Mark | L6: Spl. Remarks | M6: Group Name* | N6: Sub Group Name* | O6: Sub Sub Group Name* | P6: Item Display Name* | Q6: Tally Name | R6: Company Name | S6: Storage Location | T6: Exporter | U6: Last Purchase Rate | V6: Value | W6: Ageing | X6: Ageing Bucket | Y6: DAYS AGEING | AA6: 730 | AB6: >24 Months | AD6: 180 | AE6: >181 Days
A7: 24/07/2023 | B7: D-39 | C7: GR5903 | D7: KHAJUR BOX 10 | E7: WHITE POWDER | F7: V-2 | G7: 56059 | H7: 37 | I7: 10 | J7: =I7*H7 -> 370 | K7: Date Powder | L7: V2 | M7: {=VLOOKUP(Q7,[1]CDPL!$A:$D,{3,4},0)} -> DATES | N7: Powder | O7: AL BARAKAH | P7: 10KG AL BARAKAH DATE POWDER V2 | Q7: 10KG AL BARAKAH DATE POWDER V2 | R7: CDPL | S7: Savla | T7: AL BARAKAH | U7: 215 | V7: =U7*J7 -> 79550 | W7: =$W$4-A7 -> 1023 | X7: =VLOOKUP(W7,$AA$2:$AB$6,2) -> >24 Months | Y7: =VLOOKUP(W7,$AD$2:$AE$6,2) -> >181 Days
A8: 27/07/2024 | B8: D-39 | C8: GR6534 | D8: KHAJUR POWDER BOX 10 | E8: WHITE | F8: V-2 | G8: 93289 | H8: 114 | I8: 10 | J8: =I8*H8 -> 1140 | K8: Date Powder | L8: V2 | M8: {=VLOOKUP(Q8,[1]CDPL!$A:$D,{3,4},0)} -> DATES | N8: Powder | O8: AL BARAKAH | P8: 10KG AL BARAKAH DATE POWDER V2 | Q8: 10KG AL BARAKAH DATE POWDER V2 | R8: CDPL | S8: Savla | T8: AL BARAKAH | U8: 215 | V8: =U8*J8 -> 245100 | W8: =$W$4-A8 -> 654 | X8: =VLOOKUP(W8,$AA$2:$AB$6,2) -> 18-24 Months | Y8: =VLOOKUP(W8,$AD$2:$AE$6,2) -> >181 Days
A9: 27/07/2024 | B9: D-39 | C9: GR6534 | D9: KHAJUR POWDER BOX 10 | E9: WHITE | F9: V-2 | G9: 93289 | H9: 77 | I9: 10 | J9: =I9*H9 -> 770 | K9: Date Powder | L9: V2 | M9: {=VLOOKUP(Q9,[1]CDPL!$A:$D,{3,4},0)} -> DATES | N9: Powder | O9: AL BARAKAH | P9: 10KG AL BARAKAH DATE POWDER V2 | Q9: 10KG AL BARAKAH DATE POWDER V2 | R9: CDPL | S9: Savla | T9: AL BARAKAH | U9: 215 | V9: =U9*J9 -> 165550 | W9: =$W$4-A9 -> 654 | X9: =VLOOKUP(W9,$AA$2:$AB$6,2) -> 18-24 Months | Y9: =VLOOKUP(W9,$AD$2:$AE$6,2) -> >181 Days
A10: 27/09/2024 | B10: D-39 | C10: GR10651 | D10: KHAJUR BOX 10 | E10: WHITE | F10: - | G10: 110715 | H10: 97 | I10: 10 | J10: =I10*H10 -> 970 | K10: Dry Dates | L10: Chopped Date | M10: {=VLOOKUP(Q10,[1]CDPL!$A:$D,{3,4},0)} -> DATES | N10: Diced | O10: AL BARAKAH | P10: Al Barakah Chopped Dates Dried 10KG | Q10: AL BARAKAH CHOPPED DATES | R10: CDPL | S10: Savla | T10: AL BARAKAH | U10: 110 | V10: =U10*J10 -> 106700 | W10: =$W$4-A10 -> 592 | X10: =VLOOKUP(W10,$AA$2:$AB$6,2) -> 18-24 Months | Y10: =VLOOKUP(W10,$AD$2:$AE$6,2) -> >181 Days
A11: 25/11/2024 | B11: D-39 | C11: GR14538 | D11: KHAJUR BOX 10 | E11: SAAD/ BROWN | F11: BLACK | G11: 121319 | H11: 17 | I11: 10 | J11: =I11*H11 -> 170 | K11: Economical Dates | L11: Lulu | M11: {=VLOOKUP(Q11,[1]CDPL!$A:$D,{3,4},0)} -> DATES | N11: Lulu | O11: Black | P11: AL BARAKAH LULU WET DATES (BLACK) 10KG | Q11: AL BARAKAH LULU BLACK DATES-10KG | R11: CDPL | S11: Savla | T11: AL BARAKAH | U11: 182 | V11: =U11*J11 -> 30940 | W11: =$W$4-A11 -> 533 | X11: =VLOOKUP(W11,$AA$2:$AB$6,2) -> 12-18 Months | Y11: =VLOOKUP(W11,$AD$2:$AE$6,2) -> >181 Days
A12: 10/12/2024 | B12: D-39 | C12: GR15535 | D12: KHAJUR BOX 10 | E12: DATE CRUSHED | F12: WHITE | G12: 123526 | H12: 60 | I12: 10 | J12: =I12*H12 -> 600 | K12: Dry Dates | L12: Crushed Date | M12: {=VLOOKUP(Q12,[1]CDPL!$A:$D,{3,4},0)} -> DATES | N12: Diced | O12: AL BARAKAH | P12: Al Barakah Crushed Dates 10KG | Q12: AL BARAKAH CRUSHED DATES 10KG | R12: CDPL | S12: Savla | T12: AL BARAKAH | U12: 116.6 | V12: =U12*J12 -> 69960 | W12: =$W$4-A12 -> 518 | X12: =VLOOKUP(W12,$AA$2:$AB$6,2) -> 12-18 Months | Y12: =VLOOKUP(W12,$AD$2:$AE$6,2) -> >181 Days
A13: 10/12/2024 | B13: D-39 | C13: GR15535 | D13: KHAJUR BOX 10 | E13: DATE POWDER V2 | F13: WHITE | G13: 123525 | H13: 918 | I13: 10 | J13: =I13*H13 -> 9180 | K13: Date Powder | L13: V2 | M13: {=VLOOKUP(Q13,[1]CDPL!$A:$D,{3,4},0)} -> DATES | N13: Powder | O13: AL BARAKAH | P13: 10KG AL BARAKAH DATE POWDER V2 | Q13: 10KG AL BARAKAH DATE POWDER V2 | R13: CDPL | S13: Savla | T13: AL BARAKAH | U13: 215 | V13: =U13*J13 -> 1973700 | W13: =$W$4-A13 -> 518 | X13: =VLOOKUP(W13,$AA$2:$AB$6,2) -> 12-18 Months | Y13: =VLOOKUP(W13,$AD$2:$AE$6,2) -> >181 Days
A14: 15/01/2025 | B14: D-514 | C14: GR7072 | D14: KHAJUR BOX 5 | E14: SIAFA AJWA G | F14: 74228 | G14: 78999 | H14: 45 | I14: 5 | J14: =I14*H14 -> 225 | K14: Premium Dates | L14: Ajwa | M14: {=VLOOKUP(Q14,[1]CDPL!$A:$D,{3,4},0)} -> DATES | N14: Ajwa | O14: Premium | P14: Ajwa Regular | Q14: Wet Dates Ajwa | R14: CDPL | S14: Savla | T14: Local | U14: 980 | V14: =U14*J14 -> 220500 | W14: =$W$4-A14 -> 482 | X14: =VLOOKUP(W14,$AA$2:$AB$6,2) -> 12-18 Months | Y14: =VLOOKUP(W14,$AD$2:$AE$6,2) -> >181 Days
A15: 15/01/2025 | B15: D-514 | C15: GR7072 | D15: KHAJUR BOX 5 | E15: SIFA AJWA S | F15: 74229 | G15: 79000 | H15: 31 | I15: 5 | J15: =I15*H15 -> 155 | K15: Premium Dates | L15: Ajwa | M15: {=VLOOKUP(Q15,[1]CDPL!$A:$D,{3,4},0)} -> DATES | N15: Ajwa | O15: Premium | P15: Ajwa Regular | Q15: Wet Dates Ajwa | R15: CDPL | S15: Savla | T15: Local | U15: 980 | V15: =U15*J15 -> 151900 | W15: =$W$4-A15 -> 482 | X15: =VLOOKUP(W15,$AA$2:$AB$6,2) -> 12-18 Months | Y15: =VLOOKUP(W15,$AD$2:$AE$6,2) -> >181 Days
A16: 10/02/2025 | B16: D-514 | C16: GR7683 | D16: KHAJUR BOX 15 | E16: DATES WET MEDJOUL BABY | F16: 5KGX3 | G16: 79912 | H16: 9 | I16: 15 | J16: =I16*H16 -> 135 | K16: Premium Dates | L16: Medjoul-Mini | M16: {=VLOOKUP(Q16,[1]CDPL!$A:$D,{3,4},0)} -> DATES | N16: Medjoul-Junior | O16: Mini | P16: MDJL Mini Dates 5 kg | Q16: WET DATES MEDJOUL BULK MINI (5) | R16: CDPL | S16: Savla | T16: Hadiklaim | U16: 477 | V16: =U16*J16 -> 64395 | W16: =$W$4-A16 -> 456 | X16: =VLOOKUP(W16,$AA$2:$AB$6,2) -> 12-18 Months | Y16: =VLOOKUP(W16,$AD$2:$AE$6,2) -> >181 Days
A17: 10/02/2025 | B17: D-514 | C17: GR7683 | D17: KHAJUR BOX (M) 8 | E17: DATE MEDJOUL KING SOLOMON | F17: 500 GM | G17: 79910 | H17: 59 | I17: 8 | J17: =I17*H17 -> 472 | K17: Premium Dates | L17: Medjoul-Large | M17: {=VLOOKUP(Q17,[1]CDPL!$A:$D,{3,4},0)} -> DATES | N17: Medjoul-Large | O17: Large | P17: Medjoul Dates Large 5 kg | Q17: WET DATES MEDJOUL BULK LARGE (5) | R17: CDPL | S17: Savla | T17: Hadiklaim | U17: 817 | V17: =U17*J17 -> 385624 | W17: =$W$4-A17 -> 456 | X17: =VLOOKUP(W17,$AA$2:$AB$6,2) -> 12-18 Months | Y17: =VLOOKUP(W17,$AD$2:$AE$6,2) -> >181 Days
A18: 10/02/2025 | B18: D-514 | C18: GR7683 | D18: KHAJUR BOX (M) 8 | E18: DATE MEDJOUL KING SOLOMON | F18: 1 KG | G18: 79911 | H18: 7 | I18: 8 | J18: =I18*H18 -> 56 | K18: Premium Dates | L18: Medjoul-Jumbo | M18: {=VLOOKUP(Q18,[1]CDPL!$A:$D,{3,4},0)} -> DATES | N18: Medjoul-Jumbo | O18: JUMBO | P18: MEDJOUL DATES JUMBO 8 kg | Q18: WET DATES MEDJOUL JUMBO | R18: CDPL | S18: Savla | T18: Hadiklaim | U18: 1045 | V18: =U18*J18 -> 58520 | W18: =$W$4-A18 -> 456 | X18: =VLOOKUP(W18,$AA$2:$AB$6,2) -> 12-18 Months | Y18: =VLOOKUP(W18,$AD$2:$AE$6,2) -> >181 Days
A19: 11/02/2025 | B19: D-514 | C19: GR7699 | D19: KHAJUR BOX (M) 5 | E19: MEDJOUL SUPER JUMBO | F19: NO.2 | G19: 79952 | H19: 9 | I19: 5 | J19: =I19*H19 -> 45 | K19: Premium Dates | L19: Medjoul-Rej | M19: {=VLOOKUP(Q19,[1]CFPL!$A:$D,{3,4},0)} -> DATES | N19: OFF-GRADE DATES | O19: S.JUMBO | P19: MEDJOUL DATES SUPER JUMBO 5KG | Q19: Off-Grade Dates | R19: CDPL | S19: Savla | T19: Hadiklaim | U19: 1139 | V19: =U19*J19 -> 51255 | W19: =$W$4-A19 -> 455 | X19: =VLOOKUP(W19,$AA$2:$AB$6,2) -> 12-18 Months | Y19: =VLOOKUP(W19,$AD$2:$AE$6,2) -> >181 Days
A20: 26/02/2025 | B20: D-39 | C20: GR20724 | D20: KHAJUR BOX 10 | E20: - | F20: KING SOLOMON | G20: 133830 | H20: 119 | I20: 8 | J20: =I20*H20 -> 952 | K20: Premium Dates | L20: Medjoul-Large | M20: {=VLOOKUP(Q20,[1]CFPL!$A:$D,{3,4},0)} -> DATES | N20: Medjoul-Medium | O20: Large | P20: Medjoul Tajir RTV | Q20: King Solomon Medjoul Dates Medium 500 Gm | R20: CDPL | S20: Savla | T20: Hadiklaim | U20: 817 | V20: =U20*J20 -> 777784 | W20: =$W$4-A20 -> 440 | X20: =VLOOKUP(W20,$AA$2:$AB$6,2) -> 12-18 Months | Y20: =VLOOKUP(W20,$AD$2:$AE$6,2) -> >181 Days
A21: 19/03/2025 | B21: D-514 | C21: GR8554 | D21: KHAJUR BOX (M) 5 | E21: MDJL LARGE | F21: NO-2 | G21: 81382 | H21: 4 | I21: 5 | J21: =I21*H21 -> 20 | K21: Premium Dates | L21: Medjoul-Rej | M21: {=VLOOKUP(Q21,[1]CFPL!$A:$D,{3,4},0)} -> DATES | N21: OFF-GRADE DATES | O21: Large | P21: Medjoul Large No.2 Sorted | Q21: Off-Grade Dates | R21: CDPL | S21: Savla | T21: Hadiklaim | U21: 200 | V21: =U21*J21 -> 4000 | W21: =$W$4-A21 -> 419 | X21: =VLOOKUP(W21,$AA$2:$AB$6,2) -> 12-18 Months | Y21: =VLOOKUP(W21,$AD$2:$AE$6,2) -> >181 Days
A22: 21/03/2025 | B22: D-514 | C22: GR8597 | D22: KHAJUR BOX 5 | E22: ROYAL DELIGHT | F22: AJWA | G22: 81466 | H22: 73 | I22: 5 | J22: =I22*H22 -> 365 | K22: Premium Dates | L22: Ajwa | M22: {=VLOOKUP(Q22,[1]CDPL!$A:$D,{3,4},0)} -> DATES | N22: Ajwa | O22: RTV | P22: Royal Delight Ajwa 5kg | Q22: Royal Delight Ajwa Dates 5 Kgs | R22: CDPL | S22: Savla | T22: Local | U22: 980 | V22: =U22*J22 -> 357700 | W22: =$W$4-A22 -> 417 | X22: =VLOOKUP(W22,$AA$2:$AB$6,2) -> 12-18 Months | Y22: =VLOOKUP(W22,$AD$2:$AE$6,2) -> >181 Days
A23: 31/03/2025 | B23: D-514 | C23: GR8855 | D23: KHAJUR BOX 10 | E23: WANAN DATES | F23: 12.5 KG | G23: 81944 | H23: 1 | I23: 12.5 | J23: =I23*H23 -> 12.5 | K23: Organic Dates | L23: Org Wanan-Large | M23: {=VLOOKUP(Q23,[1]CFPL!$A:$D,{3,4},0)} -> DATES | N23: Wanan | O23: Large | P23: Organic Wanan Pr.Large | Q23: Organic Wanan Premium Large | R23: CDPL | S23: Savla | T23: NAKHEEL | U23: 715 | V23: =U23*J23 -> 8937.5 | W23: =$W$4-A23 -> 407 | X23: =VLOOKUP(W23,$AA$2:$AB$6,2) -> 12-18 Months | Y23: =VLOOKUP(W23,$AD$2:$AE$6,2) -> >181 Days
A24: 31/03/2025 | B24: D-514 | C24: GR8855 | D24: KHAJUR BOX (M)12 | E24: SEQEE DATES | F24: 12.5 KG | G24: 81942 | H24: 2 | I24: 12.5 | J24: =I24*H24 -> 25 | K24: Organic Dates | L24: Org Seqee-Large | M24: {=VLOOKUP(Q24,[1]CFPL!$A:$D,{3,4},0)} -> DATES | N24: Seqee | O24: Large | P24: Organic Seqee Pr.Large | Q24: Organic Seqee Premium Large | R24: CDPL | S24: Savla | T24: NAKHEEL | U24: 641 | V24: =U24*J24 -> 16025 | W24: =$W$4-A24 -> 407 | X24: =VLOOKUP(W24,$AA$2:$AB$6,2) -> 12-18 Months | Y24: =VLOOKUP(W24,$AD$2:$AE$6,2) -> >181 Days
A25: 31/03/2025 | B25: D-514 | C25: GR8855 | D25: KHAJUR BOX (M)12 | E25: KHIDRI | F25: 12.5 KG | G25: 81943 | H25: 1 | I25: 12.5 | J25: =I25*H25 -> 12.5 | K25: Organic Dates | L25: Org Khidri-Med | M25: {=VLOOKUP(Q25,[1]CFPL!$A:$D,{3,4},0)} -> DATES | N25: Khidri | O25: Medium | P25: Organic Khidri Pr.Medium | Q25: Organic Khidri Premium Medium | R25: CDPL | S25: Savla | T25: NAKHEEL | U25: 403 | V25: =U25*J25 -> 5037.5 | W25: =$W$4-A25 -> 407 | X25: =VLOOKUP(W25,$AA$2:$AB$6,2) -> 12-18 Months | Y25: =VLOOKUP(W25,$AD$2:$AE$6,2) -> >181 Days
A26: 07/04/2025 | B26: D-39 | C26: GR465 | D26: KHAJUR BOX 10 | E26: CRUSHED WHITE | F26: - | G26: 138382 | H26: 3 | I26: 10 | J26: =I26*H26 -> 30 | K26: Dry Dates | L26: Crushed Date | M26: {=VLOOKUP(Q26,[1]CDPL!$A:$D,{3,4},0)} -> DATES | N26: Diced | O26: AL BARAKAH | P26: Al Barakah Crushed Dates 10KG | Q26: AL BARAKAH CRUSHED DATES 10KG | R26: CDPL | S26: Savla | T26: AL BARAKAH | U26: 127 | V26: =U26*J26 -> 3810 | W26: =$W$4-A26 -> 400 | X26: =VLOOKUP(W26,$AA$2:$AB$6,2) -> 12-18 Months | Y26: =VLOOKUP(W26,$AD$2:$AE$6,2) -> >181 Days
A27: 07/04/2025 | B27: D-514 | C27: GR117 | D27: KHAJUR BOX (M)12 | E27: ORGANIC WANAN | F27: PR.JUMBO | G27: 76578 | H27: 11 | I27: 12.5 | J27: =I27*H27 -> 137.5 | K27: Organic Dates | L27: Org Wanan-Jumbo | M27: {=VLOOKUP(Q27,[1]CFPL!$A:$D,{3,4},0)} -> DATES | N27: Wanan | O27: Jumbo | P27: Organic Wanan Pr.Jumbo | Q27: Organic Wanan Premium Jumbo | R27: CDPL | S27: Savla | T27: NAKHEEL | U27: 938 | V27: =U27*J27 -> 128975 | W27: =$W$4-A27 -> 400 | X27: =VLOOKUP(W27,$AA$2:$AB$6,2) -> 12-18 Months | Y27: =VLOOKUP(W27,$AD$2:$AE$6,2) -> >181 Days
A28: 07/04/2025 | B28: D-514 | C28: GR117 | D28: KHAJUR BOX (M)12 | E28: ORGANIC WANAN | F28: PR.LARGE | G28: 76579 | H28: 10 | I28: 12.5 | J28: =I28*H28 -> 125 | K28: Organic Dates | L28: Org Wanan-Large | M28: {=VLOOKUP(Q28,[1]CFPL!$A:$D,{3,4},0)} -> DATES | N28: Wanan | O28: Large | P28: Organic Wanan Pr.Large | Q28: Organic Wanan Premium Large | R28: CDPL | S28: Savla | T28: NAKHEEL | U28: 715 | V28: =U28*J28 -> 89375 | W28: =$W$4-A28 -> 400 | X28: =VLOOKUP(W28,$AA$2:$AB$6,2) -> 12-18 Months | Y28: =VLOOKUP(W28,$AD$2:$AE$6,2) -> >181 Days
A29: 30/04/2025 | B29: D-514 | C29: GR748 | D29: KHAJUR BOX 5 | E29: RABIA DETLAND DATES | F29: - | G29: 2056 | H29: 5 | I29: 5 | J29: =I29*H29 -> 25 | K29: Economical Dates | L29: Rabia | M29: {=VLOOKUP(Q29,[1]CDPL!$A:$D,{3,4},0)} -> DATES | N29: Rabia | O29: Rabia | P29: Rabia Dates 5kg | Q29: Wet Dates (Rabia) | R29: CDPL | S29: Savla | T29: Local | U29: 187.5 | V29: =U29*J29 -> 4687.5 | W29: =$W$4-A29 -> 377 | X29: =VLOOKUP(W29,$AA$2:$AB$6,2) -> 12-18 Months | Y29: =VLOOKUP(W29,$AD$2:$AE$6,2) -> >181 Days
A30: 16/05/2025 | B30: D-39 | C30: GR3027 | D30: KHAJUR BOX 10 | E30: DATE POWDER | F30: - | G30: 142972 | H30: 50 | I30: 10 | J30: =I30*H30 -> 500 | K30: Date Powder | L30: V1 | M30: {=VLOOKUP(Q30,[1]CDPL!$A:$D,{3,4},0)} -> DATES | N30: Powder | O30: AL BARAKAH | P30: 10KG AL BARAKAH DATE POWDER V1 | Q30: 10KG AL BARAKAH DATE POWDER V1 | R30: CDPL | S30: Savla | T30: AL BARAKAH | U30: 270 | V30: =U30*J30 -> 135000 | W30: =$W$4-A30 -> 361 | X30: =VLOOKUP(W30,$AA$2:$AB$6,2) -> 06-12 Months | Y30: =VLOOKUP(W30,$AD$2:$AE$6,2) -> >181 Days
A31: 29/06/2025 | B31: D-39 | C31: GR5609 | D31: KHAJUR POWDER BOX 10 | E31: AL BARAKAH | F31: MIX | G31: 147739 | H31: 32 | I31: 10 | J31: =I31*H31 -> 320 | K31: Date Powder | L31: V1 | M31: {=VLOOKUP(Q31,[1]CDPL!$A:$D,{3,4},0)} -> DATES | N31: Powder | O31: AL BARAKAH | P31: 10KG AL BARAKAH DATE POWDER | Q31: 10KG AL BARAKAH DATE POWDER V1 | R31: CDPL | S31: Savla | T31: AL BARAKAH | U31: 270 | V31: =U31*J31 -> 86400 | W31: =$W$4-A31 -> 317 | X31: =VLOOKUP(W31,$AA$2:$AB$6,2) -> 06-12 Months | Y31: =VLOOKUP(W31,$AD$2:$AE$6,2) -> >181 Days
A32: 24/09/2025 | B32: D-39 | C32: GR10777 | D32: KHAJUR POWDER BOX 10 | E32: AL BARAKAH | F32: - | G32: 156985 | H32: 1099 | I32: 10 | J32: =I32*H32 -> 10990 | K32: Date Powder | L32: V1 | M32: {=VLOOKUP(Q32,[1]CDPL!$A:$D,{3,4},0)} -> DATES | N32: Powder | O32: AL BARAKAH | P32: 10KG AL BARAKAH DATE POWDER | Q32: 10KG AL BARAKAH DATE POWDER V1 | R32: CDPL | S32: Savla | T32: AL BARAKAH | U32: 280 | V32: =U32*J32 -> 3077200 | W32: =$W$4-A32 -> 230 | X32: =VLOOKUP(W32,$AA$2:$AB$6,2) -> 06-12 Months | Y32: =VLOOKUP(W32,$AD$2:$AE$6,2) -> >181 Days
A33: 04/11/2025 | B33: D-39 | C33: GR13565 | D33: KHAJUR BOX KIMIA 6 | E33: KIMIA GOLD | F33: - | G33: 164985 | H33: 342 | I33: 6.8 | J33: =I33*H33 -> 2325.6 | K33: Economical Dates | L33: Mazafati | M33: {=VLOOKUP(Q33,[1]CDPL!$A:$D,{3,4},0)} -> DATES | N33: Kimia | O33: Local | P33: Wet Dates (Mazafati) | Q33: Wet Dates (Mazafati) | R33: CDPL | S33: Savla | T33: Local | U33: 200 | V33: =U33*J33 -> 465120 | W33: =$W$4-A33 -> 189 | X33: =VLOOKUP(W33,$AA$2:$AB$6,2) -> 06-12 Months | Y33: =VLOOKUP(W33,$AD$2:$AE$6,2) -> >181 Days
A34: 19/11/2025 | B34: D-514 | C34: GR5839 | D34: KHAJUR BOX 5 | E34: AJWA PREMIUM (JFD)8883 | F34: - | G34: 9620 | H34: 4 | I34: 5 | J34: =I34*H34 -> 20 | K34: Premium Dates | L34: Ajwa | M34: {=VLOOKUP(Q34,[1]CDPL!$A:$D,{3,4},0)} -> DATES | N34: Ajwa | O34: Premium | P34: Ajwa Premium | Q34: Wet Dates Ajwa | R34: CDPL | S34: Savla | T34: Local | U34: 675 | V34: =U34*J34 -> 13500 | W34: =$W$4-A34 -> 174 | X34: =VLOOKUP(W34,$AA$2:$AB$6,2) -> < 6 Months | Y34: =VLOOKUP(W34,$AD$2:$AE$6,2) -> 90-180 Days
A35: 19/11/2025 | B35: D-514 | C35: GR5839 | D35: KHAJUR BOX 5 | E35: AJWA REGULAR (JFD) 8884 | F35: - | G35: 9621 | H35: 40 | I35: 5 | J35: =I35*H35 -> 200 | K35: Premium Dates | L35: Ajwa | M35: {=VLOOKUP(Q35,[1]CDPL!$A:$D,{3,4},0)} -> DATES | N35: Ajwa | O35: Regular | P35: Ajwa Regular | Q35: Wet Dates Ajwa | R35: CDPL | S35: Savla | T35: Local | U35: 675 | V35: =U35*J35 -> 135000 | W35: =$W$4-A35 -> 174 | X35: =VLOOKUP(W35,$AA$2:$AB$6,2) -> < 6 Months | Y35: =VLOOKUP(W35,$AD$2:$AE$6,2) -> 90-180 Days
A36: 13/12/2025 | B36: D-514 | C36: GR6454 | D36: KHAJUR BOX 5 | E36: SIAFA MABROOM REGUL.[8701] | F36: - | G36: 10801 | H36: 40 | I36: 5 | J36: =I36*H36 -> 200 | K36: Premium Dates | L36: Mabroom | M36: {=VLOOKUP(Q36,[1]CDPL!$A:$D,{3,4},0)} -> DATES | N36: Mabroom | O36: Mabroom | P36: Mabroom Regular | Q36: Wet Dates (Mabroom) | R36: CDPL | S36: Savla | T36: Local | U36: 800 | V36: =U36*J36 -> 160000 | W36: =$W$4-A36 -> 150 | X36: =VLOOKUP(W36,$AA$2:$AB$6,2) -> < 6 Months | Y36: =VLOOKUP(W36,$AD$2:$AE$6,2) -> 90-180 Days
A37: 13/12/2025 | B37: D-514 | C37: GR6454 | D37: KHAJUR BOX 5 | E37: AJWA REGULAR [8884] | F37: - | G37: 10798 | H37: 15 | I37: 5 | J37: =I37*H37 -> 75 | K37: Premium Dates | L37: Ajwa | M37: {=VLOOKUP(Q37,[1]CDPL!$A:$D,{3,4},0)} -> DATES | N37: Ajwa | O37: Regular | P37: Ajwa Regular | Q37: Wet Dates Ajwa | R37: CDPL | S37: Savla | T37: Local | U37: 675 | V37: =U37*J37 -> 50625 | W37: =$W$4-A37 -> 150 | X37: =VLOOKUP(W37,$AA$2:$AB$6,2) -> < 6 Months | Y37: =VLOOKUP(W37,$AD$2:$AE$6,2) -> 90-180 Days
A38: 05/01/2026 | B38: D-39 | C38: GR18127 | D38: KHAJUR SYRUP BUCKET 25 | E38: DATE SYRUP | F38: - | G38: 176443 | H38: 3 | I38: 25 | J38: =I38*H38 -> 75 | K38: Date Syrup | L38: Bucket 25Kg | M38: {=VLOOKUP(Q38,[1]CDPL!$A:$D,{3,4},0)} -> DATES | N38: Syrup | O38: AL BARAKAH | P38: AL BARAKAH DATES SYRUP 25 kg Pack | Q38: 25KG AL BARAKAH DATE SYRUP V1 | R38: CDPL | S38: Savla | T38: AL BARAKAH | U38: 109.8 | V38: =U38*J38 -> 8235 | W38: =$W$4-A38 -> 127 | X38: =VLOOKUP(W38,$AA$2:$AB$6,2) -> < 6 Months | Y38: =VLOOKUP(W38,$AD$2:$AE$6,2) -> 90-180 Days
A39: 12/01/2026 | B39: D-514 | C39: GR7119 | D39: KHAJUR BOX 5 | E39: AJWA WHITE BOX | F39: - | G39: 12108 | H39: 73 | I39: 5 | J39: =I39*H39 -> 365 | K39: Premium Dates | L39: Ajwa | M39: {=VLOOKUP(Q39,[1]CDPL!$A:$D,{3,4},0)} -> DATES | N39: Ajwa | O39: Regular | P39: Ajwa Regular | Q39: Wet Dates Ajwa | R39: CDPL | S39: Savla | T39: Local | U39: 675 | V39: =U39*J39 -> 246375 | W39: =$W$4-A39 -> 120 | X39: =VLOOKUP(W39,$AA$2:$AB$6,2) -> < 6 Months | Y39: =VLOOKUP(W39,$AD$2:$AE$6,2) -> 90-180 Days
A40: 18/01/2026 | B40: D-514 | C40: GR7275 | D40: KHAJUR BOX 5 | E40: SUPER SELECT SAFAWI | F40: SS | G40: 12324 | H40: 970 | I40: 5 | J40: =I40*H40 -> 4850 | K40: Premium Dates | L40: Safawi-SS | M40: {=VLOOKUP(Q40,[1]CFPL!$A:$D,{3,4},0)} -> DATES | N40: Safavi | O40: Super Select | P40: Wet Dates Safavi - Super Select | Q40: Wet Dates Safavi | R40: CDPL | S40: Savla | T40: AL BARAKAH | U40: 435 | V40: =U40*J40 -> 2109750 | W40: =$W$4-A40 -> 114 | X40: =VLOOKUP(W40,$AA$2:$AB$6,2) -> < 6 Months | Y40: =VLOOKUP(W40,$AD$2:$AE$6,2) -> 90-180 Days
...

Sheet 30th Dec 25 (2)
A1: Savla Foods & Rishi Cold Storage Pvt Ltd | Y1: Overdays | Z1: Bucket
A2: Report Date : | B2: =TODAY() -> 46154 | Y2: 0 | Z2: < 6 Months
A3: As On Date : | B3: =TODAY()-1 -> 46153 | Y3: 180 | Z3: 06-12 Months
A4: Stock Details Report | J4: =TODAY()-1 -> 46153 | V4: =TODAY() -> 46154 | Y4: 365 | Z4: 12-18 Months
H5: =SUBTOTAL(9,H7:H999964) -> 92330.93 | J5: =SUBTOTAL(9,J7:J999964) -> 624011.65 | K5: 46019 | U5: =SUBTOTAL(9,U7:U412) -> 1.4985432e+08 | Y5: 540 | Z5: 18-24 Months
A6: Inward Dt | B6: Unit | C6: Inward No | D6: Item Description | E6: Item Mark | F6: Vakkal | G6: Lot No | H6: Net Qty On Cartons | I6: Weight KG | J6: Total Inventory Kgs | K6: Group Name* | L6: Sub Group Name* | M6: Sub Sub Group Name* | N6: Item Display Name* | O6: Tally Name | P6: Company Name | Q6: Storage Location | R6: Stock | S6: Exporter | T6: Last Purchase Rate | U6: Value | V6: Ageing | W6: Ageing Bucket | Y6: 730 | Z6: >24 Months
A7: 24/07/2023 | B7: D-39 | C7: GR5903 | D7: KHAJUR BOX 10 | E7: WHITE POWDER | F7: V-2 | G7: 56059 | H7: 45 | I7: 10 | J7: =I7*H7 -> 450 | K7: Date Powder | L7: V2 | M7: AL BARAKAH | N7: 10KG AL BARAKAH DATE POWDER V2 | O7: 10KG AL BARAKAH DATE POWDER V2 | P7: CDPL | Q7: Savla | R7: Rental | S7: AL BARAKAH | T7: 215 | U7: =T7*J7 -> 96750 | V7: =$V$4-A7 -> 1023 | W7: =VLOOKUP(V7,$Y$2:$Z$6,2) -> >24 Months
A8: 06/12/2023 | B8: D-39 | C8: GR14501 | D8: KHAJUR BOX 8 | E8: BASOOR=OMAN DRY DATES | F8: GRADE 2 | G8: 77517 | H8: 14 | I8: 7 | J8: =I8*H8 -> 98 | K8: Dry Dates | L8: Omani Kharik | M8: Dry Dates | N8: BUSOOR DRY DATES GRADE - 2 | O8: DRY DATES-GRADE 2 | P8: CDPL | Q8: Savla | R8: Rental | S8: NAKHEEL | T8: 241 | U8: =T8*J8 -> 23618 | V8: =$V$4-A8 -> 888 | W8: =VLOOKUP(V8,$Y$2:$Z$6,2) -> >24 Months
A9: 06/12/2023 | B9: D-39 | C9: GR14501 | D9: KHAJUR BOX 8 | E9: BASOOR=OMAN DRY DATES | F9: GRADE 2 | G9: 77517 | H9: 9 | I9: 7 | J9: =I9*H9 -> 63 | K9: Dry Dates | L9: Omani Kharik | M9: Dry Dates | N9: BUSOOR DRY DATES GRADE - 2 | O9: DRY DATES-GRADE 2 | P9: CDPL | Q9: Savla | R9: Rental | S9: NAKHEEL | T9: 241 | U9: =T9*J9 -> 15183 | V9: =$V$4-A9 -> 888 | W9: =VLOOKUP(V9,$Y$2:$Z$6,2) -> >24 Months
A10: 06/12/2023 | B10: D-39 | C10: GR14501 | D10: KHAJUR BOX 8 | E10: BASOOR=OMAN DRY DATES | F10: GRADE 2 | G10: 77517 | H10: 49 | I10: 7 | J10: =I10*H10 -> 343 | K10: Dry Dates | L10: Omani Kharik | M10: Dry Dates | N10: BUSOOR DRY DATES GRADE - 2 | O10: DRY DATES-GRADE 2 | P10: CDPL | Q10: Savla | R10: Rental | S10: NAKHEEL | T10: 241 | U10: =T10*J10 -> 82663 | V10: =$V$4-A10 -> 888 | W10: =VLOOKUP(V10,$Y$2:$Z$6,2) -> >24 Months
A11: 06/12/2023 | B11: D-39 | C11: GR14501 | D11: KHAJUR BOX 8 | E11: BASOOR=OMAN DRY DATES | F11: GRADE 2 | G11: 77517 | H11: 3 | I11: 7 | J11: =I11*H11 -> 21 | K11: Dry Dates | L11: Omani Kharik | M11: Dry Dates | N11: BUSOOR DRY DATES GRADE - 2 | O11: DRY DATES-GRADE 2 | P11: CDPL | Q11: Savla | R11: Rental | S11: NAKHEEL | T11: 241 | U11: =T11*J11 -> 5061 | V11: =$V$4-A11 -> 888 | W11: =VLOOKUP(V11,$Y$2:$Z$6,2) -> >24 Months
A12: 09/12/2023 | B12: D-514 | C12: GR6307 | D12: KHAJUR BOX 5 | E12: ARSH RABIA REGULAR | F12: - | G12: 65864 | H12: 88 | I12: 5 | J12: =I12*H12 -> 440 | K12: Economical Dates | L12: Rabia | M12: Rabia | N12: Rabia Dates 5kg | O12: Wet Dates (Rabia) | P12: CDPL | Q12: Savla | R12: Rental | S12: Local | T12: 187.5 | U12: =T12*J12 -> 82500 | V12: =$V$4-A12 -> 885 | W12: =VLOOKUP(V12,$Y$2:$Z$6,2) -> >24 Months
A13: 22/12/2023 | B13: D-39 | C13: GR15493 | D13: KHAJUR BOX 10 | E13: AZMAH DATES | F13: 500GM | G13: 79112 | H13: 16 | I13: 10 | J13: =I13*H13 -> 160 | K13: Premium Dates | L13: Safawi | M13: Azmah 500gm | N13: Azmah Dates 10kg | O13: Wet Dates Safavi | P13: CDPL | Q13: Savla | R13: Fix (M2G) (+) | S13: Local | T13: 550 | U13: =T13*J13 -> 88000 | V13: =$V$4-A13 -> 872 | W13: =VLOOKUP(V13,$Y$2:$Z$6,2) -> >24 Months
A14: 22/12/2023 | B14: D-39 | C14: GR15515 | D14: KHAJUR BOX 5 | E14: RABIA/RAWAT | F14: - | G14: 79138 | H14: 5 | I14: 5 | J14: =I14*H14 -> 25 | K14: Economical Dates | L14: Rabia | M14: Rabia | N14: Rabia Dates 5kg | O14: Wet Dates (Rabia) | P14: CDPL | Q14: Savla | R14: Rental | S14: Local | T14: 187.5 | U14: =T14*J14 -> 4687.5 | V14: =$V$4-A14 -> 872 | W14: =VLOOKUP(V14,$Y$2:$Z$6,2) -> >24 Months
A15: 23/12/2023 | B15: D-39 | C15: GR15573 | D15: KHAJUR BOX 5 | E15: SAFAVI | F15: - | G15: 79273 | H15: 1 | I15: 5 | J15: =I15*H15 -> 5 | K15: Premium Dates | L15: Safawi | M15: Safawi | N15: Safawi Dates 5kg | O15: Wet Dates Safavi | P15: CDPL | Q15: Savla | R15: Fix (M2G) (+) | S15: Local | T15: 550 | U15: =T15*J15 -> 2750 | V15: =$V$4-A15 -> 871 | W15: =VLOOKUP(V15,$Y$2:$Z$6,2) -> >24 Months
A16: 25/12/2023 | B16: D-39 | C16: GR15667 | D16: KHAREK BOX 15 | E16: - | F16: CUTT | G16: 79450 | H16: 6 | I16: 15 | J16: =I16*H16 -> 90 | K16: Dry Dates | L16: KHAREK | M16: RED KHAREK | N16: Red Kharek Cut | O16: Seedless Chopped Red Kharik Dry Dates | P16: CDPL | Q16: Savla | R16: Rental | S16: Local | T16: 250 | U16: =T16*J16 -> 22500 | V16: =$V$4-A16 -> 869 | W16: =VLOOKUP(V16,$Y$2:$Z$6,2) -> >24 Months
A17: 27/03/2024 | B17: D-39 | C17: GR21140 | D17: KHAJUR BOX 5 | E17: SAFAVI DATES | F17: WHITE | G17: 90090 | H17: 2 | I17: 5 | J17: =I17*H17 -> 10 | K17: Premium Dates | L17: Safawi | M17: Safawi | N17: Safawi Dates 5kg | O17: Wet Dates Safavi | P17: CDPL | Q17: Savla | R17: Fix (M2G) (+) | S17: Local | T17: 550 | U17: =T17*J17 -> 5500 | V17: =$V$4-A17 -> 776 | W17: =VLOOKUP(V17,$Y$2:$Z$6,2) -> >24 Months
A18: 27/03/2024 | B18: D-39 | C18: GR21140 | D18: KHAJUR BOX 5 | E18: KALMI DATES | F18: SAFAVI | G18: 90088 | H18: 2 | I18: 5 | J18: =I18*H18 -> 10 | K18: Premium Dates | L18: Safawi | M18: Safawi | N18: Safawi Dates 5kg | O18: Wet Dates Safavi | P18: CDPL | Q18: Savla | R18: Fix (M2G) (+) | S18: Local | T18: 550 | U18: =T18*J18 -> 5500 | V18: =$V$4-A18 -> 776 | W18: =VLOOKUP(V18,$Y$2:$Z$6,2) -> >24 Months
... A76: 29/06/2025 | B76: D-39 | C76: GR5609 | D76: KHAJUR POWDER BOX 10 | E76: AL BARAKAH | F76: MIX | G76: 147739 | H76: 32 | I76: 10 | J76: =I76*H76 -> 320 | K76: Date Powder | L76: V1 | M76: AL BARAKAH | N76: 10KG AL BARAKAH DATE POWDER | O76: 10KG AL BARAKAH DATE POWDER V1 | P76: CDPL | Q76: Savla | R76: Rental | S76: AL BARAKAH | T76: 270 | U76: =T76*J76 -> 86400 | V76: =$V$4-A76 -> 317 | W76: =VLOOKUP(V76,$Y$2:$Z$6,2) -> 06-12 Months
A77: 19/07/2025 | B77: D-514 | C77: GR2898 | D77: KHAJUR BOX 5 | E77: SIAFA AJWA REGULAR (2929) | F77: - | G77: 4728 | H77: 4 | I77: 5 | J77: =I77*H77 -> 20 | K77: Premium Dates | L77: Ajwa | M77: Premium | N77: Ajwa Regular | O77: Wet Dates Ajwa | P77: CDPL | Q77: Savla | R77: Rental | S77: 0 | T77: 950 | U77: =T77*J77 -> 19000 | V77: =$V$4-A77 -> 297 | W77: =VLOOKUP(V77,$Y$2:$Z$6,2) -> 06-12 Months
A78: 24/09/2025 | B78: D-39 | C78: GR10777 | D78: KHAJUR POWDER BOX 10 | E78: AL BARAKAH | F78: - | G78: 156985 | H78: 1570 | I78: 10 | J78: =I78*H78 -> 15700 | K78: Date Powder | L78: V1 | M78: AL BARAKAH | N78: 10KG AL BARAKAH DATE POWDER | O78: 10KG AL BARAKAH DATE POWDER V1 | P78: CDPL | Q78: Savla | R78: Rental | S78: AL BARAKAH | T78: 280 | U78: =T78*J78 -> 4396000 | V78: =$V$4-A78 -> 230 | W78: =VLOOKUP(V78,$Y$2:$Z$6,2) -> 06-12 Months
